#######################################################################
# +-----------------------------------------------------------------+ #
# |                            BO3 object                           | #
# +-----------------------------------------------------------------+ #
#######################################################################

Author: Bo3 BulkEdit

Description: Converted Schematic - Modified by Bo3BulkEdit

Version: 3

SettingsMode: WriteDisable

#######################################################################
# +-----------------------------------------------------------------+ #
# |                          Main settings                          | #
# +-----------------------------------------------------------------+ #
#######################################################################

IsOTGPlus: false
Tree: false
Frequency: 1
Rarity: 100
RotateRandomly: true
SpawnHeight: HighestSolidBlock
SpawnHeightOffset: 0
SpawnHeightVariance: 0
MaxBranchDepth: 10
ExcludedBiomes: All

##############################
# Height Limits for the BO3. #
##############################

MinHeight: 0
MaxHeight: 256

#######################################################################
# +-----------------------------------------------------------------+ #
# |                      Source block settings                      | #
# +-----------------------------------------------------------------+ #
#######################################################################

SourceBlocks: AIR,GRASS,DIRT,STONE,LEAVES,LONG_GRASS
MaxPercentageOutsideSourceBlock: 40
OutsideSourceBlock: placeAnyway

CanOverride: true
BranchFrequency: 2
ReplaceBelow: STONE
ReplaceWithBiomeBlocks: true
ReplaceWithGroundBlock: DIRT
ReplaceWithSurfaceBlock: GRASS
ReplaceWithStoneBlock: STONE
SmoothRadius: 0
SmoothHeightOffset: 0
BO3Group: Ships:2, CoralSmall:1, CoralBig:2
IsSpawnPoint: true

#######################################################################
# +-----------------------------------------------------------------+ #
# |                              Blocks                             | #
# +-----------------------------------------------------------------+ #
#######################################################################

Block(1,-5,-2,STONE)
Block(2,-5,-2,STONE)
Block(3,-5,-2,STONE)
Block(4,-5,-2,STONE)
Block(0,-5,-1,STONE)
Block(1,-5,-1,STONE)
Block(2,-5,-1,STONE)
Block(3,-5,-1,STONE)
Block(4,-5,-1,STONE)
Block(-1,-5,0,STONE)
Block(0,-5,0,STONE)
Block(1,-5,0,STONE)
Block(2,-5,0,STONE)
Block(3,-5,0,STONE)
Block(4,-5,0,STONE)
Block(-1,-5,1,STONE)
Block(0,-5,1,STONE)
Block(1,-5,1,STONE)
Block(2,-5,1,STONE)
Block(3,-5,1,STONE)
Block(0,-5,2,STONE)
Block(1,-5,2,STONE)
Block(2,-5,2,STONE)
Block(-1,-4,-5,STONE)
Block(0,-4,-4,STONE)
Block(0,-4,-3,STONE)
Block(1,-4,-3,STONE)
Block(2,-4,-3,STONE)
Block(0,-4,-2,STONE)
Block(1,-4,-2,STONE)
Block(2,-4,-2,STONE)
Block(3,-4,-2,STONE)
Block(4,-4,-2,STONE)
Block(-1,-4,-1,STONE)
Block(0,-4,-1,STONE)
Block(1,-4,-1,STONE)
Block(2,-4,-1,STONE)
Block(3,-4,-1,STONE)
Block(4,-4,-1,STONE)
Block(-2,-4,0,STONE)
Block(-1,-4,0,STONE)
Block(0,-4,0,STONE)
Block(1,-4,0,STONE)
Block(2,-4,0,STONE)
Block(3,-4,0,STONE)
Block(4,-4,0,STONE)
Block(5,-4,0,STONE)
Block(-3,-4,1,STONE)
Block(-2,-4,1,STONE)
Block(-1,-4,1,STONE)
Block(0,-4,1,STONE)
Block(1,-4,1,STONE)
Block(2,-4,1,STONE)
Block(3,-4,1,STONE)
Block(4,-4,1,STONE)
Block(5,-4,1,STONE)
Block(-3,-4,2,STONE)
Block(-2,-4,2,STONE)
Block(-1,-4,2,STONE)
Block(0,-4,2,STONE)
Block(1,-4,2,STONE)
Block(2,-4,2,STONE)
Block(3,-4,2,STONE)
Block(4,-4,2,STONE)
Block(5,-4,2,STONE)
Block(-2,-4,3,STONE)
Block(-1,-4,3,STONE)
Block(0,-4,3,STONE)
Block(1,-4,3,STONE)
Block(2,-4,3,STONE)
Block(3,-4,3,STONE)
Block(4,-4,3,STONE:5)
Block(-1,-4,4,STONE)
Block(0,-4,4,STONE)
Block(1,-4,4,STONE)
Block(2,-4,4,STONE)
Block(3,-4,4,STONE)
Block(-1,-3,-5,STONE)
Block(0,-3,-4,STONE)
Block(0,-3,-3,STONE)
Block(1,-3,-3,STONE)
Block(2,-3,-3,STONE)
Block(0,-3,-2,STONE)
Block(1,-3,-2,STONE)
Block(2,-3,-2,STONE)
Block(3,-3,-2,STONE)
Block(4,-3,-2,STONE)
Block(-1,-3,-1,STONE)
Block(0,-3,-1,STONE)
Block(1,-3,-1,STONE)
Block(2,-3,-1,STONE)
Block(3,-3,-1,STONE)
Block(4,-3,-1,STONE)
Block(-2,-3,0,STONE)
Block(-1,-3,0,STONE)
Block(0,-3,0,STONE)
Block(1,-3,0,STONE)
Block(2,-3,0,STONE)
Block(3,-3,0,STONE)
Block(4,-3,0,STONE)
Block(5,-3,0,STONE)
Block(-3,-3,1,STONE)
Block(-2,-3,1,STONE)
Block(-1,-3,1,STONE)
Block(0,-3,1,STONE)
Block(1,-3,1,STONE)
Block(2,-3,1,STONE)
Block(3,-3,1,STONE)
Block(4,-3,1,STONE)
Block(5,-3,1,STONE)
Block(-3,-3,2,STONE)
Block(-2,-3,2,STONE)
Block(-1,-3,2,STONE)
Block(0,-3,2,STONE)
Block(1,-3,2,STONE)
Block(2,-3,2,STONE)
Block(3,-3,2,STONE)
Block(4,-3,2,STONE)
Block(5,-3,2,STONE)
Block(-2,-3,3,STONE)
Block(-1,-3,3,STONE)
Block(0,-3,3,STONE)
Block(1,-3,3,STONE)
Block(2,-3,3,STONE)
Block(3,-3,3,STONE)
Block(4,-3,3,STONE:5)
Block(-1,-3,4,STONE)
Block(0,-3,4,STONE)
Block(1,-3,4,STONE)
Block(2,-3,4,STONE)
Block(3,-3,4,STONE)
Block(0,-2,-5,STONE)
Block(1,-2,-5,STONE:5)
Block(-1,-2,-4,STONE)
Block(0,-2,-4,STONE)
Block(1,-2,-4,STONE)
Block(2,-2,-4,STONE)
Block(-4,-2,-3,STONE)
Block(-3,-2,-3,STONE)
Block(-2,-2,-3,STONE)
Block(-1,-2,-3,STONE)
Block(0,-2,-3,STONE)
Block(1,-2,-3,STONE)
Block(2,-2,-3,STONE)
Block(3,-2,-3,STONE)
Block(-3,-2,-2,STONE)
Block(-2,-2,-2,STONE)
Block(-1,-2,-2,STONE)
Block(0,-2,-2,STONE)
Block(1,-2,-2,STONE)
Block(2,-2,-2,STONE)
Block(3,-2,-2,STONE)
Block(4,-2,-2,STONE)
Block(-3,-2,-1,STONE)
Block(-2,-2,-1,STONE:5)
Block(-1,-2,-1,WOOL:7)
Block(0,-2,-1,STONE)
Block(1,-2,-1,STONE)
Block(2,-2,-1,STONE)
Block(3,-2,-1,STONE)
Block(4,-2,-1,STONE)
Block(-4,-2,0,STONE)
Block(-3,-2,0,CLAY)
Block(-2,-2,0,STONE:5)
Block(-1,-2,0,STONE:5)
Block(0,-2,0,STONE)
Block(1,-2,0,STONE)
Block(2,-2,0,STONE)
Block(3,-2,0,STONE)
Block(4,-2,0,STONE)
Block(5,-2,0,STONE)
Block(-4,-2,1,STONE)
Block(-3,-2,1,CLAY)
Block(-2,-2,1,STONE)
Block(-1,-2,1,CLAY)
Block(0,-2,1,STONE)
Block(1,-2,1,STONE)
Block(2,-2,1,STONE)
Block(3,-2,1,STONE)
Block(4,-2,1,STONE:5)
Block(5,-2,1,WOOL:7)
Block(-3,-2,2,STONE)
Block(-2,-2,2,STONE)
Block(-1,-2,2,STONE)
Block(0,-2,2,STONE)
Block(1,-2,2,STONE)
Block(2,-2,2,STONE)
Block(3,-2,2,STONE)
Block(4,-2,2,STONE)
Block(5,-2,2,STONE:5)
Block(-2,-2,3,WOOL:7)
Block(-1,-2,3,STONE)
Block(0,-2,3,STONE)
Block(1,-2,3,STONE)
Block(2,-2,3,STONE:5)
Block(3,-2,3,STONE)
Block(4,-2,3,CLAY)
Block(5,-2,3,STONE:5)
Block(-2,-2,4,STONE)
Block(-1,-2,4,STONE:5)
Block(0,-2,4,WOOL:7)
Block(1,-2,4,STONE:5)
Block(2,-2,4,CLAY)
Block(3,-2,4,CLAY)
Block(4,-2,4,STONE)
Block(-2,-2,5,STONE)
Block(-1,-2,5,STONE:5)
Block(0,-2,5,STONE:5)
Block(1,-2,5,STONE:5)
Block(2,-2,5,STONE)
Block(3,-2,5,STONE)
Block(-2,-2,6,STONE)
Block(-1,-2,6,STONE:5)
Block(0,-2,6,WOOL:7)
Block(1,-2,6,WOOL:7)
Block(2,-2,6,STONE:5)
Block(0,-1,-5,STONE:5)
Block(1,-1,-5,WOOL:7)
Block(2,-1,-5,WOOL:7)
Block(-1,-1,-4,STONE)
Block(0,-1,-4,CLAY)
Block(1,-1,-4,STONE:5)
Block(2,-1,-4,STONE:5)
Block(3,-1,-4,STONE)
Block(-3,-1,-3,STONE)
Block(-1,-1,-3,CLAY)
Block(0,-1,-3,STONE)
Block(1,-1,-3,STONE)
Block(2,-1,-3,WOOL:7)
Block(3,-1,-3,STONE)
Block(-3,-1,-2,STONE)
Block(-2,-1,-2,CLAY)
Block(-1,-1,-2,CLAY)
Block(0,-1,-2,STONE)
Block(1,-1,-2,STONE)
Block(2,-1,-2,STONE)
Block(3,-1,-2,STONE)
Block(4,-1,-2,STONE)
Block(-3,-1,-1,CLAY)
Block(-2,-1,-1,STONE)
Block(-1,-1,-1,STONE:5)
Block(0,-1,-1,STONE)
Block(1,-1,-1,STONE)
Block(2,-1,-1,STONE)
Block(3,-1,-1,STONE)
Block(4,-1,-1,WOOL:7)
Block(5,-1,-1,STONE:5)
Block(-3,-1,0,STONE)
Block(-2,-1,0,STONE:5)
Block(-1,-1,0,STONE:5)
Block(0,-1,0,STONE)
Block(1,-1,0,STONE)
Block(2,-1,0,STONE)
Block(3,-1,0,STONE)
Block(4,-1,0,STONE)
Block(5,-1,0,STONE)
Block(-3,-1,1,STONE)
Block(-2,-1,1,STONE:5)
Block(-1,-1,1,STONE)
Block(0,-1,1,STONE)
Block(1,-1,1,STONE)
Block(2,-1,1,STONE)
Block(3,-1,1,STONE)
Block(4,-1,1,WOOL:7)
Block(5,-1,1,STONE:5)
Block(-3,-1,2,STONE:5)
Block(-2,-1,2,WOOL:7)
Block(-1,-1,2,STONE:5)
Block(0,-1,2,CLAY)
Block(1,-1,2,STONE)
Block(2,-1,2,STONE)
Block(3,-1,2,STONE:5)
Block(4,-1,2,STONE:5)
Block(5,-1,2,STONE:5)
Block(-2,-1,3,STONE:5)
Block(-1,-1,3,STONE)
Block(0,-1,3,STONE)
Block(1,-1,3,STONE:5)
Block(2,-1,3,WOOL:7)
Block(3,-1,3,WOOL:7)
Block(4,-1,3,STONE:5)
Block(5,-1,3,WOOL:7)
Block(-2,-1,4,CLAY)
Block(-1,-1,4,CLAY)
Block(0,-1,4,STONE:5)
Block(1,-1,4,WOOL:7)
Block(2,-1,4,STONE:5)
Block(3,-1,4,STONE)
Block(4,-1,4,STONE:5)
Block(-2,-1,5,STONE)
Block(-1,-1,5,STONE)
Block(0,-1,5,STONE)
Block(1,-1,5,STONE:5)
Block(2,-1,5,STONE)
Block(3,-1,5,STONE:5)
Block(-2,-1,6,STONE:5)
Block(-1,-1,6,CLAY)
Block(0,-1,6,STONE)
Block(1,-1,6,STONE:5)
Block(2,-1,6,CLAY)
Block(3,-1,6,STONE)
Block(0,-1,7,STONE:5)
Block(1,-1,7,STONE:5)
Block(2,-1,7,STONE)
Block(0,0,-5,STONE)
Block(1,0,-5,STONE:5)
Block(2,0,-5,WOOL:7)
Block(0,0,-4,STONE)
Block(1,0,-4,STONE:5)
Block(2,0,-4,WOOL:7)
Block(3,0,-4,STONE:5)
Block(-1,0,-3,STONE)
Block(0,0,-3,STONE)
Block(1,0,-3,CLAY)
Block(2,0,-3,STONE:5)
Block(3,0,-3,STONE)
Block(4,0,-3,CLAY)
Block(-1,0,-2,STONE:5)
Block(0,0,-2,STONE)
Block(1,0,-2,CLAY)
Block(2,0,-2,STONE)
Block(3,0,-2,CLAY)
Block(4,0,-2,CLAY)
Block(5,0,-2,STONE)
Block(-2,0,-1,WOOL:7)
Block(-1,0,-1,WOOL:7)
Block(0,0,-1,STONE:5)
Block(1,0,-1,STONE:5)
Block(2,0,-1,STONE)
Block(3,0,-1,STONE:5)
Block(4,0,-1,STONE)
Block(5,0,-1,STONE)
Block(-3,0,0,STONE:5)
Block(-2,0,0,STONE:5)
Block(-1,0,0,STONE:5)
Block(0,0,0,STONE:5)
Block(1,0,0,WOOL:7)
Block(2,0,0,STONE)
Block(3,0,0,STONE:5)
Block(4,0,0,STONE)
Block(-3,0,1,STONE)
Block(-2,0,1,STONE)
Block(-1,0,1,STONE:5)
Block(0,0,1,WOOL:7)
Block(1,0,1,WOOL:7)
Block(2,0,1,STONE)
Block(3,0,1,STONE)
Block(4,0,1,STONE:5)
Block(-2,0,2,STONE:5)
Block(-1,0,2,WOOL:7)
Block(0,0,2,STONE:5)
Block(1,0,2,STONE)
Block(2,0,2,STONE)
Block(3,0,2,STONE:5)
Block(4,0,2,STONE:5)
Block(5,0,2,WOOL:7)
Block(-2,0,3,STONE)
Block(-1,0,3,STONE:5)
Block(0,0,3,STONE)
Block(1,0,3,STONE:5)
Block(2,0,3,WOOL:7)
Block(3,0,3,STONE:5)
Block(4,0,3,STONE)
Block(5,0,3,WOOL:7)
Block(-2,0,4,CLAY)
Block(-1,0,4,STONE)
Block(0,0,4,STONE)
Block(1,0,4,STONE)
Block(2,0,4,STONE)
Block(3,0,4,STONE)
Block(4,0,4,CLAY)
Block(-2,0,5,STONE)
Block(-1,0,5,STONE)
Block(0,0,5,STONE)
Block(1,0,5,CLAY)
Block(2,0,5,STONE)
Block(3,0,5,STONE:5)
Block(-1,0,6,STONE:5)
Block(0,0,6,STONE:5)
Block(1,0,6,STONE:5)
Block(2,0,6,WOOL:7)
Block(3,0,6,STONE:5)
Block(0,1,-5,CLAY)
Block(1,1,-5,STONE:5)
Block(0,1,-4,STONE)
Block(1,1,-4,STONE)
Block(2,1,-4,WOOL:7)
Block(3,1,-4,STONE)
Block(0,1,-3,STONE:5)
Block(1,1,-3,CLAY)
Block(2,1,-3,STONE:5)
Block(3,1,-3,STONE:5)
Block(4,1,-3,STONE)
Block(-1,1,-2,WOOL:7)
Block(0,1,-2,STONE:5)
Block(1,1,-2,STONE)
Block(2,1,-2,STONE)
Block(3,1,-2,STONE)
Block(4,1,-2,STONE:5)
Block(5,1,-2,WOOL:7)
Block(-2,1,-1,STONE:5)
Block(-1,1,-1,STONE:5)
Block(0,1,-1,STONE:5)
Block(1,1,-1,STONE:5)
Block(2,1,-1,STONE:5)
Block(3,1,-1,STONE)
Block(4,1,-1,CLAY)
Block(5,1,-1,CLAY)
Block(-2,1,0,CLAY)
Block(-1,1,0,CLAY)
Block(0,1,0,STONE)
Block(1,1,0,WOOL:7)
Block(2,1,0,STONE)
Block(3,1,0,STONE)
Block(4,1,0,CLAY)
Block(-2,1,1,STONE)
Block(-1,1,1,CLAY)
Block(0,1,1,STONE)
Block(1,1,1,STONE:5)
Block(2,1,1,STONE)
Block(3,1,1,STONE)
Block(4,1,1,STONE)
Block(-2,1,2,CLAY)
Block(-1,1,2,STONE)
Block(0,1,2,STONE)
Block(1,1,2,STONE)
Block(2,1,2,STONE)
Block(3,1,2,STONE)
Block(4,1,2,CLAY)
Block(-2,1,3,STONE)
Block(-1,1,3,STONE:5)
Block(0,1,3,STONE)
Block(1,1,3,STONE:5)
Block(2,1,3,STONE:5)
Block(3,1,3,STONE)
Block(4,1,3,CLAY)
Block(5,1,3,STONE:5)
Block(-2,1,4,STONE:5)
Block(-1,1,4,WOOL:7)
Block(0,1,4,WOOL:7)
Block(1,1,4,STONE)
Block(2,1,4,CLAY)
Block(3,1,4,STONE)
Block(4,1,4,STONE)
Block(-2,1,5,STONE)
Block(-1,1,5,STONE)
Block(0,1,5,STONE)
Block(1,1,5,CLAY)
Block(2,1,5,STONE)
Block(3,1,5,STONE)
Block(2,1,6,WOOL:7)
Block(0,2,-6,STONE)
Block(0,2,-5,CLAY)
Block(0,2,-4,STONE:5)
Block(1,2,-4,STONE)
Block(0,2,-3,STONE:5)
Block(1,2,-3,STONE:5)
Block(2,2,-3,STONE:5)
Block(-1,2,-2,STONE:5)
Block(0,2,-2,STONE:5)
Block(1,2,-2,STONE)
Block(2,2,-2,CLAY)
Block(3,2,-2,STONE:5)
Block(4,2,-2,WOOL:7)
Block(5,2,-2,STONE:5)
Block(-2,2,-1,WOOL:7)
Block(-1,2,-1,STONE)
Block(0,2,-1,CLAY)
Block(1,2,-1,CLAY)
Block(2,2,-1,STONE)
Block(3,2,-1,CLAY)
Block(4,2,-1,STONE)
Block(5,2,-1,STONE)
Block(-2,2,0,STONE:5)
Block(-1,2,0,STONE)
Block(0,2,0,STONE)
Block(1,2,0,STONE:5)
Block(2,2,0,STONE)
Block(3,2,0,STONE)
Block(4,2,0,STONE)
Block(-2,2,1,STONE)
Block(-1,2,1,CLAY)
Block(0,2,1,STONE:5)
Block(1,2,1,WOOL:7)
Block(2,2,1,STONE)
Block(3,2,1,STONE)
Block(4,2,1,STONE)
Block(-2,2,2,STONE)
Block(-1,2,2,STONE)
Block(0,2,2,STONE)
Block(1,2,2,STONE)
Block(2,2,2,STONE)
Block(3,2,2,STONE)
Block(4,2,2,STONE)
Block(-2,2,3,STONE:5)
Block(-1,2,3,CLAY)
Block(0,2,3,CLAY)
Block(1,2,3,STONE)
Block(2,2,3,STONE)
Block(3,2,3,STONE)
Block(4,2,3,STONE)
Block(-2,2,4,WOOL:7)
Block(-1,2,4,STONE:5)
Block(0,2,4,STONE:5)
Block(1,2,4,STONE)
Block(2,2,4,CLAY)
Block(3,2,4,STONE)
Block(4,2,4,WOOL:7)
Block(-2,2,5,STONE:5)
Block(-1,2,5,STONE)
Block(0,2,5,STONE:5)
Block(1,2,5,STONE)
Block(2,2,5,STONE)
Block(3,2,5,STONE:5)
Block(0,3,-6,STONE:5)
Block(0,3,-5,STONE:5)
Block(-1,3,-3,CLAY)
Block(0,3,-3,STONE:5)
Block(-1,3,-2,STONE)
Block(0,3,-2,WOOL:7)
Block(1,3,-2,STONE)
Block(2,3,-2,STONE:5)
Block(3,3,-2,STONE:5)
Block(4,3,-2,STONE:5)
Block(-2,3,-1,STONE)
Block(-1,3,-1,CLAY)
Block(0,3,-1,STONE)
Block(1,3,-1,STONE)
Block(2,3,-1,CLAY)
Block(3,3,-1,STONE)
Block(4,3,-1,CLAY)
Block(-1,3,0,STONE)
Block(0,3,0,STONE:5)
Block(1,3,0,STONE)
Block(2,3,0,STONE)
Block(3,3,0,STONE)
Block(4,3,0,STONE)
Block(-1,3,1,STONE:5)
Block(0,3,1,WOOL:7)
Block(1,3,1,STONE)
Block(2,3,1,STONE)
Block(3,3,1,STONE)
Block(4,3,1,STONE:5)
Block(-1,3,2,STONE:5)
Block(0,3,2,STONE:5)
Block(1,3,2,STONE)
Block(2,3,2,STONE)
Block(3,3,2,STONE)
Block(4,3,2,STONE)
Block(-1,3,3,STONE)
Block(0,3,3,STONE:5)
Block(1,3,3,STONE)
Block(2,3,3,STONE)
Block(3,3,3,STONE)
Block(4,3,3,STONE)
Block(-2,3,4,STONE)
Block(-1,3,4,STONE)
Block(0,3,4,STONE)
Block(1,3,4,STONE)
Block(2,3,4,STONE)
Block(3,3,4,STONE)
Block(-1,3,5,STONE:5)
Block(0,3,5,WOOL:7)
Block(0,4,-2,STONE)
Block(1,4,-2,STONE)
Block(-1,4,-1,STONE)
Block(0,4,-1,STONE)
Block(1,4,-1,STONE)
Block(2,4,-1,STONE)
Block(3,4,-1,STONE)
Block(-1,4,0,STONE)
Block(0,4,0,STONE)
Block(1,4,0,STONE)
Block(2,4,0,STONE)
Block(3,4,0,STONE)
Block(4,4,0,GRASS)
Block(-1,4,1,STONE:5)
Block(0,4,1,STONE)
Block(1,4,1,STONE)
Block(2,4,1,STONE)
Block(3,4,1,STONE)
Block(4,4,1,DIRT:2)
Block(-1,4,2,STONE)
Block(0,4,2,STONE)
Block(1,4,2,STONE)
Block(2,4,2,STONE)
Block(3,4,2,STONE)
Block(4,4,2,DIRT:2)
Block(0,4,3,STONE)
Block(1,4,3,STONE)
Block(2,4,3,STONE)
Block(3,4,3,STONE)
Block(4,4,3,DIRT:2)
Block(0,4,4,STONE)
Block(1,4,4,STONE)
Block(2,4,4,STONE)
Block(1,5,-2,DIRT:2)
Block(0,5,-1,STONE)
Block(1,5,-1,STONE)
Block(2,5,-1,STONE)
Block(3,5,-1,STONE)
Block(-1,5,0,GRASS)
Block(0,5,0,STONE)
Block(1,5,0,STONE)
Block(2,5,0,STONE)
Block(3,5,0,STONE)
Block(-1,5,1,GRASS)
Block(0,5,1,STONE)
Block(1,5,1,STONE)
Block(2,5,1,STONE)
Block(3,5,1,STONE)
Block(-1,5,2,DIRT:2)
Block(0,5,2,GRASS)
Block(1,5,2,STONE)
Block(2,5,2,STONE)
Block(3,5,2,STONE)
Block(0,5,3,DIRT:2)
Block(1,5,3,STONE)
Block(2,5,3,STONE)
Block(3,5,3,DIRT:2)
Block(1,5,4,STONE)
Block(2,5,4,DIRT:2)
Block(0,6,-1,GRASS)
Block(1,6,-1,GRASS)
Block(2,6,-1,STONE)
Block(3,6,-1,STONE)
Block(0,6,0,GRASS)
Block(1,6,0,STONE)
Block(2,6,0,STONE)
Block(3,6,0,STONE)
Block(-1,6,1,TALLGRASS:1)
Block(0,6,1,GRASS)
Block(1,6,1,STONE)
Block(2,6,1,STONE)
Block(3,6,1,STONE)
Block(0,6,2,TALLGRASS:1)
Block(1,6,2,STONE)
Block(2,6,2,STONE)
Block(3,6,2,STONE)
Block(1,6,3,DIRT:2)
Block(2,6,3,STONE)
Block(1,6,4,DIRT:2)
Block(0,7,-1,TALLGRASS:1)
Block(1,7,-1,TALLGRASS:1)
Block(2,7,-1,GRASS)
Block(3,7,-1,DIRT:2)
Block(0,7,0,TALLGRASS:1)
Block(1,7,0,GRASS)
Block(2,7,0,DIRT:2)
Block(3,7,0,DIRT:2)
Block(0,7,1,TALLGRASS:1)
Block(1,7,1,GRASS)
Block(2,7,1,GRASS)
Block(3,7,1,GRASS)
Block(1,7,2,DIRT:2)
Block(2,7,2,DIRT:2)
Block(3,7,2,GRASS)
Block(2,7,3,DIRT:2)
Block(2,8,-1,TALLGRASS:1)
Block(1,8,1,DOUBLE_PLANT:2)
Block(2,8,1,TALLGRASS:1)
Block(3,8,1,TALLGRASS:1)
Block(3,8,2,TALLGRASS:1)
Block(1,9,1,DOUBLE_PLANT:10)

#######################################################################
# +-----------------------------------------------------------------+ #
# |                            BO3 checks                           | #
# +-----------------------------------------------------------------+ #
#######################################################################

BlockCheck(2,-8,0,GRASS,DIRT,SAND,GRAVEL,STAINED_HARDENED_CLAY,GRASS_PATH)
BlockCheck(1,-8,1,GRASS,DIRT,SAND,GRAVEL,STAINED_HARDENED_CLAY,GRASS_PATH)
BlockCheck(2,-8,1,GRASS,DIRT,SAND,GRAVEL,STAINED_HARDENED_CLAY,GRASS_PATH)
BlockCheck(3,-8,1,GRASS,DIRT,SAND,GRAVEL,STAINED_HARDENED_CLAY,GRASS_PATH)
BlockCheck(3,-7,-1,GRASS,DIRT,SAND,GRAVEL,STAINED_HARDENED_CLAY,GRASS_PATH)
BlockCheck(4,-7,-1,GRASS,DIRT,SAND,GRAVEL,STAINED_HARDENED_CLAY,GRASS_PATH)
BlockCheck(1,-7,0,GRASS,DIRT,SAND,GRAVEL,STAINED_HARDENED_CLAY,GRASS_PATH)
BlockCheck(2,-7,0,GRASS,DIRT,SAND,GRAVEL,STAINED_HARDENED_CLAY,GRASS_PATH)
BlockCheck(3,-7,0,GRASS,DIRT,SAND,GRAVEL,STAINED_HARDENED_CLAY,GRASS_PATH)
BlockCheck(1,-7,1,GRASS,DIRT,SAND,GRAVEL,STAINED_HARDENED_CLAY,GRASS_PATH)
BlockCheck(2,-7,1,GRASS,DIRT,SAND,GRAVEL,STAINED_HARDENED_CLAY,GRASS_PATH)
BlockCheck(3,-7,1,GRASS,DIRT,SAND,GRAVEL,STAINED_HARDENED_CLAY,GRASS_PATH)
BlockCheck(4,-6,-2,GRASS,DIRT,SAND,GRAVEL,STAINED_HARDENED_CLAY,GRASS_PATH)
BlockCheck(-2,-6,-1,GRASS,DIRT,SAND,GRAVEL,STAINED_HARDENED_CLAY,GRASS_PATH)
BlockCheck(1,-6,-1,GRASS,DIRT,SAND,GRAVEL,STAINED_HARDENED_CLAY,GRASS_PATH)
BlockCheck(2,-6,-1,GRASS,DIRT,SAND,GRAVEL,STAINED_HARDENED_CLAY,GRASS_PATH)
BlockCheck(3,-6,-1,GRASS,DIRT,SAND,GRAVEL,STAINED_HARDENED_CLAY,GRASS_PATH)
BlockCheck(4,-6,-1,GRASS,DIRT,SAND,GRAVEL,STAINED_HARDENED_CLAY,GRASS_PATH)
BlockCheck(-1,-6,0,GRASS,DIRT,SAND,GRAVEL,STAINED_HARDENED_CLAY,GRASS_PATH)
BlockCheck(0,-6,0,GRASS,DIRT,SAND,GRAVEL,STAINED_HARDENED_CLAY,GRASS_PATH)
BlockCheck(1,-6,0,GRASS,DIRT,SAND,GRAVEL,STAINED_HARDENED_CLAY,GRASS_PATH)
BlockCheck(2,-6,0,GRASS,DIRT,SAND,GRAVEL,STAINED_HARDENED_CLAY,GRASS_PATH)
BlockCheck(3,-6,0,GRASS,DIRT,SAND,GRAVEL,STAINED_HARDENED_CLAY,GRASS_PATH)
BlockCheck(4,-6,0,GRASS,DIRT,SAND,GRAVEL,STAINED_HARDENED_CLAY,GRASS_PATH)
BlockCheck(-1,-6,1,GRASS,DIRT,SAND,GRAVEL,STAINED_HARDENED_CLAY,GRASS_PATH)
BlockCheck(0,-6,1,GRASS,DIRT,SAND,GRAVEL,STAINED_HARDENED_CLAY,GRASS_PATH)
BlockCheck(1,-6,1,GRASS,DIRT,SAND,GRAVEL,STAINED_HARDENED_CLAY,GRASS_PATH)
BlockCheck(2,-6,1,GRASS,DIRT,SAND,GRAVEL,STAINED_HARDENED_CLAY,GRASS_PATH)
BlockCheck(3,-6,1,GRASS,DIRT,SAND,GRAVEL,STAINED_HARDENED_CLAY,GRASS_PATH)
BlockCheck(0,-6,2,GRASS,DIRT,SAND,GRAVEL,STAINED_HARDENED_CLAY,GRASS_PATH)
BlockCheck(1,-6,2,GRASS,DIRT,SAND,GRAVEL,STAINED_HARDENED_CLAY,GRASS_PATH)
BlockCheck(2,-6,2,GRASS,DIRT,SAND,GRAVEL,STAINED_HARDENED_CLAY,GRASS_PATH)
BlockCheck(-2,-5,1,GRASS,DIRT,SAND,GRAVEL,STAINED_HARDENED_CLAY,GRASS_PATH)
BlockCheck(4,-5,1,GRASS,DIRT,SAND,GRAVEL,STAINED_HARDENED_CLAY,GRASS_PATH)
BlockCheck(5,-5,1,GRASS,DIRT,SAND,GRAVEL,STAINED_HARDENED_CLAY,GRASS_PATH)
BlockCheck(-3,-5,2,GRASS,DIRT,SAND,GRAVEL,STAINED_HARDENED_CLAY,GRASS_PATH)
BlockCheck(-2,-5,2,GRASS,DIRT,SAND,GRAVEL,STAINED_HARDENED_CLAY,GRASS_PATH)
BlockCheck(-1,-5,2,GRASS,DIRT,SAND,GRAVEL,STAINED_HARDENED_CLAY,GRASS_PATH)
BlockCheck(3,-5,2,GRASS,DIRT,SAND,GRAVEL,STAINED_HARDENED_CLAY,GRASS_PATH)
BlockCheck(4,-5,2,GRASS,DIRT,SAND,GRAVEL,STAINED_HARDENED_CLAY,GRASS_PATH)
BlockCheck(5,-5,2,GRASS,DIRT,SAND,GRAVEL,STAINED_HARDENED_CLAY,GRASS_PATH)
BlockCheck(-3,-5,3,GRASS,DIRT,SAND,GRAVEL,STAINED_HARDENED_CLAY,GRASS_PATH)
BlockCheck(-2,-5,3,GRASS,DIRT,SAND,GRAVEL,STAINED_HARDENED_CLAY,GRASS_PATH)
BlockCheck(-1,-5,3,GRASS,DIRT,SAND,GRAVEL,STAINED_HARDENED_CLAY,GRASS_PATH)
BlockCheck(0,-5,3,GRASS,DIRT,SAND,GRAVEL,STAINED_HARDENED_CLAY,GRASS_PATH)
BlockCheck(1,-5,3,GRASS,DIRT,SAND,GRAVEL,STAINED_HARDENED_CLAY,GRASS_PATH)
BlockCheck(2,-5,3,GRASS,DIRT,SAND,GRAVEL,STAINED_HARDENED_CLAY,GRASS_PATH)
BlockCheck(3,-5,3,GRASS,DIRT,SAND,GRAVEL,STAINED_HARDENED_CLAY,GRASS_PATH)
BlockCheck(4,-5,3,GRASS,DIRT,SAND,GRAVEL,STAINED_HARDENED_CLAY,GRASS_PATH)
BlockCheck(5,-5,3,GRASS,DIRT,SAND,GRAVEL,STAINED_HARDENED_CLAY,GRASS_PATH)
BlockCheck(-3,-5,4,GRASS,DIRT,SAND,GRAVEL,STAINED_HARDENED_CLAY,GRASS_PATH)
BlockCheck(-2,-5,4,GRASS,DIRT,SAND,GRAVEL,STAINED_HARDENED_CLAY,GRASS_PATH)
BlockCheck(-1,-5,4,GRASS,DIRT,SAND,GRAVEL,STAINED_HARDENED_CLAY,GRASS_PATH)
BlockCheck(0,-5,4,GRASS,DIRT,SAND,GRAVEL,STAINED_HARDENED_CLAY,GRASS_PATH)
BlockCheck(1,-5,4,GRASS,DIRT,SAND,GRAVEL,STAINED_HARDENED_CLAY,GRASS_PATH)
BlockCheck(2,-5,4,GRASS,DIRT,SAND,GRAVEL,STAINED_HARDENED_CLAY,GRASS_PATH)
BlockCheck(3,-5,4,GRASS,DIRT,SAND,GRAVEL,STAINED_HARDENED_CLAY,GRASS_PATH)
BlockCheck(4,-5,4,GRASS,DIRT,SAND,GRAVEL,STAINED_HARDENED_CLAY,GRASS_PATH)
BlockCheck(5,-5,4,GRASS,DIRT,SAND,GRAVEL,STAINED_HARDENED_CLAY,GRASS_PATH)
BlockCheck(6,-4,2,GRASS,DIRT,SAND,GRAVEL,STAINED_HARDENED_CLAY,GRASS_PATH)
BlockCheck(-3,-4,3,GRASS,DIRT,SAND,GRAVEL,STAINED_HARDENED_CLAY,GRASS_PATH)
BlockCheck(5,-4,3,GRASS,DIRT,SAND,GRAVEL,STAINED_HARDENED_CLAY,GRASS_PATH)
BlockCheck(-2,-4,4,GRASS,DIRT,SAND,GRAVEL,STAINED_HARDENED_CLAY,GRASS_PATH)
BlockCheck(4,-4,4,GRASS,DIRT,SAND,GRAVEL,STAINED_HARDENED_CLAY,GRASS_PATH)
BlockCheck(-2,-4,5,GRASS,DIRT,SAND,GRAVEL,STAINED_HARDENED_CLAY,GRASS_PATH)
BlockCheck(-1,-4,5,GRASS,DIRT,SAND,GRAVEL,STAINED_HARDENED_CLAY,GRASS_PATH)
BlockCheck(0,-4,5,GRASS,DIRT,SAND,GRAVEL,STAINED_HARDENED_CLAY,GRASS_PATH)
BlockCheck(1,-4,5,GRASS,DIRT,SAND,GRAVEL,STAINED_HARDENED_CLAY,GRASS_PATH)
BlockCheck(2,-4,5,GRASS,DIRT,SAND,GRAVEL,STAINED_HARDENED_CLAY,GRASS_PATH)
BlockCheck(-1,-4,6,GRASS,DIRT,SAND,GRAVEL,STAINED_HARDENED_CLAY,GRASS_PATH)
BlockCheck(6,-3,2,GRASS,DIRT,SAND,GRAVEL,STAINED_HARDENED_CLAY,GRASS_PATH)
BlockCheck(-3,-3,3,GRASS,DIRT,SAND,GRAVEL,STAINED_HARDENED_CLAY,GRASS_PATH)
BlockCheck(5,-3,3,GRASS,DIRT,SAND,GRAVEL,STAINED_HARDENED_CLAY,GRASS_PATH)
BlockCheck(-2,-3,4,GRASS,DIRT,SAND,GRAVEL,STAINED_HARDENED_CLAY,GRASS_PATH)
BlockCheck(4,-3,4,GRASS,DIRT,SAND,GRAVEL,STAINED_HARDENED_CLAY,GRASS_PATH)
BlockCheck(-2,-3,5,GRASS,DIRT,SAND,GRAVEL,STAINED_HARDENED_CLAY,GRASS_PATH)
BlockCheck(-1,-3,5,GRASS,DIRT,SAND,GRAVEL,STAINED_HARDENED_CLAY,GRASS_PATH)
BlockCheck(0,-3,5,GRASS,DIRT,SAND,GRAVEL,STAINED_HARDENED_CLAY,GRASS_PATH)
BlockCheck(1,-3,5,GRASS,DIRT,SAND,GRAVEL,STAINED_HARDENED_CLAY,GRASS_PATH)
BlockCheck(2,-3,5,GRASS,DIRT,SAND,GRAVEL,STAINED_HARDENED_CLAY,GRASS_PATH)
BlockCheck(-1,-3,6,GRASS,DIRT,SAND,GRAVEL,STAINED_HARDENED_CLAY,GRASS_PATH)
BlockCheck(-2,-2,7,GRASS,DIRT,SAND,GRAVEL,STAINED_HARDENED_CLAY,GRASS_PATH)
BlockCheck(-1,-2,7,GRASS,DIRT,SAND,GRAVEL,STAINED_HARDENED_CLAY,GRASS_PATH)
BlockCheck(0,-2,7,GRASS,DIRT,SAND,GRAVEL,STAINED_HARDENED_CLAY,GRASS_PATH)
BlockCheck(1,-2,7,GRASS,DIRT,SAND,GRAVEL,STAINED_HARDENED_CLAY,GRASS_PATH)

