Author: Bo3 BulkEdit

Description: Converted Schematic - Modified by Bo3BulkEdit

Version: 3

SettingsMode: WriteDisable

IsOTGPlus: false
Tree: false
Frequency: 1
Rarity: 100
RotateRandomly: false
SpawnHeight: randomY
MaxBranchDepth: 20
ExcludedBiomes: All

MinHeight: 0
MaxHeight: 256

SourceBlocks: AIR
MaxPercentageOutsideSourceBlock: 100
OutsideSourceBlock: placeAnyway

B(-2,-8,-7,PLANKS:1)
B(-1,-8,-7,PLANKS:1)
B(0,-8,-7,PLANKS:1)
B(1,-8,-7,PLANKS:1)
B(2,-8,-7,PLANKS:1)
B(-2,-8,-6,PLANKS:1)
B(-1,-8,-6,PLANKS:1)
B(0,-8,-6,PLANKS:1)
B(1,-8,-6,PLANKS:1)
B(2,-8,-6,PLANKS:1)
B(-1,-8,-5,PLANKS:1)
B(0,-8,-5,PLANKS:1)
B(1,-8,-5,PLANKS:1)
B(-1,-8,-4,PLANKS:1)
B(0,-8,-4,PLANKS:1)
B(1,-8,-4,PLANKS:1)
B(-1,-8,-3,PLANKS:1)
B(0,-8,-3,PLANKS:1)
B(1,-8,-3,PLANKS:1)
B(-1,-8,-2,PLANKS:1)
B(0,-8,-2,PLANKS:1)
B(1,-8,-2,PLANKS:1)
B(-1,-8,-1,PLANKS:1)
B(0,-8,-1,PLANKS:1)
B(1,-8,-1,PLANKS:1)
B(-1,-8,0,PLANKS:1)
B(0,-8,0,PLANKS:1)
B(1,-8,0,PLANKS:1)
B(0,-8,1,PLANKS:1)
B(0,-8,2,PLANKS:1)
B(0,-8,3,PLANKS:1)
B(0,-8,4,PLANKS:1)
B(0,-8,5,PLANKS:1)
B(0,-8,6,PLANKS:1)
B(0,-8,7,PLANKS:1)
B(0,-8,8,PLANKS:1)
B(-4,-7,-7,PLANKS:1)
B(-3,-7,-7,PLANKS:1)
B(-2,-7,-7,WATER:0)
B(-1,-7,-7,WATER:0)
B(0,-7,-7,WATER:0)
B(1,-7,-7,WATER:0)
B(2,-7,-7,WATER:0)
B(3,-7,-7,PLANKS:1)
B(4,-7,-7,PLANKS:1)
B(-4,-7,-6,PLANKS:1)
B(-3,-7,-6,PLANKS:1)
B(-2,-7,-6,WATER:0)
B(-1,-7,-6,WATER:0)
B(0,-7,-6,WATER:0)
B(1,-7,-6,WATER:0)
B(2,-7,-6,WATER:0)
B(3,-7,-6,PLANKS:1)
B(4,-7,-6,PLANKS:1)
B(-4,-7,-5,PLANKS:1)
B(-3,-7,-5,PLANKS:1)
B(-2,-7,-5,PLANKS:1)
B(-1,-7,-5,WATER:0)
B(0,-7,-5,WATER:0)
B(1,-7,-5,WATER:0)
B(2,-7,-5,PLANKS:1)
B(3,-7,-5,PLANKS:1)
B(4,-7,-5,PLANKS:1)
B(-4,-7,-4,PLANKS:1)
B(-3,-7,-4,PLANKS:1)
B(-2,-7,-4,PLANKS:1)
B(-1,-7,-4,PLANKS:1)
B(0,-7,-4,WATER:0)
B(1,-7,-4,PLANKS:1)
B(2,-7,-4,PLANKS:1)
B(3,-7,-4,PLANKS:1)
B(4,-7,-4,PLANKS:1)
B(-4,-7,-3,PLANKS:1)
B(-3,-7,-3,PLANKS:1)
B(-2,-7,-3,PLANKS:1)
B(-1,-7,-3,WATER:0)
B(0,-7,-3,WATER:0)
B(1,-7,-3,WATER:0)
B(2,-7,-3,PLANKS:1)
B(3,-7,-3,PLANKS:1)
B(4,-7,-3,PLANKS:1)
B(-4,-7,-2,PLANKS:1)
B(-3,-7,-2,PLANKS:1)
B(-2,-7,-2,PLANKS:1)
B(-1,-7,-2,WATER:0)
B(0,-7,-2,WATER:0)
B(1,-7,-2,WATER:0)
B(2,-7,-2,PLANKS:1)
B(3,-7,-2,PLANKS:1)
B(4,-7,-2,PLANKS:1)
B(-4,-7,-1,PLANKS:1)
B(-3,-7,-1,PLANKS:1)
B(-2,-7,-1,PLANKS:1)
B(-1,-7,-1,PLANKS:1)
B(0,-7,-1,PLANKS:1)
B(1,-7,-1,PLANKS:1)
B(2,-7,-1,PLANKS:1)
B(3,-7,-1,PLANKS:1)
B(4,-7,-1,PLANKS:1)
B(-4,-7,0,PLANKS:1)
B(-3,-7,0,PLANKS:1)
B(-2,-7,0,PLANKS:1)
B(-1,-7,0,PLANKS:1)
B(0,-7,0,LOG:1)
B(1,-7,0,PLANKS:1)
B(2,-7,0,PLANKS:1)
B(3,-7,0,PLANKS:1)
B(4,-7,0,PLANKS:1)
B(-3,-7,1,PLANKS:1)
B(-2,-7,1,PLANKS:1)
B(-1,-7,1,PLANKS:1)
B(0,-7,1,PLANKS:1)
B(1,-7,1,PLANKS:1)
B(2,-7,1,PLANKS:1)
B(3,-7,1,PLANKS:1)
B(-3,-7,2,PLANKS:1)
B(-2,-7,2,PLANKS:1)
B(-1,-7,2,PLANKS:1)
B(0,-7,2,PLANKS:1)
B(1,-7,2,PLANKS:1)
B(2,-7,2,PLANKS:1)
B(3,-7,2,PLANKS:1)
B(-2,-7,3,PLANKS:1)
B(-1,-7,3,PLANKS:1)
B(0,-7,3,PLANKS:1)
B(1,-7,3,PLANKS:1)
B(2,-7,3,PLANKS:1)
B(-2,-7,4,PLANKS:1)
B(-1,-7,4,PLANKS:1)
B(0,-7,4,PLANKS:1)
B(1,-7,4,PLANKS:1)
B(2,-7,4,PLANKS:1)
B(-2,-7,5,PLANKS:1)
B(-1,-7,5,PLANKS:1)
B(0,-7,5,PLANKS:1)
B(1,-7,5,PLANKS:1)
B(2,-7,5,PLANKS:1)
B(-1,-7,6,PLANKS:1)
B(0,-7,6,PLANKS:1)
B(1,-7,6,PLANKS:1)
B(-1,-7,7,PLANKS:1)
B(0,-7,7,PLANKS:1)
B(1,-7,7,PLANKS:1)
B(-1,-7,8,PLANKS:1)
B(0,-7,8,PLANKS:1)
B(1,-7,8,PLANKS:1)
B(-5,-6,-7,PLANKS:1)
B(-4,-6,-7,WATER:0)
B(-3,-6,-7,WATER:0)
B(-2,-6,-7,WATER:0)
B(-1,-6,-7,WATER:0)
B(0,-6,-7,WATER:0)
B(1,-6,-7,WATER:0)
B(2,-6,-7,WATER:0)
B(5,-6,-7,PLANKS:1)
B(-5,-6,-6,PLANKS:1)
B(-4,-6,-6,WATER:0)
B(-3,-6,-6,WATER:0)
B(-2,-6,-6,WATER:0)
B(-1,-6,-6,WATER:0)
B(0,-6,-6,WATER:0)
B(1,-6,-6,WATER:0)
B(2,-6,-6,WATER:0)
B(3,-6,-6,SPRUCE_FENCE:0)
B(5,-6,-6,PLANKS:1)
B(-5,-6,-5,PLANKS:1)
B(-4,-6,-5,WATER:0)
B(-3,-6,-5,WATER:0)
B(-2,-6,-5,WATER:0)
B(-1,-6,-5,WATER:0)
B(0,-6,-5,WATER:0)
B(1,-6,-5,WATER:0)
B(2,-6,-5,WATER:0)
B(3,-6,-5,WATER:0)
B(4,-6,-5,WATER:0)
B(5,-6,-5,PLANKS:1)
B(-5,-6,-4,PLANKS:1)
B(-4,-6,-4,PLANKS:1)
B(-3,-6,-4,PLANKS:1)
B(-2,-6,-4,PLANKS:1)
B(-1,-6,-4,PLANKS:1)
B(0,-6,-4,WATER:0)
B(1,-6,-4,PLANKS:1)
B(2,-6,-4,PLANKS:1)
B(3,-6,-4,PLANKS:1)
B(4,-6,-4,PLANKS:1)
B(5,-6,-4,PLANKS:1)
B(-5,-6,-3,PLANKS:1)
B(-4,-6,-3,WATER:0)
B(-3,-6,-3,WATER:0)
B(-2,-6,-3,WATER:0)
B(-1,-6,-3,WATER:0)
B(0,-6,-3,WATER:0)
B(1,-6,-3,WATER:0)
B(2,-6,-3,WATER:0)
B(3,-6,-3,WATER:0)
B(4,-6,-3,WATER:0)
B(5,-6,-3,PLANKS:1)
B(-5,-6,-2,PLANKS:1)
B(-4,-6,-2,WATER:0)
B(-3,-6,-2,WATER:0)
B(-2,-6,-2,WATER:0)
B(-1,-6,-2,WATER:0)
B(0,-6,-2,WATER:0)
B(1,-6,-2,WATER:0)
B(2,-6,-2,WATER:0)
B(3,-6,-2,WATER:0)
B(4,-6,-2,WATER:0)
B(5,-6,-2,PLANKS:1)
B(-4,-6,-1,PLANKS:1)
B(-3,-6,-1,WATER:0)
B(-2,-6,-1,WATER:0)
B(-1,-6,-1,WATER:0)
B(0,-6,-1,WATER:0)
B(1,-6,-1,WATER:0)
B(2,-6,-1,WATER:0)
B(3,-6,-1,WATER:0)
B(4,-6,-1,PLANKS:1)
B(-4,-6,0,PLANKS:1)
B(-3,-6,0,WATER:0)
B(-2,-6,0,WATER:0)
B(-1,-6,0,WATER:0)
B(0,-6,0,LOG:1)
B(1,-6,0,WATER:0)
B(2,-6,0,WATER:0)
B(3,-6,0,WATER:0)
B(4,-6,0,PLANKS:1)
B(-4,-6,1,PLANKS:1)
B(-3,-6,1,WATER:0)
B(-2,-6,1,WATER:0)
B(-1,-6,1,WATER:0)
B(0,-6,1,WATER:0)
B(1,-6,1,WATER:0)
B(2,-6,1,WATER:0)
B(3,-6,1,WATER:0)
B(4,-6,1,PLANKS:1)
B(-4,-6,2,PLANKS:1)
B(-3,-6,2,WATER:0)
B(-2,-6,2,WATER:0)
B(-1,-6,2,WATER:0)
B(0,-6,2,WATER:0)
B(1,-6,2,WATER:0)
B(2,-6,2,WATER:0)
B(3,-6,2,WATER:0)
B(4,-6,2,PLANKS:1)
B(-4,-6,3,PLANKS:1)
B(-3,-6,3,PLANKS:1)
B(-2,-6,3,PLANKS:1)
B(-1,-6,3,PLANKS:1)
B(0,-6,3,WATER:0)
B(1,-6,3,PLANKS:1)
B(2,-6,3,PLANKS:1)
B(3,-6,3,PLANKS:1)
B(4,-6,3,PLANKS:1)
B(-4,-6,4,PLANKS:1)
B(-3,-6,4,PLANKS:1)
B(-2,-6,4,WATER:0)
B(-1,-6,4,WATER:0)
B(0,-6,4,WATER:0)
B(1,-6,4,WATER:0)
B(2,-6,4,WATER:0)
B(3,-6,4,PLANKS:1)
B(4,-6,4,PLANKS:1)
B(-4,-6,5,PLANKS:1)
B(-3,-6,5,PLANKS:1)
B(-2,-6,5,WATER:0)
B(-1,-6,5,WATER:0)
B(0,-6,5,WATER:0)
B(1,-6,5,WATER:0)
B(2,-6,5,WATER:0)
B(3,-6,5,PLANKS:1)
B(4,-6,5,PLANKS:1)
B(-3,-6,6,PLANKS:1)
B(-2,-6,6,PLANKS:1)
B(-1,-6,6,WATER:0)
B(0,-6,6,WATER:0)
B(1,-6,6,WATER:0)
B(2,-6,6,PLANKS:1)
B(3,-6,6,PLANKS:1)
B(-3,-6,7,PLANKS:1)
B(-2,-6,7,PLANKS:1)
B(-1,-6,7,WATER:0)
B(0,-6,7,WATER:0)
B(1,-6,7,WATER:0)
B(2,-6,7,PLANKS:1)
B(3,-6,7,PLANKS:1)
B(-2,-6,8,PLANKS:1)
B(-1,-6,8,WATER:0)
B(0,-6,8,WATER:0)
B(1,-6,8,WATER:0)
B(2,-6,8,PLANKS:1)
B(-4,-5,-7,WATER:0)
B(-3,-5,-7,WATER:0)
B(-2,-5,-7,WATER:0)
B(-1,-5,-7,WATER:0)
B(0,-5,-7,WATER:0)
B(1,-5,-7,WATER:0)
B(2,-5,-7,WATER:0)
B(5,-5,-7,PLANKS:1)
B(-4,-5,-6,WATER:0)
B(-3,-5,-6,WATER:0)
B(-2,-5,-6,WATER:0)
B(-1,-5,-6,WATER:0)
B(0,-5,-6,WATER:0)
B(1,-5,-6,WATER:0)
B(2,-5,-6,WATER:0)
B(5,-5,-6,PLANKS:1)
B(-5,-5,-5,PLANKS:1)
B(-4,-5,-5,WATER:0)
B(-3,-5,-5,WATER:0)
B(-2,-5,-5,WATER:0)
B(-1,-5,-5,WATER:0)
B(0,-5,-5,WATER:0)
B(1,-5,-5,WATER:0)
B(2,-5,-5,WATER:0)
B(3,-5,-5,WATER:0)
B(4,-5,-5,WATER:0)
B(5,-5,-5,PLANKS:1)
B(-5,-5,-4,PLANKS:1)
B(-4,-5,-4,PLANKS:1)
B(-3,-5,-4,PLANKS:1)
B(-2,-5,-4,PLANKS:1)
B(-1,-5,-4,PLANKS:1)
B(0,-5,-4,PLANKS:1)
B(1,-5,-4,PLANKS:1)
B(2,-5,-4,PLANKS:1)
B(3,-5,-4,PLANKS:1)
B(4,-5,-4,PLANKS:1)
B(5,-5,-4,PLANKS:1)
B(-5,-5,-3,PLANKS:1)
B(-4,-5,-3,WATER:0)
B(-3,-5,-3,WATER:0)
B(-2,-5,-3,WATER:0)
B(-1,-5,-3,WATER:0)
B(0,-5,-3,WATER:0)
B(1,-5,-3,WATER:0)
B(2,-5,-3,WATER:0)
B(3,-5,-3,WATER:0)
B(4,-5,-3,WATER:0)
B(5,-5,-3,PLANKS:1)
B(-5,-5,-2,PLANKS:1)
B(-4,-5,-2,WATER:0)
B(-3,-5,-2,WATER:0)
B(-2,-5,-2,WATER:0)
B(-1,-5,-2,WATER:0)
B(0,-5,-2,WATER:0)
B(1,-5,-2,WATER:0)
B(2,-5,-2,WATER:0)
B(3,-5,-2,WATER:0)
B(4,-5,-2,WATER:0)
B(5,-5,-2,PLANKS:1)
B(-5,-5,-1,PLANKS:1)
B(-4,-5,-1,WATER:0)
B(-3,-5,-1,WATER:0)
B(-2,-5,-1,WATER:0)
B(-1,-5,-1,WATER:0)
B(0,-5,-1,WATER:0)
B(1,-5,-1,WATER:0)
B(2,-5,-1,WATER:0)
B(3,-5,-1,WATER:0)
B(4,-5,-1,WATER:0)
B(5,-5,-1,PLANKS:1)
B(-5,-5,0,PLANKS:1)
B(-4,-5,0,WATER:0)
B(-3,-5,0,WATER:0)
B(-2,-5,0,WATER:0)
B(-1,-5,0,WATER:0)
B(0,-5,0,LOG:1)
B(1,-5,0,WATER:0)
B(2,-5,0,WATER:0)
B(3,-5,0,WATER:0)
B(4,-5,0,WATER:0)
B(5,-5,0,PLANKS:1)
B(-5,-5,1,PLANKS:1)
B(-4,-5,1,WATER:0)
B(-3,-5,1,WATER:0)
B(-2,-5,1,WATER:0)
B(-1,-5,1,WATER:0)
B(0,-5,1,WATER:0)
B(1,-5,1,WATER:0)
B(2,-5,1,WATER:0)
B(3,-5,1,WATER:0)
B(4,-5,1,WATER:0)
B(5,-5,1,PLANKS:1)
B(-5,-5,2,PLANKS:1)
B(-4,-5,2,WATER:0)
B(-3,-5,2,WATER:0)
B(-2,-5,2,WATER:0)
B(-1,-5,2,WATER:0)
B(0,-5,2,WATER:0)
B(1,-5,2,WATER:0)
B(2,-5,2,WATER:0)
B(3,-5,2,WATER:0)
B(4,-5,2,WATER:0)
B(5,-5,2,PLANKS:1)
B(-4,-5,3,PLANKS:1)
B(-3,-5,3,PLANKS:1)
B(-2,-5,3,PLANKS:1)
B(-1,-5,3,PLANKS:1)
B(0,-5,3,WATER:0)
B(1,-5,3,PLANKS:1)
B(2,-5,3,PLANKS:1)
B(3,-5,3,PLANKS:1)
B(4,-5,3,PLANKS:1)
B(-4,-5,4,PLANKS:1)
B(-3,-5,4,WATER:0)
B(-2,-5,4,WATER:0)
B(-1,-5,4,WATER:0)
B(0,-5,4,WATER:0)
B(1,-5,4,WATER:0)
B(2,-5,4,WATER:0)
B(3,-5,4,WATER:0)
B(4,-5,4,PLANKS:1)
B(-4,-5,5,PLANKS:1)
B(-3,-5,5,WATER:0)
B(-2,-5,5,WATER:0)
B(-1,-5,5,WATER:0)
B(0,-5,5,WATER:0)
B(1,-5,5,WATER:0)
B(2,-5,5,WATER:0)
B(3,-5,5,WATER:0)
B(4,-5,5,PLANKS:1)
B(-4,-5,6,PLANKS:1)
B(-3,-5,6,WATER:0)
B(-2,-5,6,WATER:0)
B(-1,-5,6,WATER:0)
B(0,-5,6,WATER:0)
B(1,-5,6,WATER:0)
B(2,-5,6,WATER:0)
B(3,-5,6,WATER:0)
B(4,-5,6,PLANKS:1)
B(-4,-5,7,PLANKS:1)
B(-3,-5,7,WATER:0)
B(-2,-5,7,WATER:0)
B(-1,-5,7,WATER:0)
B(0,-5,7,WATER:0)
B(1,-5,7,WATER:0)
B(2,-5,7,WATER:0)
B(3,-5,7,WATER:0)
B(4,-5,7,PLANKS:1)
B(-4,-5,8,PLANKS:1)
B(-3,-5,8,PLANKS:1)
B(-2,-5,8,WATER:0)
B(-1,-5,8,WATER:0)
B(0,-5,8,WATER:0)
B(1,-5,8,WATER:0)
B(2,-5,8,WATER:0)
B(3,-5,8,PLANKS:1)
B(4,-5,8,PLANKS:1)
B(-4,-4,-7,WATER:0)
B(-3,-4,-7,WATER:0)
B(-2,-4,-7,WOODEN_SLAB:8)
B(-1,-4,-7,WOODEN_SLAB:8)
B(0,-4,-7,WOODEN_SLAB:8)
B(1,-4,-7,WOODEN_SLAB:8)
B(2,-4,-7,WATER:0)
B(-4,-4,-6,WATER:0)
B(-3,-4,-6,WATER:0)
B(-2,-4,-6,WOODEN_SLAB:8)
B(-1,-4,-6,WOODEN_SLAB:8)
B(0,-4,-6,WOODEN_SLAB:8)
B(1,-4,-6,WOODEN_SLAB:8)
B(2,-4,-6,WOODEN_SLAB:8)
B(5,-4,-6,PLANKS:5)
B(-5,-4,-5,PLANKS:5)
B(-4,-4,-5,WOODEN_SLAB:8)
B(-3,-4,-5,WOODEN_SLAB:8)
B(-2,-4,-5,WOODEN_SLAB:8)
B(-1,-4,-5,WOODEN_SLAB:8)
B(0,-4,-5,WOODEN_SLAB:8)
B(1,-4,-5,WOODEN_SLAB:8)
B(2,-4,-5,WOODEN_SLAB:8)
B(3,-4,-5,WOODEN_SLAB:8)
B(4,-4,-5,WOODEN_SLAB:8)
B(5,-4,-5,PLANKS:5)
B(-5,-4,-4,PLANKS:5)
B(-4,-4,-4,DOUBLE_WOODEN_SLAB:0)
B(-3,-4,-4,DOUBLE_WOODEN_SLAB:0)
B(-2,-4,-4,DOUBLE_WOODEN_SLAB:0)
B(-1,-4,-4,DOUBLE_WOODEN_SLAB:0)
B(0,-4,-4,DOUBLE_WOODEN_SLAB:0)
B(1,-4,-4,DOUBLE_WOODEN_SLAB:0)
B(2,-4,-4,DOUBLE_WOODEN_SLAB:0)
B(3,-4,-4,DOUBLE_WOODEN_SLAB:0)
B(4,-4,-4,DOUBLE_WOODEN_SLAB:0)
B(5,-4,-4,PLANKS:5)
B(-5,-4,-3,PLANKS:5)
B(-4,-4,-3,WOODEN_SLAB:8)
B(-3,-4,-3,WOODEN_SLAB:8)
B(-2,-4,-3,WOODEN_SLAB:8)
B(-1,-4,-3,WOODEN_SLAB:8)
B(0,-4,-3,WOODEN_SLAB:8)
B(1,-4,-3,WOODEN_SLAB:8)
B(2,-4,-3,WOODEN_SLAB:8)
B(3,-4,-3,WOODEN_SLAB:8)
B(4,-4,-3,WOODEN_SLAB:8)
B(5,-4,-3,PLANKS:5)
B(-5,-4,-2,PLANKS:5)
B(-4,-4,-2,WOODEN_SLAB:8)
B(-3,-4,-2,WOODEN_SLAB:8)
B(-2,-4,-2,WOODEN_SLAB:8)
B(-1,-4,-2,WOODEN_SLAB:8)
B(0,-4,-2,WOODEN_SLAB:8)
B(1,-4,-2,WOODEN_SLAB:8)
B(2,-4,-2,WOODEN_SLAB:8)
B(3,-4,-2,WOODEN_SLAB:8)
B(4,-4,-2,WOODEN_SLAB:8)
B(5,-4,-2,PLANKS:5)
B(-5,-4,-1,PLANKS:5)
B(-4,-4,-1,WOODEN_SLAB:8)
B(-3,-4,-1,WOODEN_SLAB:8)
B(-2,-4,-1,WOODEN_SLAB:8)
B(-1,-4,-1,WOODEN_SLAB:8)
B(0,-4,-1,WOODEN_SLAB:8)
B(1,-4,-1,WOODEN_SLAB:8)
B(2,-4,-1,WOODEN_SLAB:8)
B(3,-4,-1,WOODEN_SLAB:8)
B(4,-4,-1,WOODEN_SLAB:8)
B(5,-4,-1,PLANKS:5)
B(-5,-4,0,PLANKS:5)
B(-4,-4,0,WOODEN_SLAB:8)
B(-3,-4,0,WOODEN_SLAB:8)
B(-2,-4,0,WOODEN_SLAB:8)
B(-1,-4,0,WOODEN_SLAB:8)
B(0,-4,0,LOG:1)
B(1,-4,0,WOODEN_SLAB:8)
B(2,-4,0,WOODEN_SLAB:8)
B(3,-4,0,WOODEN_SLAB:8)
B(4,-4,0,WOODEN_SLAB:8)
B(5,-4,0,PLANKS:5)
B(-5,-4,1,PLANKS:5)
B(-4,-4,1,WOODEN_SLAB:8)
B(-3,-4,1,WOODEN_SLAB:8)
B(-2,-4,1,WOODEN_SLAB:8)
B(-1,-4,1,WOODEN_SLAB:8)
B(0,-4,1,WOODEN_SLAB:8)
B(1,-4,1,WOODEN_SLAB:8)
B(2,-4,1,WOODEN_SLAB:8)
B(3,-4,1,WOODEN_SLAB:8)
B(4,-4,1,WOODEN_SLAB:8)
B(5,-4,1,PLANKS:5)
B(-5,-4,2,PLANKS:5)
B(-4,-4,2,WOODEN_SLAB:8)
B(-3,-4,2,WOODEN_SLAB:8)
B(-2,-4,2,WOODEN_SLAB:8)
B(-1,-4,2,WOODEN_SLAB:8)
B(0,-4,2,WOODEN_SLAB:8)
B(1,-4,2,WOODEN_SLAB:8)
B(2,-4,2,WOODEN_SLAB:8)
B(3,-4,2,WOODEN_SLAB:8)
B(4,-4,2,WOODEN_SLAB:8)
B(5,-4,2,PLANKS:5)
B(-4,-4,3,PLANKS:5)
B(-3,-4,3,DOUBLE_WOODEN_SLAB:0)
B(-2,-4,3,DOUBLE_WOODEN_SLAB:0)
B(-1,-4,3,DOUBLE_WOODEN_SLAB:0)
B(0,-4,3,DOUBLE_WOODEN_SLAB:0)
B(1,-4,3,DOUBLE_WOODEN_SLAB:0)
B(2,-4,3,DOUBLE_WOODEN_SLAB:0)
B(3,-4,3,DOUBLE_WOODEN_SLAB:0)
B(4,-4,3,PLANKS:5)
B(-4,-4,4,PLANKS:5)
B(-3,-4,4,WOODEN_SLAB:8)
B(-2,-4,4,WOODEN_SLAB:8)
B(-1,-4,4,WOODEN_SLAB:8)
B(0,-4,4,WOODEN_SLAB:8)
B(1,-4,4,WOODEN_SLAB:8)
B(2,-4,4,WOODEN_SLAB:8)
B(3,-4,4,WOODEN_SLAB:8)
B(4,-4,4,PLANKS:5)
B(-4,-4,5,PLANKS:5)
B(-3,-4,5,WOODEN_SLAB:8)
B(-2,-4,5,WOODEN_SLAB:8)
B(-1,-4,5,WOODEN_SLAB:8)
B(0,-4,5,WOODEN_SLAB:8)
B(1,-4,5,WOODEN_SLAB:8)
B(2,-4,5,WOODEN_SLAB:8)
B(3,-4,5,WOODEN_SLAB:8)
B(4,-4,5,PLANKS:5)
B(-4,-4,6,PLANKS:1)
B(-3,-4,6,WOODEN_SLAB:8)
B(-2,-4,6,WOODEN_SLAB:8)
B(-1,-4,6,WOODEN_SLAB:8)
B(0,-4,6,WOODEN_SLAB:8)
B(1,-4,6,WOODEN_SLAB:8)
B(2,-4,6,WOODEN_SLAB:8)
B(3,-4,6,WOODEN_SLAB:8)
B(4,-4,6,PLANKS:1)
B(-4,-4,7,PLANKS:1)
B(-3,-4,7,WOODEN_SLAB:8)
B(-2,-4,7,WOODEN_SLAB:8)
B(-1,-4,7,WATER:0)
B(0,-4,7,WOODEN_SLAB:8)
B(1,-4,7,WOODEN_SLAB:8)
B(2,-4,7,WOODEN_SLAB:8)
B(3,-4,7,WOODEN_SLAB:8)
B(4,-4,7,PLANKS:1)
B(-4,-4,8,PLANKS:1)
B(-3,-4,8,WOODEN_SLAB:8)
B(-2,-4,8,WATER:0)
B(-1,-4,8,WATER:0)
B(0,-4,8,WATER:0)
B(1,-4,8,WOODEN_SLAB:8)
B(2,-4,8,WOODEN_SLAB:8)
B(3,-4,8,WOODEN_SLAB:8)
B(4,-4,8,PLANKS:1)
B(-4,-3,-7,WATER:0)
B(-3,-3,-7,WATER:0)
B(-2,-3,-7,WATER:0)
B(-1,-3,-7,WATER:0)
B(0,-3,-7,WATER:0)
B(1,-3,-7,WATER:0)
B(2,-3,-7,WATER:0)
B(-4,-3,-6,WATER:0)
B(-3,-3,-6,WATER:0)
B(-2,-3,-6,WATER:0)
B(-1,-3,-6,WATER:0)
B(0,-3,-6,WATER:0)
B(1,-3,-6,WATER:0)
B(2,-3,-6,WATER:0)
B(-4,-3,-5,WATER:0)
B(-3,-3,-5,WATER:0)
B(-2,-3,-5,WATER:0)
B(-1,-3,-5,PLANKS:2)
B(0,-3,-5,PLANKS:2)
B(1,-3,-5,PLANKS:2)
B(3,-3,-5,SPRUCE_STAIRS:0)
B(4,-3,-5,DISPENSER:1)
B(5,-3,-5,CONCRETE:15)
B(6,-3,-5,DISPENSER:5)
B(-5,-3,-4,PLANKS:5)
B(-4,-3,-4,WATER:0)
B(-3,-3,-4,WATER:0)
B(-2,-3,-4,WATER:0)
B(-1,-3,-4,PLANKS:2)
B(0,-3,-4,PLANKS:2)
B(1,-3,-4,PLANKS:2)
B(5,-3,-4,PLANKS:5)
B(-5,-3,-3,PLANKS:5)
B(-4,-3,-3,WATER:0)
B(-3,-3,-3,WATER:0)
B(-2,-3,-3,WATER:0)
B(-1,-3,-3,PLANKS:2)
B(0,-3,-3,PLANKS:2)
B(1,-3,-3,PLANKS:2)
B(5,-3,-3,PLANKS:5)
B(-6,-3,-2,DISPENSER:4)
B(-5,-3,-2,CONCRETE:15)
B(-4,-3,-2,DISPENSER:1)
B(-3,-3,-2,SPRUCE_STAIRS:1)
B(-2,-3,-2,WATER:0)
B(-1,-3,-2,WATER:0)
B(0,-3,-2,WATER:0)
B(1,-3,-2,WATER:0)
B(3,-3,-2,SPRUCE_STAIRS:0)
B(4,-3,-2,DISPENSER:1)
B(5,-3,-2,CONCRETE:15)
B(6,-3,-2,DISPENSER:5)
B(-5,-3,-1,PLANKS:5)
B(-4,-3,-1,WATER:0)
B(-3,-3,-1,WATER:0)
B(-2,-3,-1,WATER:0)
B(-1,-3,-1,WATER:0)
B(0,-3,-1,WATER:0)
B(1,-3,-1,WATER:0)
B(5,-3,-1,PLANKS:5)
B(-5,-3,0,PLANKS:5)
B(-4,-3,0,WATER:0)
B(-3,-3,0,WATER:0)
B(-2,-3,0,WATER:0)
B(-1,-3,0,WATER:0)
B(0,-3,0,LOG:1)
B(1,-3,0,WATER:0)
B(2,-3,0,WATER:0)
B(5,-3,0,PLANKS:5)
B(-6,-3,1,DISPENSER:4)
B(-5,-3,1,CONCRETE:15)
B(-4,-3,1,DISPENSER:1)
B(-3,-3,1,SPRUCE_STAIRS:1)
B(-2,-3,1,WATER:0)
B(-1,-3,1,WATER:0)
B(0,-3,1,WATER:0)
B(1,-3,1,WATER:0)
B(2,-3,1,WATER:0)
B(3,-3,1,SPRUCE_STAIRS:0)
B(4,-3,1,DISPENSER:1)
B(5,-3,1,CONCRETE:15)
B(6,-3,1,DISPENSER:5)
B(-5,-3,2,PLANKS:5)
B(-4,-3,2,WATER:0)
B(-3,-3,2,WATER:0)
B(-2,-3,2,WATER:0)
B(-1,-3,2,WATER:0)
B(0,-3,2,WATER:0)
B(1,-3,2,WATER:0)
B(2,-3,2,WATER:0)
B(3,-3,2,WATER:0)
B(4,-3,2,WATER:0)
B(5,-3,2,PLANKS:5)
B(-5,-3,3,PLANKS:5)
B(-4,-3,3,WATER:0)
B(-3,-3,3,WATER:0)
B(-2,-3,3,WATER:0)
B(-1,-3,3,PLANKS:2)
B(0,-3,3,PLANKS:2)
B(1,-3,3,WATER:0)
B(2,-3,3,WATER:0)
B(3,-3,3,WATER:0)
B(4,-3,3,WATER:0)
B(5,-3,3,PLANKS:5)
B(-5,-3,4,DISPENSER:4)
B(-4,-3,4,CONCRETE:15)
B(-3,-3,4,DISPENSER:1)
B(-2,-3,4,SPRUCE_STAIRS:1)
B(-1,-3,4,PLANKS:2)
B(0,-3,4,PLANKS:2)
B(1,-3,4,WATER:0)
B(2,-3,4,SPRUCE_STAIRS:0)
B(3,-3,4,DISPENSER:1)
B(4,-3,4,CONCRETE:15)
B(5,-3,4,DISPENSER:5)
B(-4,-3,5,PLANKS:5)
B(-3,-3,5,PLANKS:1)
B(-2,-3,5,PLANKS:1)
B(-1,-3,5,PLANKS:1)
B(0,-3,5,IRON_DOOR:3)
B(1,-3,5,PLANKS:1)
B(2,-3,5,PLANKS:1)
B(3,-3,5,PLANKS:1)
B(4,-3,5,PLANKS:5)
B(-4,-3,6,PLANKS:5)
B(-3,-3,6,CRAFTING_TABLE:0)
B(-2,-3,6,AIR:0)
B(-1,-3,6,AIR:0)
B(0,-3,6,AIR:0)
B(1,-3,6,AIR:0)
B(2,-3,6,AIR:0)
RB(3,-3,6,CHEST:3,../NBT/StructureLoot/JunkChest_1.nbt,15,CHEST:3,../NBT/StructureLoot/JunkChest_2.nbt,15,CHEST:3,../NBT/StructureLoot/JunkChest_3.nbt,15,CHEST:3,../NBT/StructureLoot/JunkChest_4.nbt,15,CHEST:3,../NBT/StructureLoot/JunkChest_5.nbt,15,CHEST:3,../NBT/StructureLoot/Common1.nbt,15,CHEST:3,../NBT/StructureLoot/Common2.nbt,15,CHEST:3,../NBT/StructureLoot/Common3.nbt,15,CHEST:3,../NBT/StructureLoot/Common4.nbt,15,CHEST:3,../NBT/StructureLoot/Common5.nbt,15,CHEST:3,../NBT/StructureLoot/Common6.nbt,15,CHEST:3,../NBT/StructureLoot/Common7.nbt,15,CHEST:3,../NBT/StructureLoot/Common8.nbt,15,CHEST:3,../NBT/StructureLoot/Common9.nbt,15,CHEST:3,../NBT/StructureLoot/Common10.nbt,15,CHEST:3,../NBT/StructureLoot/Common11.nbt,15,CHEST:3,../NBT/StructureLoot/Common12.nbt,15,CHEST:3,../NBT/StructureLoot/Common13.nbt,15,CHEST:3,../NBT/StructureLoot/Common14.nbt,15,CHEST:3,../NBT/StructureLoot/Common15.nbt,100)
B(4,-3,6,PLANKS:5)
B(-5,-3,7,DARK_OAK_STAIRS:6)
B(-4,-3,7,PLANKS:5)
B(-3,-3,7,AIR:0)
B(-2,-3,7,AIR:0)
B(-1,-3,7,AIR:0)
B(0,-3,7,AIR:0)
B(1,-3,7,DARK_OAK_STAIRS:0)
B(2,-3,7,AIR:0)
B(3,-3,7,AIR:0)
B(4,-3,7,PLANKS:5)
B(5,-3,7,DARK_OAK_STAIRS:6)
B(-5,-3,8,DARK_OAK_STAIRS:4)
RB(-4,-3,8,CHEST:5,../NBT/StructureLoot/JunkChest_1.nbt,15,CHEST:5,../NBT/StructureLoot/JunkChest_2.nbt,15,CHEST:5,../NBT/StructureLoot/JunkChest_3.nbt,15,CHEST:5,../NBT/StructureLoot/JunkChest_4.nbt,15,CHEST:5,../NBT/StructureLoot/JunkChest_5.nbt,15,CHEST:5,../NBT/StructureLoot/Common1.nbt,15,CHEST:5,../NBT/StructureLoot/Common2.nbt,15,CHEST:5,../NBT/StructureLoot/Common3.nbt,15,CHEST:5,../NBT/StructureLoot/Common4.nbt,15,CHEST:5,../NBT/StructureLoot/Common5.nbt,15,CHEST:5,../NBT/StructureLoot/Common6.nbt,15,CHEST:5,../NBT/StructureLoot/Common7.nbt,15,CHEST:5,../NBT/StructureLoot/Common8.nbt,15,CHEST:5,../NBT/StructureLoot/Common9.nbt,15,CHEST:5,../NBT/StructureLoot/Common10.nbt,15,CHEST:5,../NBT/StructureLoot/Common11.nbt,15,CHEST:5,../NBT/StructureLoot/Common12.nbt,15,CHEST:5,../NBT/StructureLoot/Common13.nbt,15,CHEST:5,../NBT/StructureLoot/Common14.nbt,15,CHEST:5,../NBT/StructureLoot/Common15.nbt,100)
B(-3,-3,8,AIR:0)
B(-2,-3,8,AIR:0)
B(-1,-3,8,AIR:0)
B(0,-3,8,AIR:0)
B(1,-3,8,AIR:0)
B(2,-3,8,AIR:0)
B(3,-3,8,AIR:0)
RB(4,-3,8,CHEST:4,../NBT/LoreStoryline/LoreGeneric_5.nbt,2,CHEST:4,../NBT/LoreStoryline/LoreGeneric_4.nbt,2,CHEST:4,../NBT/LoreStoryline/LoreGeneric_3.nbt,2,CHEST:4,../NBT/LoreStoryline/LoreGeneric_2.nbt,2,CHEST:4,../NBT/LoreStoryline/LoreGeneric_1.nbt,2,CHEST:4,../NBT/LoreStoryline/LoreShipSunk_5.nbt,3,CHEST:4,../NBT/LoreStoryline/LoreShipSunk_4.nbt,3,CHEST:4,../NBT/LoreStoryline/LoreShipSunk_3.nbt,3,CHEST:4,../NBT/LoreStoryline/LoreShipSunk_2.nbt,3,CHEST:4,../NBT/LoreStoryline/LoreShipSunk_1.nbt,3,CHEST:4,../NBT/StructureLoot/Common1.nbt,3,CHEST:4,../NBT/StructureLoot/Common2.nbt,3,CHEST:4,../NBT/StructureLoot/Common3.nbt,3,CHEST:4,../NBT/StructureLoot/Common4.nbt,3,CHEST:4,../NBT/StructureLoot/Common5.nbt,3,CHEST:4,../NBT/StructureLoot/Common5.nbt,3,CHEST:4,../NBT/StructureLoot/Common6.nbt,3,CHEST:4,../NBT/StructureLoot/Common7.nbt,3,CHEST:4,../NBT/StructureLoot/Common8.nbt,3,CHEST:4,../NBT/StructureLoot/Common9.nbt,3,CHEST:4,../NBT/StructureLoot/Common10.nbt,3,CHEST:4,../NBT/StructureLoot/Common11.nbt,3,CHEST:4,../NBT/StructureLoot/Common12.nbt,3,CHEST:4,../NBT/StructureLoot/Common13.nbt,3,CHEST:4,../NBT/StructureLoot/Common14.nbt,3,CHEST:4,../NBT/StructureLoot/Common15.nbt,3,CHEST:4,../NBT/StructureLoot/Rare1.nbt,3,CHEST:4,../NBT/StructureLoot/Rare2.nbt,3,CHEST:4,../NBT/StructureLoot/Rare3.nbt,3,CHEST:4,../NBT/StructureLoot/Rare4.nbt,3,CHEST:4,../NBT/StructureLoot/Rare5.nbt,3,CHEST:4,../NBT/StructureLoot/Rare6.nbt,3,CHEST:4,../NBT/StructureLoot/Rare7.nbt,3,CHEST:4,../NBT/StructureLoot/Rare8.nbt,3,CHEST:4,../NBT/StructureLoot/Rare9.nbt,3,CHEST:4,../NBT/StructureLoot/Rare10.nbt,3,CHEST:4,../NBT/StructureLoot/Rare11.nbt,3,CHEST:4,../NBT/StructureLoot/Rare12.nbt,3,CHEST:4,../NBT/StructureLoot/Rare13.nbt,3,CHEST:4,../NBT/StructureLoot/Rare14.nbt,3,CHEST:4,../NBT/StructureLoot/Rare15.nbt,3,CHEST:4,../NBT/StructureLoot/Epic1.nbt,3,CHEST:4,../NBT/StructureLoot/Epic2.nbt,3,CHEST:4,../NBT/StructureLoot/Epic3.nbt,3,CHEST:4,../NBT/StructureLoot/Epic4.nbt,3,CHEST:4,../NBT/StructureLoot/Epic5.nbt,3,CHEST:4,../NBT/StructureLoot/Epic6.nbt,3,CHEST:4,../NBT/StructureLoot/Epic7.nbt,3,CHEST:4,../NBT/StructureLoot/Epic8.nbt,3,CHEST:4,../NBT/StructureLoot/Epic9.nbt,3,CHEST:4,../NBT/StructureLoot/Epic10.nbt,3,CHEST:4,../NBT/StructureLoot/Epic11.nbt,3,CHEST:4,../NBT/StructureLoot/Epic12.nbt,3,CHEST:4,../NBT/StructureLoot/Epic13.nbt,3,CHEST:4,../NBT/StructureLoot/Epic14.nbt,3,CHEST:4,../NBT/StructureLoot/Epic15.nbt,1,CHEST:4,../NBT/StructureLoot/Common15.nbt,100)
B(5,-3,8,DARK_OAK_STAIRS:5)
B(-4,-2,-7,WATER:0)
B(-3,-2,-7,WATER:0)
B(-2,-2,-7,WATER:0)
B(-1,-2,-7,WATER:0)
B(0,-2,-7,WATER:0)
B(1,-2,-7,WATER:0)
B(2,-2,-7,WATER:0)
B(-4,-2,-6,WATER:0)
B(-3,-2,-6,WATER:0)
B(-2,-2,-6,WATER:0)
B(-1,-2,-6,WATER:0)
B(0,-2,-6,WATER:0)
B(1,-2,-6,WATER:0)
B(2,-2,-6,WATER:0)
B(-4,-2,-5,WATER:0)
B(-3,-2,-5,WATER:0)
B(-2,-2,-5,WATER:0)
B(-1,-2,-5,PLANKS:2)
B(0,-2,-5,PLANKS:2)
B(1,-2,-5,PLANKS:2)
B(-5,-2,-4,PLANKS:0)
B(-4,-2,-4,WATER:0)
B(-3,-2,-4,WATER:0)
B(-2,-2,-4,WATER:0)
B(-1,-2,-4,PLANKS:2)
B(0,-2,-4,PLANKS:2)
B(1,-2,-4,PLANKS:2)
B(5,-2,-4,PLANKS:0)
B(-5,-2,-3,PLANKS:0)
B(-4,-2,-3,WATER:0)
B(-3,-2,-3,WATER:0)
B(-2,-2,-3,WATER:0)
B(-1,-2,-3,PLANKS:2)
B(0,-2,-3,PLANKS:2)
B(1,-2,-3,PLANKS:2)
B(5,-2,-3,PLANKS:0)
B(-6,-2,-2,WOODEN_SLAB:8)
B(-4,-2,-2,WATER:0)
B(-3,-2,-2,WATER:0)
B(-2,-2,-2,WATER:0)
B(-1,-2,-2,WATER:0)
B(0,-2,-2,WATER:0)
B(1,-2,-2,WATER:0)
B(6,-2,-2,WOODEN_SLAB:8)
B(-5,-2,-1,PLANKS:0)
B(-4,-2,-1,WATER:0)
B(-3,-2,-1,WATER:0)
B(-2,-2,-1,WATER:0)
B(-1,-2,-1,WATER:0)
B(0,-2,-1,WATER:0)
B(1,-2,-1,WATER:0)
B(5,-2,-1,PLANKS:0)
B(-5,-2,0,PLANKS:0)
B(-4,-2,0,WATER:0)
B(-3,-2,0,WATER:0)
B(-2,-2,0,WATER:0)
B(-1,-2,0,WATER:0)
B(0,-2,0,LOG:1)
B(1,-2,0,WATER:0)
B(2,-2,0,WATER:0)
B(5,-2,0,PLANKS:0)
B(-6,-2,1,WOODEN_SLAB:8)
B(-4,-2,1,WATER:0)
B(-3,-2,1,WATER:0)
B(-2,-2,1,WATER:0)
B(-1,-2,1,WATER:0)
B(0,-2,1,WATER:0)
B(1,-2,1,WATER:0)
B(2,-2,1,WATER:0)
B(3,-2,1,WATER:0)
B(4,-2,1,WATER:0)
B(6,-2,1,WOODEN_SLAB:8)
B(-5,-2,2,PLANKS:0)
B(-4,-2,2,WATER:0)
B(-3,-2,2,WATER:0)
B(-2,-2,2,WATER:0)
B(-1,-2,2,WATER:0)
B(0,-2,2,WATER:0)
B(1,-2,2,WATER:0)
B(2,-2,2,WATER:0)
B(3,-2,2,WATER:0)
B(4,-2,2,WATER:0)
B(5,-2,2,PLANKS:0)
B(-5,-2,3,PLANKS:0)
B(-4,-2,3,WATER:0)
B(-3,-2,3,WATER:0)
B(-2,-2,3,WATER:0)
B(-1,-2,3,PLANKS:2)
B(0,-2,3,PLANKS:2)
B(1,-2,3,WATER:0)
B(2,-2,3,WATER:0)
B(3,-2,3,WATER:0)
B(4,-2,3,WATER:0)
B(5,-2,3,PLANKS:0)
B(-5,-2,4,WOODEN_SLAB:8)
B(-4,-2,4,WATER:0)
B(-3,-2,4,WATER:0)
B(-2,-2,4,WATER:0)
B(-1,-2,4,PLANKS:2)
B(0,-2,4,PLANKS:2)
B(1,-2,4,WATER:0)
B(2,-2,4,WATER:0)
B(3,-2,4,WATER:0)
B(4,-2,4,WATER:0)
B(5,-2,4,WOODEN_SLAB:8)
B(-4,-2,5,PLANKS:0)
B(-3,-2,5,PLANKS:1)
B(-2,-2,5,PLANKS:1)
B(-1,-2,5,PLANKS:1)
B(0,-2,5,IRON_DOOR:10)
B(1,-2,5,PLANKS:1)
B(2,-2,5,PLANKS:1)
B(3,-2,5,PLANKS:1)
B(4,-2,5,PLANKS:0)
B(-5,-2,6,TRAPDOOR:12)
B(-4,-2,6,PLANKS:0)
B(-3,-2,6,AIR:0)
B(-2,-2,6,AIR:0)
B(-1,-2,6,AIR:0)
B(0,-2,6,AIR:0)
B(1,-2,6,AIR:0)
B(2,-2,6,AIR:0)
B(3,-2,6,AIR:0)
B(4,-2,6,PLANKS:0)
B(5,-2,6,TRAPDOOR:12)
B(-6,-2,7,TRAPDOOR:14)
B(-5,-2,7,PLANKS:0)
B(-4,-2,7,AIR:0)
B(-3,-2,7,AIR:0)
B(-2,-2,7,AIR:0)
B(-1,-2,7,AIR:0)
B(0,-2,7,AIR:0)
B(1,-2,7,AIR:0)
B(2,-2,7,AIR:0)
B(3,-2,7,AIR:0)
B(4,-2,7,AIR:0)
B(5,-2,7,PLANKS:0)
B(6,-2,7,TRAPDOOR:15)
B(-5,-2,8,STAINED_GLASS_PANE:15)
B(-4,-2,8,AIR:0)
B(-3,-2,8,AIR:0)
B(-2,-2,8,AIR:0)
B(-1,-2,8,AIR:0)
B(0,-2,8,AIR:0)
B(1,-2,8,AIR:0)
B(2,-2,8,AIR:0)
B(3,-2,8,AIR:0)
B(4,-2,8,AIR:0)
B(5,-2,8,STAINED_GLASS_PANE:15)
B(-4,-1,-7,WOODEN_SLAB:8)
B(-3,-1,-7,WOODEN_SLAB:8)
B(-2,-1,-7,WOODEN_SLAB:8)
B(0,-1,-7,WOODEN_SLAB:9)
B(2,-1,-7,WOODEN_SLAB:8)
B(-4,-1,-6,WOODEN_SLAB:8)
B(-3,-1,-6,WOODEN_SLAB:8)
B(-2,-1,-6,WOODEN_SLAB:8)
B(0,-1,-6,WOODEN_SLAB:9)
B(2,-1,-6,WOODEN_SLAB:8)
B(-4,-1,-5,WOODEN_SLAB:8)
B(-3,-1,-5,WOODEN_SLAB:8)
B(-2,-1,-5,WOODEN_SLAB:8)
B(-1,-1,-5,WOODEN_SLAB:8)
B(0,-1,-5,WOODEN_SLAB:8)
B(1,-1,-5,WOODEN_SLAB:8)
B(-4,-1,-4,WOODEN_SLAB:8)
B(-3,-1,-4,WOODEN_SLAB:8)
B(-2,-1,-4,WOODEN_SLAB:8)
B(-1,-1,-4,WOODEN_SLAB:8)
B(0,-1,-4,WOODEN_SLAB:8)
B(1,-1,-4,WOODEN_SLAB:8)
B(5,-1,-4,DARK_OAK_STAIRS:3)
B(-5,-1,-3,WOODEN_SLAB:5)
B(-4,-1,-3,WOODEN_SLAB:8)
B(-3,-1,-3,WOODEN_SLAB:8)
B(-2,-1,-3,WOODEN_SLAB:8)
B(-1,-1,-3,WOODEN_SLAB:8)
B(0,-1,-3,WOODEN_SLAB:8)
B(1,-1,-3,WOODEN_SLAB:8)
B(5,-1,-3,WOODEN_SLAB:5)
B(-5,-1,-2,DARK_OAK_STAIRS:2)
B(-4,-1,-2,WOODEN_SLAB:8)
B(-3,-1,-2,WOODEN_SLAB:8)
B(-2,-1,-2,WOODEN_SLAB:8)
B(-1,-1,-2,WOODEN_SLAB:8)
B(0,-1,-2,WOODEN_SLAB:8)
B(1,-1,-2,WOODEN_SLAB:8)
B(5,-1,-2,DARK_OAK_STAIRS:2)
B(-6,-1,-1,WOODEN_SLAB:13)
B(-5,-1,-1,PLANKS:5)
B(-4,-1,-1,WOODEN_SLAB:8)
B(-3,-1,-1,WOODEN_SLAB:8)
B(-2,-1,-1,WOODEN_SLAB:8)
B(-1,-1,-1,WOODEN_SLAB:8)
B(0,-1,-1,WOODEN_SLAB:8)
B(1,-1,-1,WOODEN_SLAB:8)
B(5,-1,-1,PLANKS:5)
B(6,-1,-1,WOODEN_SLAB:13)
B(-6,-1,0,WOODEN_SLAB:13)
B(-5,-1,0,PLANKS:5)
B(-4,-1,0,WOODEN_SLAB:8)
B(-3,-1,0,WOODEN_SLAB:8)
B(-2,-1,0,WOODEN_SLAB:8)
B(-1,-1,0,WOODEN_SLAB:8)
B(0,-1,0,LOG:1)
B(1,-1,0,WOODEN_SLAB:8)
B(2,-1,0,WOODEN_SLAB:8)
B(5,-1,0,PLANKS:5)
B(6,-1,0,WOODEN_SLAB:13)
B(-6,-1,1,WOODEN_SLAB:13)
B(-5,-1,1,PLANKS:5)
B(-4,-1,1,WOODEN_SLAB:8)
B(-3,-1,1,WOODEN_SLAB:8)
B(-2,-1,1,WOODEN_SLAB:8)
B(-1,-1,1,WOODEN_SLAB:8)
B(0,-1,1,WOODEN_SLAB:8)
B(1,-1,1,WOODEN_SLAB:8)
B(2,-1,1,WOODEN_SLAB:8)
B(3,-1,1,WOODEN_SLAB:8)
B(4,-1,1,WOODEN_SLAB:8)
B(5,-1,1,PLANKS:5)
B(6,-1,1,WOODEN_SLAB:13)
B(-6,-1,2,WOODEN_SLAB:13)
B(-5,-1,2,PLANKS:5)
B(-4,-1,2,WOODEN_SLAB:8)
B(-3,-1,2,WOODEN_SLAB:8)
B(-2,-1,2,WOODEN_SLAB:8)
B(-1,-1,2,WOODEN_SLAB:8)
B(0,-1,2,WOODEN_SLAB:8)
B(1,-1,2,WOODEN_SLAB:8)
B(2,-1,2,WOODEN_SLAB:8)
B(3,-1,2,WOODEN_SLAB:8)
B(4,-1,2,WOODEN_SLAB:8)
B(5,-1,2,PLANKS:5)
B(6,-1,2,WOODEN_SLAB:13)
B(-5,-1,3,PLANKS:5)
B(-4,-1,3,WOODEN_SLAB:8)
B(-3,-1,3,WOODEN_SLAB:8)
B(-2,-1,3,WOODEN_SLAB:8)
B(-1,-1,3,WOODEN_SLAB:8)
B(0,-1,3,WOODEN_SLAB:8)
B(1,-1,3,WOODEN_SLAB:8)
B(2,-1,3,WOODEN_SLAB:8)
B(3,-1,3,WOODEN_SLAB:8)
B(4,-1,3,WOODEN_SLAB:8)
B(5,-1,3,PLANKS:5)
B(-4,-1,4,DARK_OAK_STAIRS:3)
B(-3,-1,4,WOODEN_SLAB:8)
B(-2,-1,4,WOODEN_SLAB:8)
B(-1,-1,4,WOODEN_SLAB:8)
B(0,-1,4,WOODEN_SLAB:8)
B(1,-1,4,WOODEN_SLAB:8)
B(2,-1,4,WOODEN_SLAB:8)
B(3,-1,4,WOODEN_SLAB:8)
B(4,-1,4,DARK_OAK_STAIRS:3)
B(-4,-1,5,DARK_OAK_STAIRS:2)
B(-3,-1,5,DOUBLE_WOODEN_SLAB:0)
B(-2,-1,5,PLANKS:1)
B(-1,-1,5,PLANKS:1)
B(0,-1,5,PLANKS:1)
B(1,-1,5,PLANKS:1)
B(2,-1,5,PLANKS:1)
B(3,-1,5,DOUBLE_WOODEN_SLAB:0)
B(4,-1,5,DARK_OAK_STAIRS:2)
B(-4,-1,6,PLANKS:5)
B(-3,-1,6,AIR:0)
B(-2,-1,6,AIR:0)
B(-1,-1,6,AIR:0)
B(0,-1,6,AIR:0)
B(1,-1,6,AIR:0)
B(2,-1,6,AIR:0)
B(3,-1,6,AIR:0)
B(4,-1,6,PLANKS:5)
B(-5,-1,7,WOODEN_SLAB:5)
B(-4,-1,7,WOODEN_SLAB:13)
B(-3,-1,7,AIR:0)
B(-2,-1,7,AIR:0)
B(-1,-1,7,AIR:0)
B(0,-1,7,AIR:0)
B(1,-1,7,AIR:0)
B(2,-1,7,AIR:0)
B(3,-1,7,AIR:0)
B(4,-1,7,WOODEN_SLAB:13)
B(5,-1,7,WOODEN_SLAB:5)
B(-5,-1,8,WOODEN_SLAB:5)
B(-4,-1,8,WOODEN_SLAB:13)
B(-3,-1,8,AIR:0)
B(-2,-1,8,AIR:0)
B(-1,-1,8,AIR:0)
B(0,-1,8,AIR:0)
B(1,-1,8,AIR:0)
B(3,-1,8,AIR:0)
B(4,-1,8,WOODEN_SLAB:13)
B(5,-1,8,WOODEN_SLAB:5)
B(-1,0,-7,TRAPDOOR:2)
B(0,0,-7,WOODEN_SLAB:1)
B(1,0,-7,TRAPDOOR:3)
B(-1,0,-6,TRAPDOOR:2)
B(0,0,-6,WOODEN_SLAB:1)
B(1,0,-6,TRAPDOOR:3)
B(-1,0,-5,SPRUCE_STAIRS:0)
B(1,0,-5,SPRUCE_STAIRS:1)
B(5,0,-4,DARK_OAK_STAIRS:7)
B(-1,0,-3,COBBLESTONE_WALL:0)
B(1,0,-3,COBBLESTONE_WALL:0)
B(5,0,-3,DARK_OAK_STAIRS:5)
B(5,0,-2,DARK_OAK_STAIRS:6)
B(-5,0,-1,PLANKS:5)
B(-1,0,-1,COBBLESTONE_WALL:0)
B(1,0,-1,COBBLESTONE_WALL:0)
B(5,0,-1,PLANKS:5)
B(-5,0,0,PLANKS:5)
B(-3,0,0,PLANKS:2)
B(-2,0,0,PLANKS:2)
B(0,0,0,PLANKS:5)
B(5,0,0,PLANKS:5)
B(-5,0,1,PLANKS:5)
B(-3,0,1,PLANKS:2)
B(-2,0,1,PLANKS:2)
B(5,0,1,PLANKS:5)
B(-5,0,2,PLANKS:5)
B(5,0,2,PLANKS:5)
B(-4,0,3,PLANKS:5)
B(0,0,3,COBBLESTONE_WALL:0)
B(4,0,3,PLANKS:5)
B(-4,0,4,DARK_OAK_STAIRS:7)
B(-3,0,4,WOODEN_SLAB:0)
B(3,0,4,WOODEN_SLAB:0)
B(4,0,4,DARK_OAK_STAIRS:7)
B(-4,0,5,DOUBLE_WOODEN_SLAB:5)
B(-3,0,5,WOODEN_SLAB:0)
B(-2,0,5,WOODEN_SLAB:0)
B(-1,0,5,WOODEN_SLAB:0)
B(0,0,5,WOODEN_SLAB:0)
B(1,0,5,WOODEN_SLAB:0)
B(2,0,5,WOODEN_SLAB:0)
B(3,0,5,WOODEN_SLAB:0)
B(4,0,5,DOUBLE_WOODEN_SLAB:5)
B(-4,0,6,DARK_OAK_STAIRS:7)
B(-3,0,6,WOODEN_SLAB:0)
B(-2,0,6,WOODEN_SLAB:0)
B(-1,0,6,WOODEN_SLAB:0)
B(0,0,6,WOODEN_SLAB:0)
B(1,0,6,WOODEN_SLAB:0)
B(2,0,6,WOODEN_SLAB:0)
B(3,0,6,WOODEN_SLAB:0)
B(4,0,6,DARK_OAK_STAIRS:7)
B(-4,0,7,WOODEN_SLAB:13)
B(-3,0,7,DOUBLE_WOODEN_SLAB:0)
B(-2,0,7,WOODEN_SLAB:8)
B(-1,0,7,WOODEN_SLAB:0)
B(0,0,7,WOODEN_SLAB:0)
B(1,0,7,WOODEN_SLAB:0)
B(2,0,7,WOODEN_SLAB:8)
B(3,0,7,DOUBLE_WOODEN_SLAB:0)
B(4,0,7,WOODEN_SLAB:13)
B(-4,0,8,WOODEN_SLAB:13)
B(-3,0,8,DOUBLE_WOODEN_SLAB:0)
B(-2,0,8,WOODEN_SLAB:8)
B(-1,0,8,WOODEN_SLAB:8)
B(0,0,8,WOODEN_SLAB:8)
B(1,0,8,WOODEN_SLAB:8)
B(2,0,8,WOODEN_SLAB:8)
B(3,0,8,DOUBLE_WOODEN_SLAB:0)
B(4,0,8,WOODEN_SLAB:13)
B(-1,1,-7,SPRUCE_STAIRS:4)
B(0,1,-7,WOODEN_SLAB:1)
B(1,1,-7,SPRUCE_STAIRS:5)
B(-1,1,-6,SPRUCE_STAIRS:4)
B(0,1,-6,WOODEN_SLAB:1)
B(1,1,-6,SPRUCE_STAIRS:5)
B(-1,1,-5,SPRUCE_STAIRS:4)
B(0,1,-5,WOODEN_SLAB:1)
B(1,1,-5,SPRUCE_STAIRS:5)
B(-1,1,-4,WOODEN_SLAB:9)
B(0,1,-4,SPRUCE_STAIRS:7)
B(1,1,-4,WOODEN_SLAB:9)
B(-3,1,0,PLANKS:2)
B(-2,1,0,PLANKS:2)
B(0,1,0,PLANKS:5)
B(-3,1,1,PLANKS:2)
B(-2,1,1,PLANKS:2)
B(0,1,2,TRAPDOOR:4)
B(-1,1,3,LEVER:2)
B(0,1,3,LOG_2:9)
B(1,1,3,LEVER:9)
B(-4,1,4,WOODEN_SLAB:5)
B(4,1,4,WOODEN_SLAB:5)
B(-4,1,5,WOODEN_SLAB:5)
B(4,1,5,WOODEN_SLAB:5)
B(-4,1,6,PLANKS:5)
B(4,1,6,PLANKS:5)
B(-4,1,7,DARK_OAK_STAIRS:7)
B(4,1,7,DARK_OAK_STAIRS:7)
B(-4,1,8,WOODEN_SLAB:13)
B(4,1,8,WOODEN_SLAB:13)
B(-1,2,-7,WOODEN_SLAB:1)
B(1,2,-7,WOODEN_SLAB:1)
B(-1,2,-6,WOODEN_SLAB:1)
B(0,2,-6,TRAPDOOR:3)
B(1,2,-6,WOODEN_SLAB:1)
B(-1,2,-5,WOODEN_SLAB:1)
B(1,2,-5,WOODEN_SLAB:1)
B(-1,2,-4,WOODEN_SLAB:1)
B(1,2,-4,WOODEN_SLAB:1)
B(-1,2,-3,WOODEN_SLAB:1)
B(0,2,-3,SPRUCE_STAIRS:2)
B(1,2,-3,WOODEN_SLAB:1)
B(-1,2,-2,SPRUCE_STAIRS:0)
B(0,2,-2,PLANKS:5)
B(1,2,-2,SPRUCE_STAIRS:1)
B(-1,2,-1,WOODEN_SLAB:1)
B(0,2,-1,SPRUCE_STAIRS:3)
B(1,2,-1,WOODEN_SLAB:1)
B(0,2,0,LOG_2:1)
B(0,2,3,LEVER:14)
B(0,3,0,PLANKS:5)
B(0,4,0,LOG_2:1)
B(0,5,0,LOG_2:1)

E(-2,-5,-1,GUARDIAN,1)
E(0,-5,7,GUARDIAN,1)
