Author: Bo3 BulkEdit

Description: Converted Schematic - Modified by Bo3BulkEdit

Version: 3

SettingsMode: WriteDisable

IsOTGPlus: false
Tree: false
Frequency: 1
Rarity: 100
RotateRandomly: false
SpawnHeight: randomY
MaxBranchDepth: 20
ExcludedBiomes: All

MinHeight: 0
MaxHeight: 256

SourceBlocks: AIR
MaxPercentageOutsideSourceBlock: 100
OutsideSourceBlock: placeAnyway

B(-2,-5,-4,WOODEN_SLAB:13)
B(2,-5,-4,WOODEN_SLAB:13)
B(-2,-4,-8,PLANKS:2)
B(-1,-4,-8,PLANKS:2)
B(-2,-4,-7,PLANKS:2)
B(-1,-4,-7,PLANKS:2)
B(-2,-4,-5,TRAPDOOR:12)
B(-1,-4,-5,WOODEN_SLAB:13)
B(0,-4,-5,WOODEN_SLAB:13)
B(1,-4,-5,WOODEN_SLAB:13)
B(2,-4,-5,TRAPDOOR:12)
B(-3,-4,-4,TRAPDOOR:14)
B(-2,-4,-4,REDSTONE_LAMP:0)
B(-1,-4,-4,TRAPDOOR:15)
B(1,-4,-4,TRAPDOOR:14)
B(2,-4,-4,REDSTONE_LAMP:0)
B(3,-4,-4,TRAPDOOR:15)
B(-2,-4,-3,TRAPDOOR:13)
B(2,-4,-3,TRAPDOOR:13)
B(-4,-3,-8,WOODEN_SLAB:5)
B(-2,-3,-8,PLANKS:2)
B(-1,-3,-8,PLANKS:2)
B(4,-3,-8,WOODEN_SLAB:5)
B(-4,-3,-7,DARK_OAK_STAIRS:2)
B(-2,-3,-7,PLANKS:2)
B(-1,-3,-7,PLANKS:2)
B(4,-3,-7,DARK_OAK_STAIRS:2)
B(-4,-3,-6,LEVER:10)
B(-3,-3,-6,PLANKS:5)
B(3,-3,-6,PLANKS:5)
B(4,-3,-6,LEVER:9)
B(-3,-3,-5,LEVER:10)
B(-2,-3,-5,PLANKS:5)
B(-1,-3,-5,DARK_OAK_STAIRS:1)
B(0,-3,-5,ANVIL:3)
B(1,-3,-5,DARK_OAK_STAIRS:0)
B(2,-3,-5,PLANKS:5)
B(3,-3,-5,LEVER:9)
B(-2,-3,-4,COBBLESTONE_WALL:0)
B(2,-3,-4,COBBLESTONE_WALL:0)
B(-4,-2,-8,DARK_OAK_STAIRS:2)
B(-3,-2,-8,DOUBLE_WOODEN_SLAB:0)
B(-2,-2,-8,WOODEN_SLAB:0)
B(-1,-2,-8,WOODEN_SLAB:0)
B(0,-2,-8,WOODEN_SLAB:0)
B(1,-2,-8,WOODEN_SLAB:0)
B(2,-2,-8,WOODEN_SLAB:0)
B(3,-2,-8,DOUBLE_WOODEN_SLAB:0)
B(4,-2,-8,DARK_OAK_STAIRS:2)
B(-4,-2,-7,PLANKS:5)
B(-3,-2,-7,WOODEN_SLAB:0)
B(-2,-2,-7,WOODEN_SLAB:0)
B(-1,-2,-7,WOODEN_SLAB:0)
B(0,-2,-7,WOODEN_SLAB:0)
B(1,-2,-7,WOODEN_SLAB:0)
B(2,-2,-7,WOODEN_SLAB:0)
B(3,-2,-7,WOODEN_SLAB:0)
B(4,-2,-7,PLANKS:5)
B(-5,-2,-6,ANVIL:0)
B(-4,-2,-6,DARK_OAK_STAIRS:4)
B(-3,-2,-6,PLANKS:5)
B(-2,-2,-6,DOUBLE_WOODEN_SLAB:0)
B(-1,-2,-6,DOUBLE_WOODEN_SLAB:0)
B(0,-2,-6,DOUBLE_WOODEN_SLAB:0)
B(1,-2,-6,DOUBLE_WOODEN_SLAB:0)
B(2,-2,-6,DOUBLE_WOODEN_SLAB:0)
B(3,-2,-6,PLANKS:5)
B(4,-2,-6,DARK_OAK_STAIRS:5)
B(5,-2,-6,ANVIL:2)
B(-3,-2,-5,DARK_OAK_STAIRS:7)
B(-2,-2,-5,PLANKS:5)
B(-1,-2,-5,DARK_OAK_STAIRS:1)
B(0,-2,-5,WOODEN_SLAB:5)
B(1,-2,-5,DARK_OAK_STAIRS:0)
B(2,-2,-5,PLANKS:5)
B(3,-2,-5,DARK_OAK_STAIRS:7)
B(-5,-1,-8,DARK_OAK_STAIRS:6)
B(-4,-1,-8,WOODEN_SLAB:5)
B(-3,-1,-8,WATER:0)
B(-2,-1,-8,WATER:0)
B(-1,-1,-8,WATER:0)
B(0,-1,-8,WATER:0)
B(1,-1,-8,WATER:0)
B(2,-1,-8,WATER:0)
B(3,-1,-8,WATER:0)
B(4,-1,-8,WOODEN_SLAB:5)
B(5,-1,-8,DARK_OAK_STAIRS:6)
B(-5,-1,-7,DARK_OAK_STAIRS:4)
B(-4,-1,-7,WATER:0)
B(-3,-1,-7,WATER:0)
B(-2,-1,-7,WATER:0)
B(-1,-1,-7,WATER:0)
B(0,-1,-7,WATER:0)
B(1,-1,-7,WATER:0)
B(2,-1,-7,WATER:0)
B(3,-1,-7,WATER:0)
B(4,-1,-7,WATER:0)
B(5,-1,-7,DARK_OAK_STAIRS:5)
B(-5,-1,-6,PLANKS:5)
B(-4,-1,-6,PLANKS:5)
B(-3,-1,-6,PLANKS:5)
B(-2,-1,-6,PLANKS:5)
B(-1,-1,-6,PLANKS:5)
B(0,-1,-6,PLANKS:5)
B(1,-1,-6,PLANKS:5)
B(2,-1,-6,PLANKS:5)
B(3,-1,-6,PLANKS:5)
B(4,-1,-6,PLANKS:5)
B(5,-1,-6,PLANKS:5)
B(-2,-1,-5,DARK_OAK_STAIRS:0)
B(-1,-1,-5,ANVIL:3)
B(0,-1,-5,WOODEN_SLAB:5)
B(1,-1,-5,ANVIL:3)
B(2,-1,-5,DARK_OAK_STAIRS:1)
B(-6,0,-8,TRAPDOOR:6)
B(-5,0,-8,PLANKS:0)
B(-4,0,-8,WATER:0)
B(-3,0,-8,WATER:0)
B(-2,0,-8,WATER:0)
B(-1,0,-8,WATER:0)
B(0,0,-8,WATER:0)
B(1,0,-8,WATER:0)
B(2,0,-8,WATER:0)
B(3,0,-8,WATER:0)
B(4,0,-8,WATER:0)
B(5,0,-8,PLANKS:0)
B(6,0,-8,TRAPDOOR:7)
B(-5,0,-7,STAINED_GLASS_PANE:15)
B(-4,0,-7,WATER:0)
B(-3,0,-7,WATER:0)
B(-2,0,-7,WATER:0)
B(-1,0,-7,WATER:0)
B(0,0,-7,WATER:0)
B(1,0,-7,WATER:0)
B(2,0,-7,WATER:0)
B(3,0,-7,WATER:0)
B(4,0,-7,WATER:0)
B(5,0,-7,STAINED_GLASS_PANE:15)
B(-6,0,-6,TRAPDOOR:6)
B(-5,0,-6,PLANKS:0)
B(-4,0,-6,STAINED_GLASS_PANE:15)
B(-3,0,-6,PLANKS:0)
B(-2,0,-6,WATER:0)
B(-1,0,-6,PLANKS:0)
B(0,0,-6,STAINED_GLASS_PANE:15)
B(1,0,-6,PLANKS:0)
B(2,0,-6,WATER:0)
B(3,0,-6,PLANKS:0)
B(4,0,-6,STAINED_GLASS_PANE:15)
B(5,0,-6,PLANKS:0)
B(6,0,-6,TRAPDOOR:7)
B(-5,0,-5,TRAPDOOR:5)
B(-3,0,-5,DARK_OAK_FENCE:0)
B(-1,0,-5,DARK_OAK_FENCE:0)
B(1,0,-5,DARK_OAK_FENCE:0)
B(3,0,-5,DARK_OAK_FENCE:0)
B(5,0,-5,TRAPDOOR:5)
B(-5,1,-8,DARK_OAK_STAIRS:0)
B(-4,1,-8,WATER:0)
B(-3,1,-8,WATER:0)
B(-2,1,-8,WATER:0)
B(-1,1,-8,WATER:0)
B(0,1,-8,WATER:0)
B(1,1,-8,WATER:0)
B(2,1,-8,WATER:0)
B(3,1,-8,WATER:0)
B(4,1,-8,WATER:0)
B(5,1,-8,DARK_OAK_STAIRS:1)
B(-5,1,-7,DARK_OAK_STAIRS:0)
B(-4,1,-7,PLANKS:5)
B(-3,1,-7,WATER:0)
B(-2,1,-7,WATER:0)
B(-1,1,-7,WATER:0)
B(0,1,-7,WATER:0)
B(1,1,-7,WATER:0)
B(2,1,-7,WATER:0)
B(3,1,-7,WATER:0)
B(4,1,-7,PLANKS:5)
B(5,1,-7,DARK_OAK_STAIRS:1)
B(-5,1,-6,DARK_OAK_STAIRS:3)
B(-4,1,-6,DARK_OAK_STAIRS:3)
B(-3,1,-6,DARK_OAK_STAIRS:3)
B(-2,1,-6,DARK_OAK_STAIRS:3)
B(-1,1,-6,DARK_OAK_STAIRS:3)
B(0,1,-6,DARK_OAK_STAIRS:3)
B(1,1,-6,DARK_OAK_STAIRS:3)
B(2,1,-6,DARK_OAK_STAIRS:3)
B(3,1,-6,DARK_OAK_STAIRS:3)
B(4,1,-6,DARK_OAK_STAIRS:3)
B(5,1,-6,DARK_OAK_STAIRS:3)
B(-4,2,-8,PLANKS:1)
B(-3,2,-8,PLANKS:1)
B(-2,2,-8,WOODEN_SLAB:0)
B(-1,2,-8,WOODEN_SLAB:0)
B(0,2,-8,WOODEN_SLAB:0)
B(1,2,-8,AIR:0)
B(2,2,-8,AIR:0)
B(3,2,-8,PLANKS:1)
B(4,2,-8,PLANKS:1)
B(-3,2,-7,WOODEN_SLAB:1)
B(-2,2,-7,PLANKS:1)
B(-1,2,-7,PLANKS:1)
B(0,2,-7,PLANKS:1)
B(1,2,-7,PLANKS:1)
B(2,2,-7,PLANKS:1)
B(3,2,-7,WOODEN_SLAB:1)
B(0,2,-6,ANVIL:2)
B(-3,3,-8,PLANKS:1)
B(-2,3,-8,AIR:0)
B(-1,3,-8,AIR:0)
B(0,3,-8,AIR:0)
B(1,3,-8,AIR:0)
B(2,3,-8,PLANKS:1)
B(3,3,-8,PLANKS:1)
B(-2,3,-7,PLANKS:1)
B(-1,3,-7,PLANKS:1)
B(0,3,-7,PLANKS:1)
B(1,3,-7,PLANKS:1)
B(2,3,-7,PLANKS:1)
B(0,3,-6,PLANKS:1)
B(0,3,-5,SPRUCE_STAIRS:7)
B(-2,4,-8,PLANKS:1)
B(-1,4,-8,PLANKS:1)
B(0,4,-8,PLANKS:1)
B(1,4,-8,PLANKS:1)
B(2,4,-8,PLANKS:1)
B(-1,4,-7,PLANKS:1)
B(0,4,-7,PLANKS:1)
B(1,4,-7,PLANKS:1)
B(0,4,-6,PLANKS:1)
B(0,4,-5,PLANKS:1)
B(0,5,-8,PLANKS:1)
B(0,5,-7,DARK_OAK_FENCE:0)
B(0,5,-6,PLANKS:1)
B(0,5,-5,PLANKS:1)
B(0,6,-8,PLANKS:1)
B(0,6,-7,DARK_OAK_FENCE:0)
B(0,6,-6,PLANKS:1)
B(0,6,-5,PLANKS:1)

