Author: Bo3 BulkEdit

Description: Converted Schematic - Modified by Bo3BulkEdit

Version: 3

SettingsMode: WriteDisable

IsOTGPlus: false
Tree: false
Frequency: 1
Rarity: 100
RotateRandomly: false
SpawnHeight: randomY
MaxBranchDepth: 20
ExcludedBiomes: All

MinHeight: 0
MaxHeight: 256

SourceBlocks: AIR
MaxPercentageOutsideSourceBlock: 100
OutsideSourceBlock: placeAnyway

B(0,-8,-7,PLANKS:1)
B(0,-8,-6,PLANKS:1)
B(-1,-8,-5,PLANKS:1)
B(0,-8,-5,PLANKS:1)
B(1,-8,-5,PLANKS:1)
B(-1,-8,-4,PLANKS:1)
B(0,-8,-4,PLANKS:1)
B(1,-8,-4,PLANKS:1)
B(-1,-8,-3,PLANKS:1)
B(0,-8,-3,PLANKS:1)
B(1,-8,-3,PLANKS:1)
B(-1,-8,-2,PLANKS:1)
B(0,-8,-2,PLANKS:1)
B(1,-8,-2,PLANKS:1)
B(-2,-8,-1,PLANKS:1)
B(-1,-8,-1,PLANKS:1)
B(0,-8,-1,PLANKS:1)
B(1,-8,-1,PLANKS:1)
B(2,-8,-1,PLANKS:1)
B(-2,-8,0,PLANKS:1)
B(-1,-8,0,PLANKS:1)
B(0,-8,0,PLANKS:1)
B(1,-8,0,PLANKS:1)
B(2,-8,0,PLANKS:1)
B(-2,-8,1,PLANKS:1)
B(-1,-8,1,PLANKS:1)
B(0,-8,1,PLANKS:1)
B(1,-8,1,PLANKS:1)
B(2,-8,1,PLANKS:1)
B(-2,-8,2,PLANKS:1)
B(-1,-8,2,PLANKS:1)
B(0,-8,2,PLANKS:1)
B(1,-8,2,PLANKS:1)
B(2,-8,2,PLANKS:1)
B(-2,-8,3,PLANKS:1)
B(-1,-8,3,PLANKS:1)
B(0,-8,3,PLANKS:1)
B(1,-8,3,PLANKS:1)
B(2,-8,3,PLANKS:1)
B(-3,-8,4,PLANKS:1)
B(-2,-8,4,PLANKS:1)
B(-1,-8,4,PLANKS:1)
B(0,-8,4,PLANKS:1)
B(1,-8,4,PLANKS:1)
B(2,-8,4,PLANKS:1)
B(3,-8,4,PLANKS:1)
B(-3,-8,5,PLANKS:1)
B(-2,-8,5,PLANKS:1)
B(-1,-8,5,PLANKS:1)
B(0,-8,5,PLANKS:1)
B(1,-8,5,PLANKS:1)
B(2,-8,5,PLANKS:1)
B(3,-8,5,PLANKS:1)
B(-3,-8,6,PLANKS:1)
B(-2,-8,6,PLANKS:1)
B(-1,-8,6,PLANKS:1)
B(0,-8,6,PLANKS:1)
B(1,-8,6,PLANKS:1)
B(2,-8,6,PLANKS:1)
B(3,-8,6,PLANKS:1)
B(-2,-8,7,PLANKS:1)
B(-1,-8,7,PLANKS:1)
B(0,-8,7,PLANKS:1)
B(1,-8,7,PLANKS:1)
B(2,-8,7,PLANKS:1)
B(-2,-8,8,PLANKS:1)
B(-1,-8,8,PLANKS:1)
B(0,-8,8,PLANKS:1)
B(1,-8,8,PLANKS:1)
B(2,-8,8,PLANKS:1)
B(-1,-7,-7,PLANKS:1)
B(0,-7,-7,WATER:0)
B(1,-7,-7,PLANKS:1)
B(-2,-7,-6,PLANKS:1)
B(-1,-7,-6,PLANKS:1)
B(0,-7,-6,WATER:0)
B(1,-7,-6,PLANKS:1)
B(2,-7,-6,PLANKS:1)
B(-3,-7,-5,PLANKS:1)
B(-2,-7,-5,PLANKS:1)
B(-1,-7,-5,WATER:0)
B(0,-7,-5,WATER:0)
B(1,-7,-5,WATER:0)
B(2,-7,-5,PLANKS:1)
B(3,-7,-5,PLANKS:1)
B(-3,-7,-4,PLANKS:1)
B(-2,-7,-4,PLANKS:1)
B(-1,-7,-4,WATER:0)
B(0,-7,-4,WATER:0)
B(1,-7,-4,WATER:0)
B(2,-7,-4,PLANKS:1)
B(3,-7,-4,PLANKS:1)
B(-3,-7,-3,PLANKS:1)
B(-2,-7,-3,PLANKS:1)
B(-1,-7,-3,WATER:0)
B(0,-7,-3,WATER:0)
B(1,-7,-3,WATER:0)
B(2,-7,-3,PLANKS:1)
B(3,-7,-3,PLANKS:1)
B(-3,-7,-2,PLANKS:1)
B(-2,-7,-2,PLANKS:1)
B(-1,-7,-2,WATER:0)
B(0,-7,-2,WATER:0)
B(1,-7,-2,WATER:0)
B(2,-7,-2,PLANKS:1)
B(3,-7,-2,PLANKS:1)
B(-4,-7,-1,PLANKS:1)
B(-3,-7,-1,PLANKS:1)
B(-2,-7,-1,WATER:0)
B(-1,-7,-1,WATER:0)
B(0,-7,-1,LOG:1)
B(1,-7,-1,WATER:0)
B(2,-7,-1,WATER:0)
B(3,-7,-1,PLANKS:1)
B(4,-7,-1,PLANKS:1)
B(-4,-7,0,PLANKS:1)
B(-3,-7,0,PLANKS:1)
B(-2,-7,0,WATER:0)
B(-1,-7,0,WATER:0)
B(0,-7,0,SPRUCE_FENCE:0)
B(1,-7,0,WATER:0)
B(2,-7,0,WATER:0)
B(3,-7,0,PLANKS:1)
B(4,-7,0,PLANKS:1)
B(-4,-7,1,PLANKS:1)
B(-3,-7,1,PLANKS:1)
B(-2,-7,1,WATER:0)
B(-1,-7,1,WATER:0)
B(0,-7,1,WATER:0)
B(1,-7,1,WATER:0)
B(2,-7,1,WATER:0)
B(3,-7,1,PLANKS:1)
B(4,-7,1,PLANKS:1)
B(-4,-7,2,PLANKS:1)
B(-3,-7,2,PLANKS:1)
B(-2,-7,2,PLANKS:1)
B(-1,-7,2,PLANKS:1)
B(0,-7,2,WATER:0)
B(1,-7,2,WATER:0)
B(2,-7,2,WATER:0)
B(3,-7,2,PLANKS:1)
B(4,-7,2,PLANKS:1)
B(-4,-7,3,PLANKS:1)
B(-3,-7,3,PLANKS:1)
B(-2,-7,3,PLANKS:1)
B(-1,-7,3,PLANKS:1)
B(0,-7,3,PLANKS:1)
B(1,-7,3,WATER:0)
B(2,-7,3,WATER:0)
B(3,-7,3,PLANKS:1)
B(4,-7,3,PLANKS:1)
B(-4,-7,4,PLANKS:1)
B(-3,-7,4,PLANKS:1)
B(-2,-7,4,PLANKS:1)
B(-1,-7,4,PLANKS:1)
B(0,-7,4,PLANKS:1)
B(1,-7,4,WATER:0)
B(2,-7,4,WATER:0)
B(3,-7,4,WATER:0)
B(4,-7,4,PLANKS:1)
B(-4,-7,5,PLANKS:1)
B(-3,-7,5,PLANKS:1)
B(-2,-7,5,PLANKS:1)
B(-1,-7,5,PLANKS:1)
B(0,-7,5,PLANKS:1)
B(1,-7,5,PLANKS:1)
B(2,-7,5,WATER:0)
B(3,-7,5,WATER:0)
B(4,-7,5,PLANKS:1)
B(-4,-7,6,PLANKS:1)
B(-3,-7,6,PLANKS:1)
B(-2,-7,6,PLANKS:1)
B(-1,-7,6,PLANKS:1)
B(0,-7,6,WATER:0)
B(1,-7,6,WATER:0)
B(2,-7,6,WATER:0)
B(3,-7,6,WATER:0)
B(4,-7,6,PLANKS:1)
B(-4,-7,7,PLANKS:1)
B(-3,-7,7,PLANKS:1)
B(-2,-7,7,WATER:0)
B(-1,-7,7,WATER:0)
B(0,-7,7,WATER:0)
B(1,-7,7,WATER:0)
B(2,-7,7,WATER:0)
B(3,-7,7,PLANKS:1)
B(4,-7,7,PLANKS:1)
B(-4,-7,8,PLANKS:1)
B(-3,-7,8,PLANKS:1)
B(-2,-7,8,WATER:0)
B(-1,-7,8,WATER:0)
B(0,-7,8,WATER:0)
B(1,-7,8,WATER:0)
B(2,-7,8,WATER:0)
B(3,-7,8,PLANKS:1)
B(4,-7,8,PLANKS:1)
B(-3,-6,-7,PLANKS:1)
B(-2,-6,-7,PLANKS:1)
B(-1,-6,-7,WATER:0)
B(0,-6,-7,WATER:0)
B(1,-6,-7,WATER:0)
B(2,-6,-7,PLANKS:1)
B(3,-6,-7,PLANKS:1)
B(-3,-6,-6,PLANKS:1)
B(-2,-6,-6,WATER:0)
B(-1,-6,-6,WATER:0)
B(0,-6,-6,WATER:0)
B(1,-6,-6,WATER:0)
B(2,-6,-6,WATER:0)
B(3,-6,-6,PLANKS:1)
B(-3,-6,-5,PLANKS:1)
B(-2,-6,-5,WATER:0)
B(-1,-6,-5,WATER:0)
B(0,-6,-5,WATER:0)
B(1,-6,-5,WATER:0)
B(2,-6,-5,WATER:0)
B(3,-6,-5,PLANKS:1)
B(-4,-6,-4,PLANKS:1)
B(-3,-6,-4,WATER:0)
B(-2,-6,-4,WATER:0)
B(-1,-6,-4,WATER:0)
B(0,-6,-4,WATER:0)
B(1,-6,-4,WATER:0)
B(2,-6,-4,WATER:0)
B(3,-6,-4,WATER:0)
B(4,-6,-4,PLANKS:1)
B(-4,-6,-3,PLANKS:1)
B(-3,-6,-3,WATER:0)
B(-2,-6,-3,WATER:0)
B(-1,-6,-3,WATER:0)
B(0,-6,-3,WATER:0)
B(1,-6,-3,WATER:0)
B(2,-6,-3,WATER:0)
B(3,-6,-3,WATER:0)
B(4,-6,-3,PLANKS:1)
B(-4,-6,-2,PLANKS:1)
B(-3,-6,-2,WATER:0)
B(-2,-6,-2,WATER:0)
B(-1,-6,-2,WATER:0)
B(0,-6,-2,WATER:0)
B(1,-6,-2,WATER:0)
B(2,-6,-2,WATER:0)
B(3,-6,-2,WATER:0)
B(4,-6,-2,PLANKS:1)
B(-4,-6,-1,PLANKS:1)
B(-3,-6,-1,WATER:0)
B(-2,-6,-1,WATER:0)
B(-1,-6,-1,WATER:0)
B(0,-6,-1,LOG:1)
B(1,-6,-1,WATER:0)
B(2,-6,-1,WATER:0)
B(3,-6,-1,WATER:0)
B(4,-6,-1,PLANKS:1)
B(-4,-6,0,PLANKS:1)
B(-3,-6,0,SPRUCE_FENCE:0)
B(-2,-6,0,WATER:0)
B(-1,-6,0,WATER:0)
B(0,-6,0,SPRUCE_FENCE:0)
B(1,-6,0,WATER:0)
B(2,-6,0,WATER:0)
B(3,-6,0,SPRUCE_FENCE:0)
B(4,-6,0,PLANKS:1)
B(-4,-6,1,PLANKS:1)
B(-3,-6,1,WATER:0)
B(-2,-6,1,WATER:0)
B(-1,-6,1,WATER:0)
B(0,-6,1,WATER:0)
B(1,-6,1,WATER:0)
B(2,-6,1,WATER:0)
B(3,-6,1,WATER:0)
B(4,-6,1,PLANKS:1)
B(-4,-6,2,PLANKS:1)
B(-3,-6,2,PLANKS:1)
B(-2,-6,2,PLANKS:1)
B(-1,-6,2,WATER:0)
B(0,-6,2,WATER:0)
B(1,-6,2,WATER:0)
B(2,-6,2,WATER:0)
B(3,-6,2,WATER:0)
B(4,-6,2,PLANKS:1)
B(-5,-6,3,PLANKS:1)
B(-4,-6,3,WATER:0)
B(-3,-6,3,WATER:0)
B(-2,-6,3,IRON_BARS:0)
B(-1,-6,3,WATER:0)
B(0,-6,3,WATER:0)
B(1,-6,3,WATER:0)
B(2,-6,3,WATER:0)
B(3,-6,3,SPRUCE_FENCE:0)
B(4,-6,3,WATER:0)
B(5,-6,3,PLANKS:1)
B(-5,-6,4,PLANKS:1)
B(-4,-6,4,WATER:0)
B(-3,-6,4,WATER:0)
B(-2,-6,4,IRON_BARS:0)
B(-1,-6,4,WATER:0)
B(0,-6,4,WATER:0)
B(1,-6,4,WATER:0)
B(2,-6,4,WATER:0)
B(3,-6,4,WATER:0)
B(4,-6,4,WATER:0)
B(5,-6,4,PLANKS:1)
B(-5,-6,5,PLANKS:1)
B(-4,-6,5,WATER:0)
B(-3,-6,5,WATER:0)
B(-2,-6,5,IRON_BARS:0)
B(-1,-6,5,WATER:0)
B(0,-6,5,WATER:0)
B(1,-6,5,WATER:0)
B(2,-6,5,WATER:0)
B(3,-6,5,WATER:0)
B(4,-6,5,WATER:0)
B(5,-6,5,PLANKS:1)
B(-5,-6,6,PLANKS:1)
B(-4,-6,6,PLANKS:1)
B(-3,-6,6,PLANKS:1)
B(-2,-6,6,PLANKS:1)
B(-1,-6,6,WATER:0)
B(0,-6,6,WATER:0)
B(1,-6,6,WATER:0)
B(2,-6,6,WATER:0)
B(3,-6,6,WATER:0)
B(4,-6,6,WATER:0)
B(5,-6,6,PLANKS:1)
B(-5,-6,7,PLANKS:1)
B(-4,-6,7,WATER:0)
B(-3,-6,7,SPRUCE_FENCE:0)
B(-2,-6,7,WATER:0)
B(-1,-6,7,WATER:0)
B(0,-6,7,WATER:0)
B(1,-6,7,WATER:0)
B(2,-6,7,WATER:0)
B(3,-6,7,SPRUCE_FENCE:0)
B(4,-6,7,WATER:0)
B(5,-6,7,PLANKS:1)
B(-4,-6,8,WATER:0)
B(-3,-6,8,WATER:0)
B(-2,-6,8,WATER:0)
B(-1,-6,8,WATER:0)
B(0,-6,8,WATER:0)
B(1,-6,8,WATER:0)
B(2,-6,8,WATER:0)
B(3,-6,8,WATER:0)
B(4,-6,8,WATER:0)
B(5,-6,8,PLANKS:1)
B(-3,-5,-7,PLANKS:1)
B(-2,-5,-7,WATER:0)
B(-1,-5,-7,WATER:0)
B(0,-5,-7,WATER:0)
B(1,-5,-7,WATER:0)
B(2,-5,-7,WATER:0)
B(3,-5,-7,PLANKS:1)
B(-3,-5,-6,PLANKS:1)
B(-2,-5,-6,WATER:0)
B(-1,-5,-6,WATER:0)
B(0,-5,-6,WATER:0)
B(1,-5,-6,WATER:0)
B(2,-5,-6,WATER:0)
B(3,-5,-6,PLANKS:1)
B(-4,-5,-5,PLANKS:1)
B(-3,-5,-5,WATER:0)
B(-2,-5,-5,WATER:0)
B(-1,-5,-5,WATER:0)
B(0,-5,-5,WATER:0)
B(1,-5,-5,WATER:0)
B(2,-5,-5,WATER:0)
B(3,-5,-5,WATER:0)
B(4,-5,-5,PLANKS:1)
B(-4,-5,-4,PLANKS:1)
B(-3,-5,-4,WATER:0)
B(-2,-5,-4,WATER:0)
B(-1,-5,-4,WATER:0)
B(0,-5,-4,WATER:0)
B(1,-5,-4,WATER:0)
B(2,-5,-4,WATER:0)
B(3,-5,-4,WATER:0)
B(4,-5,-4,PLANKS:1)
B(-4,-5,-3,PLANKS:1)
B(-3,-5,-3,WATER:0)
B(-2,-5,-3,WATER:0)
B(-1,-5,-3,WATER:0)
B(0,-5,-3,WATER:0)
B(1,-5,-3,WATER:0)
B(2,-5,-3,WATER:0)
B(3,-5,-3,WATER:0)
B(4,-5,-3,PLANKS:1)
B(-4,-5,-2,PLANKS:1)
B(-3,-5,-2,WATER:0)
B(-2,-5,-2,WATER:0)
B(-1,-5,-2,WATER:0)
B(0,-5,-2,WATER:0)
B(1,-5,-2,WATER:0)
B(2,-5,-2,WATER:0)
B(3,-5,-2,WATER:0)
B(4,-5,-2,PLANKS:1)
B(-4,-5,-1,PLANKS:1)
B(-3,-5,-1,WATER:0)
B(-2,-5,-1,WATER:0)
B(-1,-5,-1,WATER:0)
B(0,-5,-1,LOG:1)
B(1,-5,-1,WATER:0)
B(2,-5,-1,WATER:0)
B(3,-5,-1,WATER:0)
B(4,-5,-1,PLANKS:1)
B(-4,-5,0,PLANKS:1)
B(-3,-5,0,SPRUCE_FENCE:0)
B(-2,-5,0,WATER:0)
B(-1,-5,0,WATER:0)
B(0,-5,0,SPRUCE_FENCE:0)
B(1,-5,0,WATER:0)
B(2,-5,0,WATER:0)
B(3,-5,0,SPRUCE_FENCE:0)
B(4,-5,0,PLANKS:1)
B(-5,-5,1,PLANKS:1)
B(-4,-5,1,WATER:0)
B(-3,-5,1,WATER:0)
B(-2,-5,1,WATER:0)
B(-1,-5,1,WATER:0)
B(0,-5,1,WATER:0)
B(1,-5,1,WATER:0)
B(2,-5,1,WATER:0)
B(3,-5,1,WATER:0)
B(4,-5,1,WATER:0)
B(5,-5,1,PLANKS:1)
B(-5,-5,2,PLANKS:1)
B(-4,-5,2,PLANKS:1)
B(-3,-5,2,PLANKS:1)
B(-2,-5,2,PLANKS:1)
B(-1,-5,2,WATER:0)
B(0,-5,2,WATER:0)
B(1,-5,2,WATER:0)
B(2,-5,2,WATER:0)
B(3,-5,2,WATER:0)
B(4,-5,2,WATER:0)
B(5,-5,2,PLANKS:1)
B(-5,-5,3,PLANKS:1)
B(-4,-5,3,WATER:0)
B(-3,-5,3,WATER:0)
B(-2,-5,3,IRON_BARS:0)
B(-1,-5,3,WATER:0)
B(0,-5,3,WATER:0)
B(1,-5,3,WATER:0)
B(2,-5,3,WATER:0)
B(3,-5,3,SPRUCE_FENCE:0)
B(4,-5,3,WATER:0)
B(5,-5,3,PLANKS:1)
B(-5,-5,4,PLANKS:1)
B(-4,-5,4,WATER:0)
B(-3,-5,4,WATER:0)
B(-2,-5,4,IRON_BARS:0)
B(-1,-5,4,WATER:0)
B(0,-5,4,WATER:0)
B(1,-5,4,WATER:0)
B(2,-5,4,WATER:0)
B(3,-5,4,WATER:0)
B(4,-5,4,WATER:0)
B(5,-5,4,PLANKS:1)
B(-5,-5,5,PLANKS:1)
B(-4,-5,5,WATER:0)
B(-3,-5,5,WATER:0)
B(-2,-5,5,IRON_BARS:0)
B(-1,-5,5,WATER:0)
B(0,-5,5,WATER:0)
B(1,-5,5,WATER:0)
B(2,-5,5,WATER:0)
B(3,-5,5,WATER:0)
B(4,-5,5,WATER:0)
B(5,-5,5,PLANKS:1)
B(-5,-5,6,PLANKS:1)
B(-4,-5,6,PLANKS:1)
B(-3,-5,6,PLANKS:1)
B(-2,-5,6,PLANKS:1)
B(-1,-5,6,WATER:0)
B(0,-5,6,WATER:0)
B(1,-5,6,WATER:0)
B(2,-5,6,WATER:0)
B(3,-5,6,WATER:0)
B(4,-5,6,WATER:0)
B(5,-5,6,PLANKS:1)
B(-5,-5,7,PLANKS:1)
B(-4,-5,7,WATER:0)
B(-3,-5,7,SPRUCE_FENCE:0)
B(-2,-5,7,WATER:0)
B(-1,-5,7,WATER:0)
B(0,-5,7,WATER:0)
B(1,-5,7,WATER:0)
B(2,-5,7,WATER:0)
B(3,-5,7,SPRUCE_FENCE:0)
B(4,-5,7,WATER:0)
B(5,-5,7,PLANKS:1)
B(-4,-5,8,WATER:0)
B(-3,-5,8,WATER:0)
B(-2,-5,8,WATER:0)
B(-1,-5,8,WATER:0)
B(0,-5,8,WATER:0)
B(1,-5,8,WATER:0)
B(2,-5,8,WATER:0)
B(3,-5,8,WATER:0)
B(4,-5,8,WATER:0)
B(5,-5,8,PLANKS:1)
B(-3,-4,-7,PLANKS:1)
B(-2,-4,-7,WOODEN_SLAB:8)
B(-1,-4,-7,WOODEN_SLAB:8)
B(0,-4,-7,WOODEN_SLAB:8)
B(1,-4,-7,WOODEN_SLAB:8)
B(2,-4,-7,WOODEN_SLAB:8)
B(3,-4,-7,PLANKS:1)
B(-3,-4,-6,PLANKS:5)
B(-2,-4,-6,WOODEN_SLAB:8)
B(-1,-4,-6,WOODEN_SLAB:8)
B(0,-4,-6,WOODEN_SLAB:8)
B(1,-4,-6,WOODEN_SLAB:8)
B(2,-4,-6,WOODEN_SLAB:8)
B(3,-4,-6,PLANKS:5)
B(-4,-4,-5,PLANKS:5)
B(-3,-4,-5,WOODEN_SLAB:8)
B(-2,-4,-5,WOODEN_SLAB:8)
B(-1,-4,-5,WOODEN_SLAB:8)
B(0,-4,-5,WOODEN_SLAB:8)
B(1,-4,-5,WOODEN_SLAB:8)
B(2,-4,-5,WOODEN_SLAB:8)
B(3,-4,-5,WOODEN_SLAB:8)
B(4,-4,-5,PLANKS:5)
B(-4,-4,-4,PLANKS:5)
B(-3,-4,-4,WOODEN_SLAB:8)
B(-2,-4,-4,WOODEN_SLAB:8)
B(-1,-4,-4,WOODEN_SLAB:8)
B(0,-4,-4,WOODEN_SLAB:8)
B(1,-4,-4,WOODEN_SLAB:8)
B(2,-4,-4,WOODEN_SLAB:8)
B(3,-4,-4,WOODEN_SLAB:8)
B(4,-4,-4,PLANKS:5)
B(-4,-4,-3,PLANKS:5)
B(-3,-4,-3,WOODEN_SLAB:8)
B(-2,-4,-3,WOODEN_SLAB:8)
B(-1,-4,-3,WOODEN_SLAB:8)
B(0,-4,-3,WOODEN_SLAB:8)
B(1,-4,-3,WOODEN_SLAB:8)
B(2,-4,-3,WOODEN_SLAB:8)
B(3,-4,-3,WOODEN_SLAB:8)
B(4,-4,-3,PLANKS:5)
B(-4,-4,-2,PLANKS:5)
B(-3,-4,-2,WOODEN_SLAB:8)
B(-2,-4,-2,WOODEN_SLAB:8)
B(-1,-4,-2,WOODEN_SLAB:8)
B(0,-4,-2,WOODEN_SLAB:8)
B(1,-4,-2,WOODEN_SLAB:8)
B(2,-4,-2,WOODEN_SLAB:8)
B(3,-4,-2,WOODEN_SLAB:8)
B(4,-4,-2,PLANKS:5)
B(-4,-4,-1,PLANKS:5)
B(-3,-4,-1,WOODEN_SLAB:8)
B(-2,-4,-1,WOODEN_SLAB:8)
B(-1,-4,-1,WOODEN_SLAB:8)
B(0,-4,-1,LOG:1)
B(1,-4,-1,WOODEN_SLAB:8)
B(2,-4,-1,WOODEN_SLAB:8)
B(3,-4,-1,WOODEN_SLAB:8)
B(4,-4,-1,PLANKS:5)
B(-4,-4,0,PLANKS:5)
B(-3,-4,0,DOUBLE_WOODEN_SLAB:0)
B(-2,-4,0,WOODEN_SLAB:8)
B(-1,-4,0,WOODEN_SLAB:8)
B(0,-4,0,DOUBLE_WOODEN_SLAB:0)
B(1,-4,0,WOODEN_SLAB:8)
B(2,-4,0,WOODEN_SLAB:8)
B(3,-4,0,DOUBLE_WOODEN_SLAB:0)
B(4,-4,0,PLANKS:5)
B(-5,-4,1,PLANKS:5)
B(-4,-4,1,WOODEN_SLAB:8)
B(-3,-4,1,WOODEN_SLAB:8)
B(-2,-4,1,WOODEN_SLAB:8)
B(-1,-4,1,WOODEN_SLAB:8)
B(0,-4,1,WOODEN_SLAB:8)
B(1,-4,1,WOODEN_SLAB:8)
B(2,-4,1,WOODEN_SLAB:8)
B(3,-4,1,WOODEN_SLAB:8)
B(4,-4,1,WOODEN_SLAB:8)
B(5,-4,1,PLANKS:5)
B(-5,-4,2,PLANKS:5)
B(-4,-4,2,DOUBLE_WOODEN_SLAB:0)
B(-3,-4,2,DOUBLE_WOODEN_SLAB:0)
B(-2,-4,2,DOUBLE_WOODEN_SLAB:0)
B(-1,-4,2,WOODEN_SLAB:8)
B(0,-4,2,WOODEN_SLAB:8)
B(1,-4,2,WOODEN_SLAB:8)
B(2,-4,2,WOODEN_SLAB:8)
B(3,-4,2,WOODEN_SLAB:8)
B(4,-4,2,WOODEN_SLAB:8)
B(5,-4,2,PLANKS:5)
B(-5,-4,3,PLANKS:5)
B(-4,-4,3,WOODEN_SLAB:8)
B(-3,-4,3,WOODEN_SLAB:8)
B(-2,-4,3,DOUBLE_WOODEN_SLAB:0)
B(-1,-4,3,WOODEN_SLAB:8)
B(0,-4,3,WOODEN_SLAB:8)
B(1,-4,3,WOODEN_SLAB:8)
B(2,-4,3,WOODEN_SLAB:8)
B(3,-4,3,DOUBLE_WOODEN_SLAB:0)
B(4,-4,3,WOODEN_SLAB:8)
B(5,-4,3,PLANKS:5)
B(-5,-4,4,PLANKS:5)
B(-4,-4,4,WOODEN_SLAB:8)
B(-3,-4,4,WOODEN_SLAB:8)
B(-2,-4,4,DOUBLE_WOODEN_SLAB:0)
B(-1,-4,4,WOODEN_SLAB:8)
B(0,-4,4,WOODEN_SLAB:8)
B(1,-4,4,WOODEN_SLAB:8)
B(2,-4,4,WOODEN_SLAB:8)
B(3,-4,4,WOODEN_SLAB:8)
B(4,-4,4,WOODEN_SLAB:8)
B(5,-4,4,PLANKS:5)
B(-5,-4,5,PLANKS:5)
B(-4,-4,5,WOODEN_SLAB:8)
B(-3,-4,5,WOODEN_SLAB:8)
B(-2,-4,5,DOUBLE_WOODEN_SLAB:0)
B(-1,-4,5,WOODEN_SLAB:8)
B(0,-4,5,WOODEN_SLAB:8)
B(1,-4,5,WOODEN_SLAB:8)
B(2,-4,5,WOODEN_SLAB:8)
B(3,-4,5,WOODEN_SLAB:8)
B(4,-4,5,WOODEN_SLAB:8)
B(5,-4,5,PLANKS:5)
B(-5,-4,6,PLANKS:5)
B(-4,-4,6,DOUBLE_WOODEN_SLAB:0)
B(-3,-4,6,DOUBLE_WOODEN_SLAB:0)
B(-2,-4,6,DOUBLE_WOODEN_SLAB:0)
B(-1,-4,6,WOODEN_SLAB:8)
B(0,-4,6,WATER:0)
B(1,-4,6,WOODEN_SLAB:8)
B(2,-4,6,WOODEN_SLAB:8)
B(3,-4,6,WOODEN_SLAB:8)
B(4,-4,6,WOODEN_SLAB:8)
B(5,-4,6,PLANKS:5)
B(-5,-4,7,PLANKS:5)
B(-4,-4,7,WOODEN_SLAB:8)
B(-3,-4,7,DOUBLE_WOODEN_SLAB:0)
B(-2,-4,7,WOODEN_SLAB:8)
B(-1,-4,7,WATER:0)
B(0,-4,7,WATER:0)
B(1,-4,7,WATER:0)
B(2,-4,7,WOODEN_SLAB:8)
B(3,-4,7,DOUBLE_WOODEN_SLAB:0)
B(4,-4,7,WOODEN_SLAB:8)
B(5,-4,7,PLANKS:5)
B(-4,-4,8,WOODEN_SLAB:8)
B(-3,-4,8,WOODEN_SLAB:8)
B(-2,-4,8,WOODEN_SLAB:8)
B(-1,-4,8,WOODEN_SLAB:8)
B(0,-4,8,WOODEN_SLAB:8)
B(1,-4,8,WATER:0)
B(2,-4,8,WATER:0)
B(3,-4,8,WOODEN_SLAB:8)
B(4,-4,8,WOODEN_SLAB:8)
B(5,-4,8,PLANKS:5)
B(-3,-3,-7,PLANKS:5)
B(-2,-3,-7,WATER:0)
B(-1,-3,-7,WATER:0)
B(0,-3,-7,WATER:0)
B(1,-3,-7,WATER:0)
B(2,-3,-7,WATER:0)
B(3,-3,-7,PLANKS:5)
B(-3,-3,-6,PLANKS:5)
B(-2,-3,-6,WATER:0)
B(-1,-3,-6,WATER:0)
B(0,-3,-6,WATER:0)
B(1,-3,-6,WATER:0)
B(2,-3,-6,WATER:0)
B(3,-3,-6,PLANKS:5)
B(-4,-3,-5,PLANKS:5)
B(-3,-3,-5,WATER:0)
B(-2,-3,-5,WATER:0)
B(-1,-3,-5,WATER:0)
B(0,-3,-5,WATER:0)
B(1,-3,-5,WATER:0)
B(2,-3,-5,WATER:0)
B(3,-3,-5,WATER:0)
B(4,-3,-5,PLANKS:5)
B(-5,-3,-4,DISPENSER:4)
B(-4,-3,-4,CONCRETE:15)
B(-3,-3,-4,DISPENSER:1)
B(-2,-3,-4,SPRUCE_STAIRS:1)
B(-1,-3,-4,WATER:0)
B(0,-3,-4,SPRUCE_STAIRS:2)
B(1,-3,-4,WATER:0)
B(2,-3,-4,SPRUCE_STAIRS:0)
B(3,-3,-4,DISPENSER:1)
B(4,-3,-4,CONCRETE:15)
B(5,-3,-4,DISPENSER:5)
B(-4,-3,-3,PLANKS:5)
B(-3,-3,-3,WATER:0)
B(-2,-3,-3,WATER:0)
B(-1,-3,-3,WATER:0)
B(0,-3,-3,SPRUCE_STAIRS:7)
B(1,-3,-3,WATER:0)
B(2,-3,-3,WATER:0)
B(3,-3,-3,WATER:0)
B(4,-3,-3,PLANKS:5)
B(-4,-3,-2,PLANKS:5)
B(-3,-3,-2,WATER:0)
B(-2,-3,-2,WATER:0)
B(-1,-3,-2,WATER:0)
B(0,-3,-2,WATER:0)
B(1,-3,-2,WATER:0)
B(2,-3,-2,WATER:0)
B(3,-3,-2,WATER:0)
B(4,-3,-2,PLANKS:5)
B(-5,-3,-1,DISPENSER:4)
B(-4,-3,-1,CONCRETE:15)
B(-3,-3,-1,DISPENSER:1)
B(-2,-3,-1,SPRUCE_STAIRS:1)
B(-1,-3,-1,WATER:0)
B(0,-3,-1,LOG:1)
B(1,-3,-1,WATER:0)
B(2,-3,-1,SPRUCE_STAIRS:0)
B(3,-3,-1,DISPENSER:1)
B(4,-3,-1,CONCRETE:15)
B(5,-3,-1,DISPENSER:5)
B(-5,-3,0,PLANKS:5)
B(-4,-3,0,WATER:0)
B(-3,-3,0,WATER:0)
B(-2,-3,0,WATER:0)
B(-1,-3,0,WATER:0)
B(0,-3,0,WATER:0)
B(1,-3,0,WATER:0)
B(2,-3,0,WATER:0)
B(3,-3,0,WATER:0)
B(4,-3,0,WATER:0)
B(5,-3,0,PLANKS:5)
B(-5,-3,1,PLANKS:5)
B(-4,-3,1,WATER:0)
B(-3,-3,1,WATER:0)
B(-2,-3,1,WATER:0)
B(-1,-3,1,WATER:0)
B(0,-3,1,WATER:0)
B(1,-3,1,WATER:0)
B(2,-3,1,WATER:0)
B(3,-3,1,WATER:0)
B(4,-3,1,WATER:0)
B(5,-3,1,PLANKS:5)
B(-6,-3,2,DISPENSER:4)
B(-5,-3,2,CONCRETE:15)
B(-4,-3,2,DISPENSER:1)
B(-3,-3,2,SPRUCE_STAIRS:1)
B(-2,-3,2,WATER:0)
B(-1,-3,2,PLANKS:2)
B(0,-3,2,PLANKS:2)
B(1,-3,2,WATER:0)
B(2,-3,2,WATER:0)
B(3,-3,2,SPRUCE_STAIRS:0)
B(4,-3,2,DISPENSER:1)
B(5,-3,2,CONCRETE:15)
B(6,-3,2,DISPENSER:5)
B(-5,-3,3,PLANKS:5)
B(-4,-3,3,WATER:0)
B(-3,-3,3,WATER:0)
B(-2,-3,3,WATER:0)
B(-1,-3,3,PLANKS:2)
B(0,-3,3,PLANKS:2)
B(1,-3,3,WATER:0)
B(2,-3,3,WATER:0)
B(3,-3,3,WATER:0)
B(4,-3,3,WATER:0)
B(5,-3,3,PLANKS:5)
B(-5,-3,4,PLANKS:5)
B(-4,-3,4,WATER:0)
B(-3,-3,4,WATER:0)
B(-2,-3,4,WATER:0)
B(-1,-3,4,WATER:0)
B(0,-3,4,WATER:0)
B(1,-3,4,WATER:0)
B(2,-3,4,WATER:0)
B(3,-3,4,WATER:0)
B(4,-3,4,WATER:0)
B(5,-3,4,PLANKS:5)
B(-6,-3,5,DISPENSER:4)
B(-5,-3,5,CONCRETE:15)
B(-4,-3,5,DISPENSER:1)
B(-3,-3,5,SPRUCE_STAIRS:1)
B(-2,-3,5,WATER:0)
B(-1,-3,5,WATER:0)
B(0,-3,5,WATER:0)
B(1,-3,5,WATER:0)
B(2,-3,5,WATER:0)
B(3,-3,5,SPRUCE_STAIRS:0)
B(4,-3,5,DISPENSER:1)
B(5,-3,5,CONCRETE:15)
B(6,-3,5,DISPENSER:5)
B(-5,-3,6,PLANKS:5)
B(-4,-3,6,WATER:0)
B(-3,-3,6,WATER:0)
B(-2,-3,6,WATER:0)
B(-1,-3,6,WATER:0)
B(0,-3,6,WATER:0)
B(1,-3,6,WATER:0)
B(2,-3,6,WATER:0)
B(3,-3,6,WATER:0)
B(4,-3,6,WATER:0)
B(5,-3,6,PLANKS:5)
B(-4,-3,7,WATER:0)
B(-3,-3,7,WATER:0)
B(-2,-3,7,WATER:0)
B(-1,-3,7,WATER:0)
B(0,-3,7,WATER:0)
B(1,-3,7,WATER:0)
B(2,-3,7,WATER:0)
B(3,-3,7,WATER:0)
B(4,-3,7,WATER:0)
B(5,-3,7,PLANKS:5)
B(-4,-3,8,WATER:0)
B(-3,-3,8,WATER:0)
B(-2,-3,8,WATER:0)
B(-1,-3,8,WATER:0)
B(0,-3,8,WATER:0)
B(1,-3,8,WATER:0)
B(2,-3,8,WATER:0)
B(3,-3,8,SPRUCE_STAIRS:0)
B(4,-3,8,DISPENSER:1)
B(-3,-2,-7,PLANKS:0)
B(-2,-2,-7,WATER:0)
B(-1,-2,-7,WATER:0)
B(0,-2,-7,WATER:0)
B(1,-2,-7,WATER:0)
B(2,-2,-7,WATER:0)
B(3,-2,-7,PLANKS:0)
B(-4,-2,-6,PLANKS:0)
B(-3,-2,-6,WATER:0)
B(-2,-2,-6,WATER:0)
B(-1,-2,-6,WATER:0)
B(0,-2,-6,WATER:0)
B(1,-2,-6,WATER:0)
B(2,-2,-6,WATER:0)
B(3,-2,-6,WATER:0)
B(4,-2,-6,PLANKS:0)
B(-4,-2,-5,PLANKS:0)
B(-3,-2,-5,WATER:0)
B(-2,-2,-5,WATER:0)
B(-1,-2,-5,WATER:0)
B(0,-2,-5,WATER:0)
B(1,-2,-5,WATER:0)
B(2,-2,-5,WATER:0)
B(3,-2,-5,WATER:0)
B(4,-2,-5,PLANKS:0)
B(-5,-2,-4,WOODEN_SLAB:8)
B(-4,-2,-4,WATER:0)
B(-3,-2,-4,WATER:0)
B(-2,-2,-4,WATER:0)
B(-1,-2,-4,WATER:0)
B(0,-2,-4,WATER:0)
B(1,-2,-4,WATER:0)
B(2,-2,-4,WATER:0)
B(3,-2,-4,WATER:0)
B(5,-2,-4,WOODEN_SLAB:8)
B(-4,-2,-3,PLANKS:0)
B(-3,-2,-3,WATER:0)
B(-2,-2,-3,WATER:0)
B(-1,-2,-3,WATER:0)
B(0,-2,-3,SPRUCE_STAIRS:2)
B(1,-2,-3,WATER:0)
B(2,-2,-3,WATER:0)
B(3,-2,-3,WATER:0)
B(4,-2,-3,PLANKS:0)
B(-4,-2,-2,PLANKS:0)
B(-3,-2,-2,WATER:0)
B(-2,-2,-2,WATER:0)
B(-1,-2,-2,WATER:0)
B(0,-2,-2,SPRUCE_STAIRS:7)
B(1,-2,-2,WATER:0)
B(2,-2,-2,WATER:0)
B(3,-2,-2,WATER:0)
B(4,-2,-2,PLANKS:0)
B(-5,-2,-1,WOODEN_SLAB:8)
B(-4,-2,-1,WATER:0)
B(-3,-2,-1,WATER:0)
B(-2,-2,-1,WATER:0)
B(-1,-2,-1,WATER:0)
B(0,-2,-1,LOG:1)
B(1,-2,-1,WATER:0)
B(2,-2,-1,WATER:0)
B(3,-2,-1,WATER:0)
B(4,-2,-1,WATER:0)
B(5,-2,-1,WOODEN_SLAB:8)
B(-5,-2,0,PLANKS:0)
B(-4,-2,0,WATER:0)
B(-3,-2,0,WATER:0)
B(-2,-2,0,WATER:0)
B(-1,-2,0,WATER:0)
B(0,-2,0,WATER:0)
B(1,-2,0,WATER:0)
B(2,-2,0,WATER:0)
B(3,-2,0,WATER:0)
B(4,-2,0,WATER:0)
B(5,-2,0,PLANKS:0)
B(-5,-2,1,PLANKS:0)
B(-4,-2,1,WATER:0)
B(-3,-2,1,WATER:0)
B(-2,-2,1,WATER:0)
B(-1,-2,1,WATER:0)
B(0,-2,1,WATER:0)
B(1,-2,1,WATER:0)
B(2,-2,1,WATER:0)
B(3,-2,1,WATER:0)
B(4,-2,1,WATER:0)
B(5,-2,1,PLANKS:0)
B(-6,-2,2,WOODEN_SLAB:8)
B(-5,-2,2,WATER:0)
B(-4,-2,2,WATER:0)
B(-3,-2,2,WATER:0)
B(-2,-2,2,WATER:0)
B(-1,-2,2,PLANKS:2)
B(0,-2,2,PLANKS:2)
B(1,-2,2,WATER:0)
B(2,-2,2,WATER:0)
B(3,-2,2,WATER:0)
B(4,-2,2,WATER:0)
B(6,-2,2,WOODEN_SLAB:8)
B(-5,-2,3,PLANKS:0)
B(-4,-2,3,WATER:0)
B(-3,-2,3,WATER:0)
B(-2,-2,3,WATER:0)
B(-1,-2,3,PLANKS:2)
B(0,-2,3,PLANKS:2)
B(1,-2,3,WATER:0)
B(2,-2,3,WATER:0)
B(3,-2,3,WATER:0)
B(4,-2,3,WATER:0)
B(5,-2,3,PLANKS:0)
B(-5,-2,4,PLANKS:0)
B(-4,-2,4,WATER:0)
B(-3,-2,4,WATER:0)
B(-2,-2,4,WATER:0)
B(-1,-2,4,WATER:0)
B(0,-2,4,WATER:0)
B(1,-2,4,WATER:0)
B(2,-2,4,WATER:0)
B(3,-2,4,WATER:0)
B(4,-2,4,WATER:0)
B(5,-2,4,PLANKS:0)
B(-6,-2,5,WOODEN_SLAB:8)
B(-5,-2,5,WATER:0)
B(-4,-2,5,WATER:0)
B(-3,-2,5,WATER:0)
B(-2,-2,5,WATER:0)
B(-1,-2,5,WATER:0)
B(0,-2,5,WATER:0)
B(1,-2,5,WATER:0)
B(2,-2,5,WATER:0)
B(3,-2,5,WATER:0)
B(4,-2,5,WATER:0)
B(5,-2,5,WATER:0)
B(6,-2,5,WOODEN_SLAB:8)
B(-5,-2,6,PLANKS:0)
B(-4,-2,6,WATER:0)
B(-3,-2,6,WATER:0)
B(-2,-2,6,WATER:0)
B(-1,-2,6,WATER:0)
B(0,-2,6,WATER:0)
B(1,-2,6,WATER:0)
B(2,-2,6,WATER:0)
B(3,-2,6,WATER:0)
B(4,-2,6,WATER:0)
B(5,-2,6,PLANKS:0)
B(-4,-2,7,WATER:0)
B(-3,-2,7,WATER:0)
B(-2,-2,7,WATER:0)
B(-1,-2,7,WATER:0)
B(0,-2,7,WATER:0)
B(1,-2,7,WATER:0)
B(2,-2,7,WATER:0)
B(3,-2,7,WATER:0)
B(4,-2,7,WATER:0)
B(5,-2,7,PLANKS:0)
B(-4,-2,8,WATER:0)
B(-3,-2,8,WATER:0)
B(-2,-2,8,WATER:0)
B(-1,-2,8,WATER:0)
B(0,-2,8,WATER:0)
B(1,-2,8,WATER:0)
B(2,-2,8,WATER:0)
B(-3,-1,-7,PLANKS:5)
B(-2,-1,-7,WATER:0)
B(-1,-1,-7,WATER:0)
B(0,-1,-7,WATER:0)
B(1,-1,-7,WATER:0)
B(2,-1,-7,WATER:0)
B(3,-1,-7,PLANKS:5)
B(-4,-1,-6,PLANKS:5)
B(-3,-1,-6,WATER:0)
B(-2,-1,-6,WATER:0)
B(-1,-1,-6,WATER:0)
B(0,-1,-6,WATER:0)
B(1,-1,-6,WATER:0)
B(2,-1,-6,WATER:0)
B(3,-1,-6,WATER:0)
B(4,-1,-6,PLANKS:5)
B(-4,-1,-5,PLANKS:5)
B(-3,-1,-5,WATER:0)
B(-2,-1,-5,WATER:0)
B(-1,-1,-5,WATER:0)
B(0,-1,-5,WATER:0)
B(1,-1,-5,WATER:0)
B(2,-1,-5,WATER:0)
B(3,-1,-5,WATER:0)
B(4,-1,-5,PLANKS:5)
B(-4,-1,-4,PLANKS:5)
B(-3,-1,-4,WATER:0)
B(-2,-1,-4,WATER:0)
B(-1,-1,-4,WATER:0)
B(0,-1,-4,WATER:0)
B(1,-1,-4,WATER:0)
B(2,-1,-4,WATER:0)
B(3,-1,-4,WATER:0)
B(4,-1,-4,PLANKS:5)
B(-4,-1,-3,PLANKS:5)
B(-3,-1,-3,WATER:0)
B(-2,-1,-3,WATER:0)
B(-1,-1,-3,WATER:0)
B(0,-1,-3,WATER:0)
B(1,-1,-3,WATER:0)
B(2,-1,-3,WATER:0)
B(3,-1,-3,WATER:0)
B(4,-1,-3,PLANKS:5)
B(-4,-1,-2,PLANKS:5)
B(-3,-1,-2,WATER:0)
B(-2,-1,-2,WOODEN_SLAB:8)
B(-1,-1,-2,WOODEN_SLAB:8)
B(0,-1,-2,SPRUCE_STAIRS:2)
B(1,-1,-2,WOODEN_SLAB:8)
B(2,-1,-2,WOODEN_SLAB:8)
B(3,-1,-2,WATER:0)
B(4,-1,-2,PLANKS:5)
B(-5,-1,-1,WOODEN_SLAB:13)
B(-4,-1,-1,PLANKS:5)
B(-3,-1,-1,WOODEN_SLAB:8)
B(-2,-1,-1,WOODEN_SLAB:8)
B(-1,-1,-1,WOODEN_SLAB:8)
B(0,-1,-1,LOG:1)
B(1,-1,-1,WOODEN_SLAB:8)
B(2,-1,-1,WOODEN_SLAB:8)
B(3,-1,-1,WOODEN_SLAB:8)
B(4,-1,-1,PLANKS:5)
B(5,-1,-1,WOODEN_SLAB:13)
B(-5,-1,0,PLANKS:5)
B(-4,-1,0,WOODEN_SLAB:8)
B(-3,-1,0,WOODEN_SLAB:8)
B(-2,-1,0,WOODEN_SLAB:8)
B(-1,-1,0,WOODEN_SLAB:8)
B(0,-1,0,WOODEN_SLAB:8)
B(1,-1,0,WOODEN_SLAB:8)
B(2,-1,0,WOODEN_SLAB:8)
B(3,-1,0,WOODEN_SLAB:8)
B(4,-1,0,WOODEN_SLAB:8)
B(5,-1,0,PLANKS:5)
B(-6,-1,1,WOODEN_SLAB:13)
B(-5,-1,1,PLANKS:5)
B(-4,-1,1,WOODEN_SLAB:8)
B(-3,-1,1,WOODEN_SLAB:8)
B(-2,-1,1,WOODEN_SLAB:8)
B(-1,-1,1,WOODEN_SLAB:8)
B(0,-1,1,WOODEN_SLAB:8)
B(1,-1,1,WOODEN_SLAB:8)
B(2,-1,1,WOODEN_SLAB:8)
B(3,-1,1,WOODEN_SLAB:8)
B(4,-1,1,WOODEN_SLAB:8)
B(5,-1,1,PLANKS:5)
B(6,-1,1,WOODEN_SLAB:13)
B(-6,-1,2,WOODEN_SLAB:13)
B(-5,-1,2,PLANKS:5)
B(-4,-1,2,WOODEN_SLAB:8)
B(-3,-1,2,WOODEN_SLAB:8)
B(-2,-1,2,WOODEN_SLAB:8)
B(-1,-1,2,WOODEN_SLAB:8)
B(0,-1,2,WOODEN_SLAB:8)
B(1,-1,2,WOODEN_SLAB:8)
B(2,-1,2,WOODEN_SLAB:8)
B(3,-1,2,WOODEN_SLAB:8)
B(4,-1,2,WOODEN_SLAB:8)
B(5,-1,2,PLANKS:5)
B(6,-1,2,WOODEN_SLAB:13)
B(-6,-1,3,WOODEN_SLAB:13)
B(-5,-1,3,PLANKS:5)
B(-4,-1,3,WOODEN_SLAB:8)
B(-3,-1,3,WOODEN_SLAB:8)
B(-2,-1,3,WOODEN_SLAB:8)
B(-1,-1,3,WOODEN_SLAB:8)
B(0,-1,3,WOODEN_SLAB:8)
B(1,-1,3,WOODEN_SLAB:8)
B(2,-1,3,WOODEN_SLAB:8)
B(3,-1,3,WOODEN_SLAB:8)
B(4,-1,3,WOODEN_SLAB:8)
B(5,-1,3,PLANKS:5)
B(6,-1,3,WOODEN_SLAB:13)
B(-5,-1,4,PLANKS:5)
B(-4,-1,4,WOODEN_SLAB:8)
B(-3,-1,4,WOODEN_SLAB:8)
B(-2,-1,4,WOODEN_SLAB:8)
B(-1,-1,4,WOODEN_SLAB:8)
B(0,-1,4,WOODEN_SLAB:8)
B(1,-1,4,WOODEN_SLAB:8)
B(2,-1,4,WOODEN_SLAB:8)
B(3,-1,4,WOODEN_SLAB:8)
B(4,-1,4,WOODEN_SLAB:8)
B(5,-1,4,PLANKS:5)
B(-5,-1,5,PLANKS:5)
B(-4,-1,5,WOODEN_SLAB:8)
B(-3,-1,5,WOODEN_SLAB:8)
B(-2,-1,5,WOODEN_SLAB:8)
B(-1,-1,5,WOODEN_SLAB:8)
B(0,-1,5,WOODEN_SLAB:8)
B(1,-1,5,WOODEN_SLAB:8)
B(2,-1,5,WOODEN_SLAB:8)
B(3,-1,5,WOODEN_SLAB:8)
B(4,-1,5,WOODEN_SLAB:8)
B(5,-1,5,PLANKS:5)
B(-5,-1,6,PLANKS:5)
B(-4,-1,6,WOODEN_SLAB:8)
B(-3,-1,6,WOODEN_SLAB:8)
B(-2,-1,6,WOODEN_SLAB:8)
B(0,-1,6,WOODEN_SLAB:9)
B(2,-1,6,WOODEN_SLAB:8)
B(3,-1,6,WOODEN_SLAB:8)
B(4,-1,6,WOODEN_SLAB:8)
B(5,-1,6,PLANKS:5)
B(-5,-1,7,PLANKS:5)
B(-4,-1,7,WOODEN_SLAB:8)
B(-3,-1,7,WOODEN_SLAB:8)
B(-2,-1,7,WOODEN_SLAB:8)
B(0,-1,7,WOODEN_SLAB:9)
B(2,-1,7,WOODEN_SLAB:8)
B(3,-1,7,WOODEN_SLAB:8)
B(4,-1,7,WOODEN_SLAB:8)
B(5,-1,7,PLANKS:5)
B(-4,-1,8,WOODEN_SLAB:8)
B(-3,-1,8,WOODEN_SLAB:8)
B(-2,-1,8,WOODEN_SLAB:8)
B(0,-1,8,WOODEN_SLAB:9)
B(2,-1,8,WOODEN_SLAB:8)
B(-3,0,-7,DARK_OAK_STAIRS:2)
B(-2,0,-7,WOODEN_SLAB:8)
B(-1,0,-7,WOODEN_SLAB:8)
B(0,0,-7,WOODEN_SLAB:8)
B(1,0,-7,WOODEN_SLAB:8)
B(2,0,-7,WOODEN_SLAB:8)
B(3,0,-7,DARK_OAK_STAIRS:2)
B(-4,0,-6,PLANKS:5)
B(-3,0,-6,WOODEN_SLAB:8)
B(-2,0,-6,WOODEN_SLAB:8)
B(-1,0,-6,WOODEN_SLAB:8)
B(0,0,-6,WOODEN_SLAB:8)
B(1,0,-6,WOODEN_SLAB:8)
B(2,0,-6,WOODEN_SLAB:8)
B(3,0,-6,WOODEN_SLAB:8)
B(4,0,-6,PLANKS:5)
B(-4,0,-5,DARK_OAK_STAIRS:7)
B(-3,0,-5,DOUBLE_WOODEN_SLAB:0)
B(-2,0,-5,WOODEN_SLAB:8)
B(-1,0,-5,WOODEN_SLAB:0)
B(0,0,-5,WOODEN_SLAB:0)
B(1,0,-5,WOODEN_SLAB:0)
B(2,0,-5,WOODEN_SLAB:8)
B(3,0,-5,DOUBLE_WOODEN_SLAB:0)
B(4,0,-5,DARK_OAK_STAIRS:7)
B(-4,0,-4,WOODEN_SLAB:13)
B(-3,0,-4,WOODEN_SLAB:0)
B(-2,0,-4,WOODEN_SLAB:0)
B(-1,0,-4,SPRUCE_STAIRS:0)
B(0,0,-4,TRAPDOOR:5)
B(1,0,-4,SPRUCE_STAIRS:1)
B(2,0,-4,WOODEN_SLAB:0)
B(3,0,-4,WOODEN_SLAB:0)
B(4,0,-4,WOODEN_SLAB:13)
B(-4,0,-3,WOODEN_SLAB:13)
B(-3,0,-3,WOODEN_SLAB:0)
B(-2,0,-3,WOODEN_SLAB:0)
B(-1,0,-3,SPRUCE_STAIRS:3)
B(0,0,-3,WATER:0)
B(1,0,-3,SPRUCE_STAIRS:3)
B(2,0,-3,WOODEN_SLAB:0)
B(3,0,-3,WOODEN_SLAB:0)
B(4,0,-3,WOODEN_SLAB:13)
B(-4,0,-2,DARK_OAK_STAIRS:6)
B(-3,0,-2,WOODEN_SLAB:0)
B(3,0,-2,WOODEN_SLAB:0)
B(4,0,-2,DARK_OAK_STAIRS:6)
B(-4,0,-1,PLANKS:5)
B(0,0,-1,PLANKS:5)
B(4,0,-1,PLANKS:5)
B(-4,0,0,PLANKS:5)
B(4,0,0,DOUBLE_WOODEN_SLAB:5)
B(-5,0,1,PLANKS:5)
B(-5,0,2,PLANKS:5)
B(-3,0,2,PLANKS:2)
B(-2,0,2,PLANKS:2)
B(-5,0,3,PLANKS:5)
B(-3,0,3,PLANKS:2)
B(-2,0,3,PLANKS:2)
B(3,0,3,PLANKS:2)
B(4,0,3,PLANKS:2)
B(-5,0,4,PLANKS:5)
B(-3,0,4,PLANKS:2)
B(-2,0,4,PLANKS:2)
B(3,0,4,PLANKS:2)
B(4,0,4,PLANKS:2)
B(-1,0,5,SPRUCE_STAIRS:0)
B(1,0,5,SPRUCE_STAIRS:1)
B(-1,0,6,TRAPDOOR:2)
B(0,0,6,WOODEN_SLAB:1)
B(1,0,6,TRAPDOOR:3)
B(-1,0,7,TRAPDOOR:2)
B(0,0,7,WOODEN_SLAB:1)
B(1,0,7,TRAPDOOR:3)
B(-1,0,8,TRAPDOOR:2)
B(0,0,8,WOODEN_SLAB:1)
B(1,0,8,TRAPDOOR:3)
B(-3,1,-7,PLANKS:5)
B(-1,1,-7,SPRUCE_STAIRS:3)
B(1,1,-7,SPRUCE_STAIRS:3)
B(3,1,-7,PLANKS:5)
B(-3,1,-6,PLANKS:5)
B(3,1,-6,PLANKS:5)
B(-4,1,-5,DARK_OAK_STAIRS:7)
B(4,1,-5,DARK_OAK_STAIRS:7)
B(-4,1,-4,DARK_OAK_STAIRS:6)
B(4,1,-4,DARK_OAK_STAIRS:6)
B(-4,1,-3,PLANKS:5)
B(0,1,-3,WATER:0)
B(4,1,-3,PLANKS:5)
B(-4,1,-2,WOODEN_SLAB:5)
B(4,1,-2,WOODEN_SLAB:5)
B(-4,1,-1,WOODEN_SLAB:5)
B(0,1,-1,PLANKS:5)
B(4,1,-1,WOODEN_SLAB:5)
B(-3,1,2,PLANKS:2)
B(-2,1,2,PLANKS:2)
B(-3,1,3,PLANKS:2)
B(-2,1,3,PLANKS:2)
B(0,1,3,SPRUCE_STAIRS:6)
B(3,1,3,PLANKS:2)
B(4,1,3,PLANKS:2)
B(-3,1,4,PLANKS:2)
B(-2,1,4,PLANKS:2)
B(-1,1,4,WOODEN_SLAB:9)
B(0,1,4,DOUBLE_WOODEN_SLAB:1)
B(1,1,4,WOODEN_SLAB:9)
B(3,1,4,PLANKS:2)
B(4,1,4,PLANKS:2)
B(-1,1,5,SPRUCE_STAIRS:4)
B(0,1,5,WOODEN_SLAB:1)
B(1,1,5,SPRUCE_STAIRS:5)
B(-1,1,6,SPRUCE_STAIRS:4)
B(0,1,6,WOODEN_SLAB:1)
B(1,1,6,SPRUCE_STAIRS:5)
B(-1,1,7,SPRUCE_STAIRS:4)
B(0,1,7,WOODEN_SLAB:1)
B(1,1,7,SPRUCE_STAIRS:5)
B(-1,1,8,SPRUCE_STAIRS:4)
B(0,1,8,WOODEN_SLAB:1)
B(1,1,8,SPRUCE_STAIRS:5)
B(-3,2,-7,WOODEN_SLAB:5)
B(3,2,-7,WOODEN_SLAB:5)
B(-3,2,-6,WOODEN_SLAB:5)
B(-4,2,-5,WOODEN_SLAB:5)
B(4,2,-5,WOODEN_SLAB:5)
B(0,2,-4,WATER:0)
B(1,2,-4,WATER:0)
B(-1,2,-3,WATER:0)
B(0,2,-3,WATER:0)
B(1,2,-3,WATER:0)
B(0,2,-2,WATER:0)
B(0,2,2,SPRUCE_STAIRS:6)
B(-1,2,3,SPRUCE_STAIRS:6)
B(0,2,3,WOODEN_SLAB:1)
B(1,2,3,SPRUCE_STAIRS:6)
B(-1,2,4,DOUBLE_WOODEN_SLAB:1)
B(0,2,4,TRAPDOOR:3)
B(1,2,4,DOUBLE_WOODEN_SLAB:1)
B(-1,2,5,DOUBLE_WOODEN_SLAB:1)
B(1,2,5,DOUBLE_WOODEN_SLAB:1)
B(-1,2,6,DOUBLE_WOODEN_SLAB:1)
B(0,2,6,TRAPDOOR:3)
B(1,2,6,DOUBLE_WOODEN_SLAB:1)
B(-1,2,7,WOODEN_SLAB:1)
B(1,2,7,WOODEN_SLAB:1)
B(-1,2,8,WOODEN_SLAB:1)
B(0,2,8,TRAPDOOR:3)
B(1,2,8,WOODEN_SLAB:1)
B(-1,3,-4,WATER:0)
B(0,3,-4,WATER:0)
B(1,3,-4,WATER:0)
B(-2,3,-3,WATER:0)
B(-1,3,-3,WATER:0)
B(0,3,-3,WATER:0)
B(1,3,-3,WATER:0)
B(-1,3,-2,WATER:0)
B(0,3,-2,WATER:0)

E(1,-6,8,GUARDIAN,1)
E(-2,-5,-3,GUARDIAN,1)
E(2,-5,-2,GUARDIAN,1)
E(-4,-5,4,SQUID,1)
