Author: Bo3 BulkEdit

Description: Converted Schematic - Modified by Bo3BulkEdit

Version: 3

SettingsMode: WriteDisable

IsOTGPlus: false
Tree: false
Frequency: 1
Rarity: 100
RotateRandomly: false
SpawnHeight: randomY
MaxBranchDepth: 20
ExcludedBiomes: All

MinHeight: 0
MaxHeight: 256

SourceBlocks: AIR
MaxPercentageOutsideSourceBlock: 100
OutsideSourceBlock: placeAnyway

B(0,-8,8,PLANKS:1)
B(0,-7,7,PLANKS:1)
B(-1,-7,8,PLANKS:1)
B(0,-7,8,WATER:0)
B(1,-7,8,PLANKS:1)
B(0,-6,6,PLANKS:1)
B(0,-6,7,PLANKS:1)
B(-2,-6,8,PLANKS:1)
B(-1,-6,8,PLANKS:1)
RB(0,-6,8,CHEST:3,../NBT/StructureLoot/JunkChest_1.nbt,15,CHEST:3,../NBT/StructureLoot/JunkChest_2.nbt,15,CHEST:3,../NBT/StructureLoot/JunkChest_3.nbt,15,CHEST:3,../NBT/StructureLoot/JunkChest_4.nbt,15,CHEST:3,../NBT/StructureLoot/JunkChest_5.nbt,15,CHEST:3,../NBT/StructureLoot/Common1.nbt,15,CHEST:3,../NBT/StructureLoot/Common2.nbt,15,CHEST:3,../NBT/StructureLoot/Common3.nbt,15,CHEST:3,../NBT/StructureLoot/Common4.nbt,15,CHEST:3,../NBT/StructureLoot/Common5.nbt,15,CHEST:3,../NBT/StructureLoot/Common6.nbt,15,CHEST:3,../NBT/StructureLoot/Common7.nbt,15,CHEST:3,../NBT/StructureLoot/Common8.nbt,15,CHEST:3,../NBT/StructureLoot/Common9.nbt,15,CHEST:3,../NBT/StructureLoot/Common10.nbt,15,CHEST:3,../NBT/StructureLoot/Common11.nbt,15,CHEST:3,../NBT/StructureLoot/Common12.nbt,15,CHEST:3,../NBT/StructureLoot/Common13.nbt,15,CHEST:3,../NBT/StructureLoot/Common14.nbt,15,CHEST:3,../NBT/StructureLoot/Common15.nbt,100)
B(1,-6,8,PLANKS:1)
B(2,-6,8,PLANKS:1)
B(0,-5,6,PLANKS:1)
B(-2,-5,7,PLANKS:1)
B(-1,-5,7,PLANKS:1)
B(0,-5,7,WATER:0)
B(1,-5,7,PLANKS:1)
B(2,-5,7,PLANKS:1)
B(-3,-5,8,PLANKS:1)
B(-2,-5,8,WATER:0)
B(-1,-5,8,WATER:0)
B(0,-5,8,WATER:0)
B(1,-5,8,WATER:0)
B(2,-5,8,WATER:0)
B(3,-5,8,PLANKS:1)
B(0,-4,4,PLANKS:1)
B(-1,-4,5,PLANKS:1)
B(0,-4,5,PLANKS:1)
B(1,-4,5,PLANKS:1)
B(-1,-4,6,PLANKS:1)
B(0,-4,6,WOODEN_SLAB:8)
B(1,-4,6,PLANKS:1)
B(-2,-4,7,PLANKS:1)
B(-1,-4,7,WOODEN_SLAB:8)
B(0,-4,7,WOODEN_SLAB:8)
B(1,-4,7,WOODEN_SLAB:8)
B(2,-4,7,PLANKS:1)
B(-3,-4,8,PLANKS:1)
B(-2,-4,8,WOODEN_SLAB:8)
B(-1,-4,8,WOODEN_SLAB:8)
B(0,-4,8,WOODEN_SLAB:8)
B(1,-4,8,WOODEN_SLAB:8)
B(2,-4,8,WOODEN_SLAB:8)
B(3,-4,8,PLANKS:1)
B(0,-3,3,PLANKS:5)
B(-1,-3,4,PLANKS:5)
B(0,-3,4,PLANKS:5)
B(1,-3,4,PLANKS:5)
B(-2,-3,5,PLANKS:5)
B(-1,-3,5,PLANKS:5)
B(0,-3,5,PLANKS:5)
B(1,-3,5,PLANKS:5)
B(2,-3,5,PLANKS:5)
B(-2,-3,6,PLANKS:5)
B(-1,-3,6,WATER:0)
B(0,-3,6,PLANKS:5)
B(1,-3,6,WATER:0)
B(2,-3,6,PLANKS:5)
B(-2,-3,7,PLANKS:5)
B(-1,-3,7,WATER:0)
B(0,-3,7,PLANKS:5)
B(1,-3,7,WATER:0)
B(2,-3,7,PLANKS:5)
B(-3,-3,8,PLANKS:5)
B(-2,-3,8,WATER:0)
B(-1,-3,8,WATER:0)
B(0,-3,8,WATER:0)
B(1,-3,8,WATER:0)
RB(2,-3,8,CHEST:4,../NBT/StructureLoot/JunkChest_1.nbt,15,CHEST:4,../NBT/StructureLoot/JunkChest_2.nbt,15,CHEST:4,../NBT/StructureLoot/JunkChest_3.nbt,15,CHEST:4,../NBT/StructureLoot/JunkChest_4.nbt,15,CHEST:4,../NBT/StructureLoot/JunkChest_5.nbt,15,CHEST:4,../NBT/StructureLoot/Common1.nbt,15,CHEST:4,../NBT/StructureLoot/Common2.nbt,15,CHEST:4,../NBT/StructureLoot/Common3.nbt,15,CHEST:4,../NBT/StructureLoot/Common4.nbt,15,CHEST:4,../NBT/StructureLoot/Common5.nbt,15,CHEST:4,../NBT/StructureLoot/Common6.nbt,15,CHEST:4,../NBT/StructureLoot/Common7.nbt,15,CHEST:4,../NBT/StructureLoot/Common8.nbt,15,CHEST:4,../NBT/StructureLoot/Common9.nbt,15,CHEST:4,../NBT/StructureLoot/Common10.nbt,15,CHEST:4,../NBT/StructureLoot/Common11.nbt,15,CHEST:4,../NBT/StructureLoot/Common12.nbt,15,CHEST:4,../NBT/StructureLoot/Common13.nbt,15,CHEST:4,../NBT/StructureLoot/Common14.nbt,15,CHEST:4,../NBT/StructureLoot/Common15.nbt,100)
B(3,-3,8,PLANKS:5)
B(0,-2,0,WOODEN_SLAB:8)
B(0,-2,1,OAK_STAIRS:6)
B(0,-2,2,PLANKS:0)
B(-1,-2,3,PLANKS:0)
B(0,-2,3,WOODEN_SLAB:8)
B(1,-2,3,PLANKS:0)
B(-1,-2,4,PLANKS:0)
B(0,-2,4,PLANKS:0)
B(1,-2,4,PLANKS:0)
B(-2,-2,5,PLANKS:0)
B(-1,-2,5,PLANKS:0)
B(0,-2,5,PLANKS:0)
B(1,-2,5,PLANKS:0)
B(2,-2,5,PLANKS:0)
B(-2,-2,6,PLANKS:0)
B(-1,-2,6,WATER:0)
B(0,-2,6,PLANKS:0)
B(1,-2,6,WATER:0)
B(2,-2,6,PLANKS:0)
B(-2,-2,7,PLANKS:0)
B(-1,-2,7,WATER:0)
B(0,-2,7,PLANKS:0)
B(1,-2,7,WATER:0)
B(2,-2,7,PLANKS:0)
B(-3,-2,8,PLANKS:0)
B(-2,-2,8,WATER:0)
B(-1,-2,8,WATER:0)
B(0,-2,8,WATER:0)
B(1,-2,8,WATER:0)
B(2,-2,8,WATER:0)
B(3,-2,8,PLANKS:0)
B(0,-1,1,DARK_OAK_STAIRS:6)
B(0,-1,2,WOODEN_SLAB:5)
B(-2,-1,4,WOODEN_SLAB:13)
B(0,-1,4,WOODEN_SLAB:9)
B(2,-1,4,WOODEN_SLAB:13)
B(-2,-1,5,WOODEN_SLAB:13)
B(0,-1,5,DOUBLE_WOODEN_SLAB:1)
B(2,-1,5,WOODEN_SLAB:13)
B(-3,-1,6,WOODEN_SLAB:13)
B(-1,-1,6,TRAPDOOR:0)
B(0,-1,6,DOUBLE_WOODEN_SLAB:1)
B(1,-1,6,TRAPDOOR:0)
B(3,-1,6,WOODEN_SLAB:13)
B(-3,-1,7,WOODEN_SLAB:5)
B(-2,-1,7,PLANKS:5)
B(-1,-1,7,PLANKS:5)
B(0,-1,7,PLANKS:5)
B(1,-1,7,PLANKS:5)
B(2,-1,7,PLANKS:5)
B(3,-1,7,WOODEN_SLAB:5)
B(-3,-1,8,PLANKS:5)
B(-2,-1,8,WATER:0)
B(-1,-1,8,WATER:0)
B(0,-1,8,WATER:0)
B(1,-1,8,WATER:0)
B(2,-1,8,WATER:0)
B(3,-1,8,PLANKS:5)
B(-1,0,1,WOODEN_SLAB:5)
B(0,0,1,DARK_OAK_STAIRS:3)
B(1,0,1,WOODEN_SLAB:5)
B(-1,0,2,WOODEN_SLAB:5)
B(0,0,2,WOODEN_SLAB:9)
B(1,0,2,WOODEN_SLAB:5)
B(-2,0,3,WOODEN_SLAB:5)
B(0,0,3,DOUBLE_WOODEN_SLAB:1)
B(2,0,3,WOODEN_SLAB:5)
B(0,0,4,DOUBLE_WOODEN_SLAB:1)
B(0,0,5,WOODEN_SLAB:1)
B(-2,0,7,DARK_OAK_STAIRS:1)
B(-1,0,7,WOODEN_SLAB:5)
B(0,0,7,WOODEN_SLAB:5)
B(1,0,7,WOODEN_SLAB:5)
B(2,0,7,DARK_OAK_STAIRS:0)
B(-3,0,8,DARK_OAK_STAIRS:3)
B(-2,0,8,WOODEN_SLAB:8)
B(-1,0,8,WOODEN_SLAB:8)
B(0,0,8,WOODEN_SLAB:8)
B(1,0,8,WOODEN_SLAB:8)
B(2,0,8,WOODEN_SLAB:8)
B(3,0,8,DARK_OAK_STAIRS:3)
B(0,1,0,WOODEN_SLAB:9)
B(0,1,1,DOUBLE_WOODEN_SLAB:1)
B(0,1,2,DOUBLE_WOODEN_SLAB:1)
B(0,1,3,WOODEN_SLAB:1)
B(-1,1,6,DISPENSER:2)
B(1,1,6,DISPENSER:2)
B(-2,1,7,PLANKS:5)
B(-1,1,7,CONCRETE:15)
B(0,1,7,PLANKS:5)
B(1,1,7,CONCRETE:15)
B(2,1,7,PLANKS:5)
B(-3,1,8,PLANKS:5)
B(-1,1,8,DISPENSER:9)
B(1,1,8,DISPENSER:9)
B(3,1,8,PLANKS:5)
B(0,2,-2,WOODEN_SLAB:9)
B(0,2,-1,DOUBLE_WOODEN_SLAB:1)
B(0,2,0,DOUBLE_WOODEN_SLAB:1)
B(0,2,1,WOODEN_SLAB:1)
B(-2,2,7,WOODEN_SLAB:5)
B(-1,2,7,WOODEN_SLAB:5)
B(0,2,7,WOODEN_SLAB:5)
B(1,2,7,WOODEN_SLAB:5)
B(2,2,7,WOODEN_SLAB:5)
B(-3,2,8,WOODEN_SLAB:5)
B(-1,2,8,LEVER:14)
B(1,2,8,LEVER:14)
B(3,2,8,WOODEN_SLAB:5)
B(-4,3,-3,WOODEN_SLAB:1)
B(-3,3,-3,WOODEN_SLAB:1)
B(0,3,-3,WOODEN_SLAB:9)
B(-2,3,-2,WOODEN_SLAB:1)
B(-1,3,-2,WOODEN_SLAB:1)
B(0,3,-2,DOUBLE_WOODEN_SLAB:1)
B(1,3,-2,WOODEN_SLAB:1)
B(2,3,-2,WOODEN_SLAB:1)
B(0,3,-1,WOODEN_SLAB:1)
B(0,4,-5,WOODEN_SLAB:9)
B(0,4,-4,DOUBLE_WOODEN_SLAB:1)
B(0,4,-3,WOODEN_SLAB:1)
B(0,5,-7,WOODEN_SLAB:9)
B(0,5,-6,DOUBLE_WOODEN_SLAB:1)
B(0,5,-5,WOODEN_SLAB:1)
B(0,6,-7,WOODEN_SLAB:1)

