Author: Bo3 BulkEdit

Description: Converted Schematic - Modified by Bo3BulkEdit

Version: 3

SettingsMode: WriteDisable

IsOTGPlus: false
Tree: false
Frequency: 1
Rarity: 100
RotateRandomly: false
SpawnHeight: randomY
MaxBranchDepth: 20
ExcludedBiomes: All

MinHeight: 0
MaxHeight: 256

SourceBlocks: AIR
MaxPercentageOutsideSourceBlock: 100
OutsideSourceBlock: placeAnyway

B(0,-8,-7,WOODEN_SLAB:9)
B(0,-7,-7,WOODEN_SLAB:1)
B(0,-7,-6,DOUBLE_WOODEN_SLAB:1)
B(0,-7,-5,WOODEN_SLAB:9)
B(0,-6,-5,WOODEN_SLAB:1)
B(0,-6,-4,DOUBLE_WOODEN_SLAB:1)
B(0,-6,-3,WOODEN_SLAB:9)
B(0,-5,-3,WOODEN_SLAB:1)
B(3,-5,-3,WOODEN_SLAB:9)
B(4,-5,-3,WOODEN_SLAB:9)
B(-2,-5,-2,WOODEN_SLAB:9)
B(-1,-5,-2,WOODEN_SLAB:9)
B(0,-5,-2,DOUBLE_WOODEN_SLAB:1)
B(1,-5,-2,WOODEN_SLAB:9)
B(2,-5,-2,WOODEN_SLAB:9)
B(0,-5,-1,WOODEN_SLAB:9)
B(0,-4,-2,WOODEN_SLAB:1)
B(0,-4,-1,DOUBLE_WOODEN_SLAB:1)
B(0,-4,0,DOUBLE_WOODEN_SLAB:1)
B(0,-4,1,WOODEN_SLAB:9)
B(-2,-4,7,WOODEN_SLAB:13)
B(-1,-4,7,WOODEN_SLAB:13)
B(0,-4,7,WOODEN_SLAB:13)
B(1,-4,7,WOODEN_SLAB:13)
B(2,-4,7,WOODEN_SLAB:13)
B(-3,-4,8,WOODEN_SLAB:13)
B(3,-4,8,WOODEN_SLAB:13)
B(0,-3,0,WOODEN_SLAB:1)
B(0,-3,1,DOUBLE_WOODEN_SLAB:1)
B(0,-3,2,DOUBLE_WOODEN_SLAB:1)
B(0,-3,3,WOODEN_SLAB:9)
B(-2,-3,6,WATER:0)
B(-1,-3,6,DISPENSER:2)
B(1,-3,6,DISPENSER:2)
B(-2,-3,7,PLANKS:5)
B(-1,-3,7,CONCRETE:15)
B(0,-3,7,PLANKS:5)
B(1,-3,7,CONCRETE:15)
B(2,-3,7,PLANKS:5)
B(-3,-3,8,PLANKS:5)
B(-2,-3,8,WATER:0)
B(-1,-3,8,DISPENSER:0)
RB(0,-3,8,CHEST:3,../NBT/LoreStoryline/LoreGeneric_5.nbt,2,CHEST:3,../NBT/LoreStoryline/LoreGeneric_4.nbt,2,CHEST:3,../NBT/LoreStoryline/LoreGeneric_3.nbt,2,CHEST:3,../NBT/LoreStoryline/LoreGeneric_2.nbt,2,CHEST:3,../NBT/LoreStoryline/LoreGeneric_1.nbt,2,CHEST:3,../NBT/LoreStoryline/LoreShipSunk_5.nbt,3,CHEST:3,../NBT/LoreStoryline/LoreShipSunk_4.nbt,3,CHEST:3,../NBT/LoreStoryline/LoreShipSunk_3.nbt,3,CHEST:3,../NBT/LoreStoryline/LoreShipSunk_2.nbt,3,CHEST:3,../NBT/LoreStoryline/LoreShipSunk_1.nbt,3,CHEST:3,../NBT/StructureLoot/Common1.nbt,3,CHEST:3,../NBT/StructureLoot/Common2.nbt,3,CHEST:3,../NBT/StructureLoot/Common3.nbt,3,CHEST:3,../NBT/StructureLoot/Common4.nbt,3,CHEST:3,../NBT/StructureLoot/Common5.nbt,3,CHEST:3,../NBT/StructureLoot/Common5.nbt,3,CHEST:3,../NBT/StructureLoot/Common6.nbt,3,CHEST:3,../NBT/StructureLoot/Common7.nbt,3,CHEST:3,../NBT/StructureLoot/Common8.nbt,3,CHEST:3,../NBT/StructureLoot/Common9.nbt,3,CHEST:3,../NBT/StructureLoot/Common10.nbt,3,CHEST:3,../NBT/StructureLoot/Common11.nbt,3,CHEST:3,../NBT/StructureLoot/Common12.nbt,3,CHEST:3,../NBT/StructureLoot/Common13.nbt,3,CHEST:3,../NBT/StructureLoot/Common14.nbt,3,CHEST:3,../NBT/StructureLoot/Common15.nbt,3,CHEST:3,../NBT/StructureLoot/Rare1.nbt,3,CHEST:3,../NBT/StructureLoot/Rare2.nbt,3,CHEST:3,../NBT/StructureLoot/Rare3.nbt,3,CHEST:3,../NBT/StructureLoot/Rare4.nbt,3,CHEST:3,../NBT/StructureLoot/Rare5.nbt,3,CHEST:3,../NBT/StructureLoot/Rare6.nbt,3,CHEST:3,../NBT/StructureLoot/Rare7.nbt,3,CHEST:3,../NBT/StructureLoot/Rare8.nbt,3,CHEST:3,../NBT/StructureLoot/Rare9.nbt,3,CHEST:3,../NBT/StructureLoot/Rare10.nbt,3,CHEST:3,../NBT/StructureLoot/Rare11.nbt,3,CHEST:3,../NBT/StructureLoot/Rare12.nbt,3,CHEST:3,../NBT/StructureLoot/Rare13.nbt,3,CHEST:3,../NBT/StructureLoot/Rare14.nbt,3,CHEST:3,../NBT/StructureLoot/Rare15.nbt,3,CHEST:3,../NBT/StructureLoot/Epic1.nbt,3,CHEST:3,../NBT/StructureLoot/Epic2.nbt,3,CHEST:3,../NBT/StructureLoot/Epic3.nbt,3,CHEST:3,../NBT/StructureLoot/Epic4.nbt,3,CHEST:3,../NBT/StructureLoot/Epic5.nbt,3,CHEST:3,../NBT/StructureLoot/Epic6.nbt,3,CHEST:3,../NBT/StructureLoot/Epic7.nbt,3,CHEST:3,../NBT/StructureLoot/Epic8.nbt,3,CHEST:3,../NBT/StructureLoot/Epic9.nbt,3,CHEST:3,../NBT/StructureLoot/Epic10.nbt,3,CHEST:3,../NBT/StructureLoot/Epic11.nbt,3,CHEST:3,../NBT/StructureLoot/Epic12.nbt,3,CHEST:3,../NBT/StructureLoot/Epic13.nbt,3,CHEST:3,../NBT/StructureLoot/Epic14.nbt,3,CHEST:3,../NBT/StructureLoot/Epic15.nbt,1,CHEST:3,../NBT/StructureLoot/Common15.nbt,100)
B(1,-3,8,DISPENSER:0)
B(2,-3,8,WATER:0)
B(3,-3,8,PLANKS:5)
B(-1,-2,1,WOODEN_SLAB:13)
B(0,-2,1,DARK_OAK_STAIRS:7)
B(1,-2,1,WOODEN_SLAB:13)
B(-1,-2,2,WOODEN_SLAB:13)
B(0,-2,2,WOODEN_SLAB:1)
B(1,-2,2,WOODEN_SLAB:13)
B(-2,-2,3,WOODEN_SLAB:13)
B(0,-2,3,DOUBLE_WOODEN_SLAB:1)
B(2,-2,3,WOODEN_SLAB:13)
B(0,-2,4,DOUBLE_WOODEN_SLAB:1)
B(-1,-2,5,WATER:0)
B(0,-2,5,WOODEN_SLAB:9)
B(-2,-2,6,WATER:0)
B(-1,-2,6,WATER:0)
B(0,-2,6,WATER:0)
B(1,-2,6,WATER:0)
B(2,-2,6,WATER:0)
B(-2,-2,7,DARK_OAK_STAIRS:5)
B(-1,-2,7,WOODEN_SLAB:13)
B(0,-2,7,WOODEN_SLAB:13)
B(1,-2,7,WOODEN_SLAB:13)
B(2,-2,7,DARK_OAK_STAIRS:4)
B(-3,-2,8,DARK_OAK_STAIRS:7)
B(-2,-2,8,WOODEN_SLAB:0)
B(-1,-2,8,WOODEN_SLAB:0)
B(0,-2,8,WOODEN_SLAB:0)
B(1,-2,8,WOODEN_SLAB:0)
B(2,-2,8,WOODEN_SLAB:0)
B(3,-2,8,DARK_OAK_STAIRS:7)
B(0,-1,1,DARK_OAK_STAIRS:2)
B(0,-1,2,WOODEN_SLAB:13)
B(1,-1,2,WATER:0)
B(-1,-1,3,WATER:0)
B(0,-1,3,WATER:0)
B(1,-1,3,WATER:0)
B(-2,-1,4,WOODEN_SLAB:5)
B(-1,-1,4,WATER:0)
B(0,-1,4,WOODEN_SLAB:1)
B(1,-1,4,WATER:0)
B(2,-1,4,WOODEN_SLAB:5)
B(-2,-1,5,WOODEN_SLAB:5)
B(-1,-1,5,WATER:0)
B(0,-1,5,DOUBLE_WOODEN_SLAB:1)
B(1,-1,5,WATER:0)
B(2,-1,5,WOODEN_SLAB:5)
B(-3,-1,6,WOODEN_SLAB:5)
B(-1,-1,6,TRAPDOOR:8)
B(0,-1,6,DOUBLE_WOODEN_SLAB:1)
B(1,-1,6,TRAPDOOR:8)
B(3,-1,6,WOODEN_SLAB:5)
B(-3,-1,7,WOODEN_SLAB:13)
B(-2,-1,7,PLANKS:5)
B(-1,-1,7,PLANKS:5)
B(0,-1,7,PLANKS:5)
B(1,-1,7,PLANKS:5)
B(2,-1,7,PLANKS:5)
B(3,-1,7,WOODEN_SLAB:13)
B(-3,-1,8,PLANKS:5)
B(-2,-1,8,WATER:0)
B(-1,-1,8,WATER:0)
B(0,-1,8,WATER:0)
B(1,-1,8,WATER:0)
B(2,-1,8,WATER:0)
B(3,-1,8,PLANKS:5)
B(0,0,0,WOODEN_SLAB:0)
B(0,0,1,OAK_STAIRS:2)
B(0,0,2,PLANKS:0)
B(1,0,2,WATER:0)
B(-1,0,3,PLANKS:0)
B(0,0,3,WOODEN_SLAB:0)
B(1,0,3,PLANKS:0)
B(-1,0,4,PLANKS:0)
B(0,0,4,PLANKS:0)
B(1,0,4,PLANKS:0)
B(-2,0,5,PLANKS:0)
B(-1,0,5,PLANKS:0)
B(0,0,5,PLANKS:0)
B(1,0,5,PLANKS:0)
B(2,0,5,PLANKS:0)
B(-2,0,6,PLANKS:0)
B(-1,0,6,WATER:0)
B(0,0,6,PLANKS:0)
B(1,0,6,WATER:0)
B(2,0,6,PLANKS:0)
B(-2,0,7,PLANKS:0)
B(-1,0,7,WATER:0)
B(0,0,7,PLANKS:0)
B(1,0,7,WATER:0)
B(2,0,7,PLANKS:0)
B(-3,0,8,PLANKS:0)
B(-2,0,8,WATER:0)
B(-1,0,8,WATER:0)
B(0,0,8,WATER:0)
B(1,0,8,WATER:0)
B(2,0,8,WATER:0)
B(3,0,8,PLANKS:0)
B(1,1,2,WATER:0)
B(0,1,3,PLANKS:5)
B(-1,1,4,PLANKS:5)
B(0,1,4,PLANKS:5)
B(1,1,4,PLANKS:5)
B(-2,1,5,PLANKS:5)
B(-1,1,5,PLANKS:5)
B(0,1,5,PLANKS:5)
B(1,1,5,PLANKS:5)
B(2,1,5,PLANKS:5)
B(-2,1,6,PLANKS:5)
B(-1,1,6,WATER:0)
B(0,1,6,PLANKS:5)
B(1,1,6,WATER:0)
B(2,1,6,PLANKS:5)
B(-2,1,7,PLANKS:5)
B(-1,1,7,WATER:0)
B(0,1,7,PLANKS:5)
B(1,1,7,WATER:0)
B(2,1,7,PLANKS:5)
B(-3,1,8,PLANKS:5)
B(-2,1,8,WATER:0)
B(-1,1,8,WATER:0)
B(0,1,8,WATER:0)
B(1,1,8,WATER:0)
B(2,1,8,WATER:0)
B(3,1,8,PLANKS:5)
B(1,2,2,WATER:0)
B(0,2,4,PLANKS:1)
B(-1,2,5,PLANKS:1)
B(0,2,5,PLANKS:1)
B(1,2,5,PLANKS:1)
B(-1,2,6,PLANKS:1)
B(0,2,6,WOODEN_SLAB:0)
B(1,2,6,PLANKS:1)
B(-2,2,7,PLANKS:1)
B(-1,2,7,WOODEN_SLAB:0)
B(0,2,7,WOODEN_SLAB:0)
B(1,2,7,WOODEN_SLAB:0)
B(2,2,7,PLANKS:1)
B(-3,2,8,PLANKS:1)
B(-2,2,8,WOODEN_SLAB:0)
B(-1,2,8,WOODEN_SLAB:0)
B(0,2,8,WOODEN_SLAB:0)
B(1,2,8,WOODEN_SLAB:0)
B(2,2,8,WOODEN_SLAB:0)
B(3,2,8,PLANKS:1)
B(1,3,2,WATER:0)
B(0,3,6,PLANKS:1)
B(-2,3,7,PLANKS:1)
B(-1,3,7,PLANKS:1)
B(0,3,7,WATER:0)
B(1,3,7,PLANKS:1)
B(2,3,7,PLANKS:1)
B(-3,3,8,PLANKS:1)
B(-2,3,8,WATER:0)
B(-1,3,8,WATER:0)
B(0,3,8,WATER:0)
B(1,3,8,WATER:0)
B(2,3,8,WATER:0)
B(3,3,8,PLANKS:1)
B(1,4,2,WATER:0)
B(0,4,6,PLANKS:1)
B(0,4,7,PLANKS:1)
B(-2,4,8,PLANKS:1)
B(-1,4,8,PLANKS:1)
B(0,4,8,WATER:0)
B(1,4,8,PLANKS:1)
B(2,4,8,PLANKS:1)
B(1,5,2,WATER:0)
B(0,5,7,PLANKS:1)
B(-1,5,8,PLANKS:1)
B(0,5,8,WATER:0)
B(1,5,8,PLANKS:1)
B(1,6,2,WATER:0)
B(0,6,8,PLANKS:1)
B(1,7,2,WATER:0)

