Author: Bo3 BulkEdit

Description: Converted Schematic - Modified by Bo3BulkEdit

Version: 3

SettingsMode: WriteDisable

IsOTGPlus: false
Tree: false
Frequency: 1
Rarity: 100
RotateRandomly: false
SpawnHeight: randomY
MaxBranchDepth: 20
ExcludedBiomes: All

MinHeight: 0
MaxHeight: 256

SourceBlocks: AIR
MaxPercentageOutsideSourceBlock: 100
OutsideSourceBlock: placeAnyway

B(0,-11,6,WOODEN_SLAB:13)
B(-2,-10,5,WOODEN_SLAB:13)
B(0,-10,5,LEVER:12)
B(2,-10,5,WOODEN_SLAB:13)
B(0,-10,6,LIT_REDSTONE_LAMP:0)
B(-3,-9,3,WOODEN_SLAB:13)
B(3,-9,3,WOODEN_SLAB:13)
B(-3,-9,4,WOODEN_SLAB:13)
B(-2,-9,4,WOODEN_SLAB:13)
B(-1,-9,4,LEVER:12)
B(1,-9,4,LEVER:12)
B(2,-9,4,WOODEN_SLAB:13)
B(3,-9,4,WOODEN_SLAB:13)
B(-2,-9,5,REDSTONE_LAMP:0)
B(-1,-9,5,DOUBLE_WOODEN_SLAB:5)
B(0,-9,5,DOUBLE_WOODEN_SLAB:5)
B(1,-9,5,DOUBLE_WOODEN_SLAB:5)
B(2,-9,5,REDSTONE_LAMP:0)
B(0,-9,6,COBBLESTONE_WALL:0)
B(0,-8,-3,WATER:0)
B(1,-8,-3,WATER:0)
B(0,-8,-2,WATER:0)
B(1,-8,-2,WATER:0)
B(2,-8,-2,WATER:0)
B(0,-8,-1,WATER:0)
B(1,-8,-1,WATER:0)
B(-4,-8,0,WOODEN_SLAB:13)
B(4,-8,0,WOODEN_SLAB:13)
B(-3,-8,1,WOODEN_SLAB:13)
B(3,-8,1,WOODEN_SLAB:13)
B(-3,-8,2,DARK_OAK_STAIRS:6)
B(3,-8,2,DARK_OAK_STAIRS:6)
B(-3,-8,3,STAINED_HARDENED_CLAY:9)
B(3,-8,3,STAINED_HARDENED_CLAY:9)
B(-3,-8,4,STAINED_HARDENED_CLAY:9)
B(-2,-8,4,STAINED_HARDENED_CLAY:9)
B(2,-8,4,STAINED_HARDENED_CLAY:9)
B(3,-8,4,STAINED_HARDENED_CLAY:9)
B(-2,-8,5,COBBLESTONE_WALL:0)
B(-1,-8,5,STAINED_HARDENED_CLAY:9)
B(0,-8,5,STAINED_HARDENED_CLAY:9)
B(1,-8,5,STAINED_HARDENED_CLAY:9)
B(2,-8,5,COBBLESTONE_WALL:0)
B(0,-7,-6,LOG:1)
B(0,-7,-4,WATER:0)
B(1,-7,-4,WATER:0)
B(-4,-7,-3,WOODEN_SLAB:13)
B(-1,-7,-3,WATER:0)
B(0,-7,-3,WATER:0)
B(1,-7,-3,WATER:0)
B(4,-7,-3,WOODEN_SLAB:13)
B(-4,-7,-2,WOODEN_SLAB:13)
B(-2,-7,-2,WATER:0)
B(-1,-7,-2,WATER:0)
B(0,-7,-2,WATER:0)
B(1,-7,-2,WATER:0)
B(2,-7,-2,WATER:0)
B(4,-7,-2,WOODEN_SLAB:13)
B(-4,-7,-1,DARK_OAK_STAIRS:6)
B(-2,-7,-1,WATER:0)
B(-1,-7,-1,WATER:0)
B(0,-7,-1,WATER:0)
B(1,-7,-1,WATER:0)
B(2,-7,-1,WATER:0)
B(4,-7,-1,DARK_OAK_STAIRS:6)
B(-4,-7,0,STAINED_HARDENED_CLAY:9)
B(-1,-7,0,WATER:0)
B(0,-7,0,WATER:0)
B(1,-7,0,WATER:0)
B(4,-7,0,STAINED_HARDENED_CLAY:9)
B(-3,-7,1,STAINED_HARDENED_CLAY:9)
B(0,-7,1,WATER:0)
B(1,-7,1,WATER:0)
B(3,-7,1,STAINED_HARDENED_CLAY:9)
B(-3,-7,2,STAINED_HARDENED_CLAY:9)
B(3,-7,2,STAINED_HARDENED_CLAY:9)
B(-3,-7,3,STAINED_HARDENED_CLAY:9)
B(3,-7,3,STAINED_HARDENED_CLAY:9)
B(-3,-7,4,STAINED_HARDENED_CLAY:9)
B(-2,-7,4,STAINED_HARDENED_CLAY:9)
B(-1,-7,4,DARK_OAK_STAIRS:6)
B(1,-7,4,DARK_OAK_STAIRS:6)
B(2,-7,4,STAINED_HARDENED_CLAY:9)
B(3,-7,4,STAINED_HARDENED_CLAY:9)
B(-1,-7,5,STAINED_HARDENED_CLAY:9)
B(0,-7,5,STAINED_HARDENED_CLAY:9)
B(1,-7,5,STAINED_HARDENED_CLAY:9)
B(0,-6,-6,LOG:1)
B(-4,-6,-5,DARK_OAK_STAIRS:6)
B(0,-6,-5,WATER:0)
B(1,-6,-5,WATER:0)
B(2,-6,-5,WATER:0)
B(3,-6,-5,WATER:0)
B(4,-6,-5,DARK_OAK_STAIRS:6)
B(-4,-6,-4,STAINED_HARDENED_CLAY:9)
B(-1,-6,-4,WATER:0)
B(0,-6,-4,WATER:0)
B(1,-6,-4,WATER:0)
B(2,-6,-4,WATER:0)
B(3,-6,-4,WATER:0)
B(4,-6,-4,STAINED_HARDENED_CLAY:9)
B(-4,-6,-3,STAINED_HARDENED_CLAY:9)
B(-3,-6,-3,WATER:0)
B(-2,-6,-3,WATER:0)
B(-1,-6,-3,WATER:0)
B(0,-6,-3,WATER:0)
B(1,-6,-3,WATER:0)
B(2,-6,-3,WATER:0)
B(3,-6,-3,WATER:0)
B(4,-6,-3,STAINED_HARDENED_CLAY:9)
B(-4,-6,-2,STAINED_HARDENED_CLAY:9)
B(-3,-6,-2,WATER:0)
B(-2,-6,-2,WATER:0)
B(-1,-6,-2,WATER:0)
B(0,-6,-2,WATER:0)
B(1,-6,-2,WATER:0)
B(2,-6,-2,WATER:0)
B(3,-6,-2,WATER:0)
B(4,-6,-2,STAINED_HARDENED_CLAY:9)
B(-4,-6,-1,STAINED_HARDENED_CLAY:9)
B(-3,-6,-1,WATER:0)
B(-2,-6,-1,WATER:0)
B(-1,-6,-1,WATER:0)
B(0,-6,-1,WATER:0)
B(1,-6,-1,WATER:0)
B(2,-6,-1,WATER:0)
B(3,-6,-1,WATER:0)
B(4,-6,-1,STAINED_HARDENED_CLAY:9)
B(-4,-6,0,STAINED_HARDENED_CLAY:9)
B(-3,-6,0,WATER:0)
B(-2,-6,0,WATER:0)
B(-1,-6,0,WATER:0)
B(0,-6,0,WATER:0)
B(1,-6,0,WATER:0)
B(2,-6,0,WATER:0)
B(3,-6,0,WATER:0)
B(4,-6,0,STAINED_HARDENED_CLAY:9)
B(-3,-6,1,STAINED_HARDENED_CLAY:9)
B(-2,-6,1,WATER:0)
B(-1,-6,1,WATER:0)
B(0,-6,1,WATER:0)
B(1,-6,1,WATER:0)
B(2,-6,1,WATER:0)
B(3,-6,1,STAINED_HARDENED_CLAY:9)
B(-3,-6,2,STAINED_HARDENED_CLAY:9)
B(-2,-6,2,WATER:0)
B(-1,-6,2,WATER:0)
B(0,-6,2,WATER:0)
B(1,-6,2,WATER:0)
B(2,-6,2,WATER:0)
B(3,-6,2,STAINED_HARDENED_CLAY:9)
B(-3,-6,3,STAINED_HARDENED_CLAY:9)
B(-2,-6,3,WOODEN_SLAB:13)
B(-1,-6,3,WATER:0)
B(0,-6,3,WATER:0)
B(1,-6,3,WATER:0)
B(2,-6,3,WOODEN_SLAB:13)
B(3,-6,3,STAINED_HARDENED_CLAY:9)
B(-3,-6,4,STAINED_HARDENED_CLAY:9)
B(-2,-6,4,STAINED_HARDENED_CLAY:9)
B(-1,-6,4,DOUBLE_WOODEN_SLAB:5)
B(0,-6,4,WOODEN_SLAB:13)
B(1,-6,4,DOUBLE_WOODEN_SLAB:5)
B(2,-6,4,STAINED_HARDENED_CLAY:9)
B(3,-6,4,STAINED_HARDENED_CLAY:9)
B(-1,-6,5,STAINED_HARDENED_CLAY:9)
B(0,-6,5,STAINED_HARDENED_CLAY:9)
B(1,-6,5,STAINED_HARDENED_CLAY:9)
B(-5,-5,-7,WOODEN_SLAB:13)
B(5,-5,-7,WOODEN_SLAB:13)
B(0,-5,-6,LOG:1)
B(-4,-5,-5,STAINED_HARDENED_CLAY:9)
B(-3,-5,-5,WATER:0)
B(-2,-5,-5,WATER:0)
B(-1,-5,-5,WATER:0)
B(0,-5,-5,WOODEN_SLAB:9)
B(1,-5,-5,WATER:0)
B(2,-5,-5,WATER:0)
B(3,-5,-5,WATER:0)
B(4,-5,-5,STAINED_HARDENED_CLAY:9)
B(-4,-5,-4,STAINED_HARDENED_CLAY:9)
B(-3,-5,-4,WATER:0)
B(-2,-5,-4,WATER:0)
B(-1,-5,-4,WATER:0)
B(0,-5,-4,WOODEN_SLAB:9)
B(1,-5,-4,WATER:0)
B(2,-5,-4,WATER:0)
B(3,-5,-4,WATER:0)
B(4,-5,-4,STAINED_HARDENED_CLAY:9)
B(-5,-5,-3,WOODEN_SLAB:13)
B(-4,-5,-3,STAINED_HARDENED_CLAY:9)
B(-3,-5,-3,WATER:0)
B(-2,-5,-3,WATER:0)
B(-1,-5,-3,WATER:0)
B(0,-5,-3,WATER:0)
B(1,-5,-3,WATER:0)
B(2,-5,-3,WATER:0)
B(3,-5,-3,WATER:0)
B(4,-5,-3,STAINED_HARDENED_CLAY:9)
B(5,-5,-3,WOODEN_SLAB:13)
B(-5,-5,-2,WOODEN_SLAB:13)
B(-4,-5,-2,STAINED_HARDENED_CLAY:9)
B(-3,-5,-2,WATER:0)
B(-2,-5,-2,WATER:0)
B(-1,-5,-2,WATER:0)
B(0,-5,-2,WATER:0)
B(1,-5,-2,WATER:0)
B(2,-5,-2,WATER:0)
B(3,-5,-2,WATER:0)
B(4,-5,-2,STAINED_HARDENED_CLAY:9)
B(5,-5,-2,WOODEN_SLAB:13)
B(-5,-5,-1,DARK_OAK_STAIRS:6)
B(-4,-5,-1,STAINED_HARDENED_CLAY:9)
B(-3,-5,-1,WATER:0)
B(-2,-5,-1,WATER:0)
B(-1,-5,-1,WATER:0)
B(0,-5,-1,WOODEN_SLAB:9)
B(1,-5,-1,WATER:0)
B(2,-5,-1,WATER:0)
B(3,-5,-1,WATER:0)
B(4,-5,-1,PLANKS:5)
B(5,-5,-1,DARK_OAK_STAIRS:6)
B(-5,-5,0,DARK_OAK_STAIRS:4)
B(-4,-5,0,STAINED_HARDENED_CLAY:9)
B(-3,-5,0,WOODEN_SLAB:9)
B(-2,-5,0,WOODEN_SLAB:9)
B(-1,-5,0,WOODEN_SLAB:9)
B(0,-5,0,WOODEN_SLAB:9)
B(1,-5,0,WOODEN_SLAB:9)
B(2,-5,0,WOODEN_SLAB:9)
B(3,-5,0,WOODEN_SLAB:9)
B(4,-5,0,STAINED_HARDENED_CLAY:9)
B(5,-5,0,DARK_OAK_STAIRS:5)
B(-5,-5,1,DARK_OAK_STAIRS:4)
B(-4,-5,1,DOUBLE_WOODEN_SLAB:5)
B(-3,-5,1,STAINED_HARDENED_CLAY:9)
B(-2,-5,1,STAINED_HARDENED_CLAY:9)
B(-1,-5,1,STAINED_HARDENED_CLAY:9)
B(0,-5,1,STAINED_HARDENED_CLAY:9)
B(1,-5,1,STAINED_HARDENED_CLAY:9)
B(2,-5,1,STAINED_HARDENED_CLAY:9)
B(3,-5,1,STAINED_HARDENED_CLAY:9)
B(4,-5,1,DOUBLE_WOODEN_SLAB:5)
B(5,-5,1,DARK_OAK_STAIRS:5)
B(-5,-5,2,DARK_OAK_STAIRS:7)
B(-4,-5,2,DARK_OAK_STAIRS:4)
B(-3,-5,2,STAINED_HARDENED_CLAY:9)
B(-2,-5,2,STAINED_HARDENED_CLAY:9)
B(-1,-5,2,STAINED_HARDENED_CLAY:9)
B(0,-5,2,STAINED_HARDENED_CLAY:9)
B(1,-5,2,STAINED_HARDENED_CLAY:9)
B(2,-5,2,STAINED_HARDENED_CLAY:9)
B(3,-5,2,STAINED_HARDENED_CLAY:9)
B(4,-5,2,DARK_OAK_STAIRS:7)
B(5,-5,2,DARK_OAK_STAIRS:5)
B(-4,-5,3,DARK_OAK_STAIRS:4)
B(-3,-5,3,STAINED_HARDENED_CLAY:9)
B(-2,-5,3,STAINED_HARDENED_CLAY:9)
B(-1,-5,3,STAINED_HARDENED_CLAY:9)
B(0,-5,3,STAINED_HARDENED_CLAY:9)
B(1,-5,3,STAINED_HARDENED_CLAY:9)
B(2,-5,3,STAINED_HARDENED_CLAY:9)
B(3,-5,3,STAINED_HARDENED_CLAY:9)
B(4,-5,3,DARK_OAK_STAIRS:5)
B(-4,-5,4,DARK_OAK_STAIRS:4)
B(-3,-5,4,STAINED_HARDENED_CLAY:9)
B(-2,-5,4,STAINED_HARDENED_CLAY:9)
B(-1,-5,4,STAINED_HARDENED_CLAY:9)
B(0,-5,4,STAINED_HARDENED_CLAY:9)
B(1,-5,4,STAINED_HARDENED_CLAY:9)
B(2,-5,4,STAINED_HARDENED_CLAY:9)
B(3,-5,4,STAINED_HARDENED_CLAY:9)
B(4,-5,4,DARK_OAK_STAIRS:5)
B(-4,-5,5,DARK_OAK_STAIRS:7)
B(-3,-5,5,DARK_OAK_STAIRS:7)
B(-2,-5,5,DARK_OAK_STAIRS:4)
B(-1,-5,5,STAINED_HARDENED_CLAY:9)
B(0,-5,5,STAINED_HARDENED_CLAY:9)
B(1,-5,5,STAINED_HARDENED_CLAY:9)
B(2,-5,5,DARK_OAK_STAIRS:7)
B(3,-5,5,DARK_OAK_STAIRS:7)
B(4,-5,5,DARK_OAK_STAIRS:5)
B(-2,-5,6,DARK_OAK_STAIRS:7)
B(-1,-5,6,DARK_OAK_STAIRS:7)
B(0,-5,6,DARK_OAK_STAIRS:7)
B(1,-5,6,DARK_OAK_STAIRS:7)
B(2,-5,6,DARK_OAK_STAIRS:5)
B(-5,-4,-7,STAINED_HARDENED_CLAY:9)
B(-1,-4,-7,WOODEN_SLAB:9)
B(0,-4,-7,WOODEN_SLAB:9)
B(1,-4,-7,WOODEN_SLAB:9)
B(5,-4,-7,STAINED_HARDENED_CLAY:9)
B(-5,-4,-6,STAINED_HARDENED_CLAY:9)
B(-4,-4,-6,WOODEN_SLAB:9)
B(-3,-4,-6,WOODEN_SLAB:9)
B(-2,-4,-6,WOODEN_SLAB:9)
B(-1,-4,-6,WOODEN_SLAB:9)
B(0,-4,-6,LOG:1)
B(1,-4,-6,WOODEN_SLAB:9)
B(2,-4,-6,WOODEN_SLAB:9)
B(3,-4,-6,WOODEN_SLAB:9)
B(4,-4,-6,WOODEN_SLAB:9)
B(5,-4,-6,STAINED_HARDENED_CLAY:9)
B(-5,-4,-5,STAINED_HARDENED_CLAY:9)
B(-4,-4,-5,STAINED_HARDENED_CLAY:9)
B(-3,-4,-5,STAINED_HARDENED_CLAY:9)
B(-2,-4,-5,STAINED_HARDENED_CLAY:9)
B(-1,-4,-5,STAINED_HARDENED_CLAY:9)
B(0,-4,-5,STAINED_HARDENED_CLAY:9)
B(1,-4,-5,STAINED_HARDENED_CLAY:9)
B(2,-4,-5,STAINED_HARDENED_CLAY:9)
B(3,-4,-5,STAINED_HARDENED_CLAY:9)
B(4,-4,-5,STAINED_HARDENED_CLAY:9)
B(5,-4,-5,STAINED_HARDENED_CLAY:9)
B(-5,-4,-4,STAINED_HARDENED_CLAY:9)
B(-4,-4,-4,STAINED_HARDENED_CLAY:9)
B(-3,-4,-4,STAINED_HARDENED_CLAY:9)
B(-2,-4,-4,STAINED_HARDENED_CLAY:9)
B(-1,-4,-4,STAINED_GLASS:15)
B(0,-4,-4,WOODEN_SLAB:1)
B(1,-4,-4,STAINED_GLASS:15)
B(2,-4,-4,STAINED_HARDENED_CLAY:9)
B(3,-4,-4,STAINED_HARDENED_CLAY:9)
B(4,-4,-4,STAINED_HARDENED_CLAY:9)
B(5,-4,-4,STAINED_HARDENED_CLAY:9)
B(-5,-4,-3,STAINED_HARDENED_CLAY:9)
B(-4,-4,-3,STAINED_HARDENED_CLAY:9)
B(-3,-4,-3,STAINED_HARDENED_CLAY:9)
B(-2,-4,-3,STAINED_HARDENED_CLAY:9)
B(-1,-4,-3,WATER:0)
B(0,-4,-3,WOODEN_SLAB:1)
B(1,-4,-3,STAINED_GLASS:15)
B(2,-4,-3,STAINED_HARDENED_CLAY:9)
B(3,-4,-3,STAINED_HARDENED_CLAY:9)
B(4,-4,-3,STAINED_HARDENED_CLAY:9)
B(5,-4,-3,STAINED_HARDENED_CLAY:9)
B(-5,-4,-2,STAINED_HARDENED_CLAY:9)
B(-4,-4,-2,STAINED_HARDENED_CLAY:9)
B(-3,-4,-2,STAINED_HARDENED_CLAY:9)
B(-2,-4,-2,STAINED_HARDENED_CLAY:9)
B(-1,-4,-2,STAINED_GLASS:15)
B(0,-4,-2,WOODEN_SLAB:1)
B(1,-4,-2,STAINED_GLASS:15)
B(2,-4,-2,STAINED_HARDENED_CLAY:9)
B(3,-4,-2,STAINED_HARDENED_CLAY:9)
B(4,-4,-2,STAINED_HARDENED_CLAY:9)
B(5,-4,-2,STAINED_HARDENED_CLAY:9)
B(-5,-4,-1,STAINED_HARDENED_CLAY:9)
B(-4,-4,-1,STAINED_HARDENED_CLAY:9)
B(-3,-4,-1,STAINED_HARDENED_CLAY:9)
B(-2,-4,-1,STAINED_HARDENED_CLAY:9)
B(-1,-4,-1,STAINED_HARDENED_CLAY:9)
B(0,-4,-1,STAINED_HARDENED_CLAY:9)
B(1,-4,-1,STAINED_HARDENED_CLAY:9)
B(2,-4,-1,STAINED_HARDENED_CLAY:9)
B(3,-4,-1,STAINED_HARDENED_CLAY:9)
B(4,-4,-1,STAINED_HARDENED_CLAY:9)
B(5,-4,-1,STAINED_HARDENED_CLAY:9)
B(-5,-4,0,STAINED_GLASS:15)
B(-4,-4,0,BOOKSHELF:0)
B(-3,-4,0,WATER:0)
B(-2,-4,0,WATER:0)
B(-1,-4,0,WATER:0)
B(0,-4,0,WATER:0)
B(1,-4,0,WATER:0)
B(2,-4,0,WATER:0)
B(3,-4,0,SAND:0)
B(4,-4,0,BOOKSHELF:0)
B(5,-4,0,STAINED_GLASS:15)
B(-5,-4,1,STAINED_GLASS:15)
B(-4,-4,1,BOOKSHELF:0)
B(-3,-4,1,WATER:0)
B(-2,-4,1,DARK_OAK_STAIRS:3)
B(-1,-4,1,WATER:0)
B(0,-4,1,BOOKSHELF:0)
B(1,-4,1,BOOKSHELF:0)
B(2,-4,1,WATER:0)
B(3,-4,1,SAND:0)
B(4,-4,1,BOOKSHELF:0)
B(5,-4,1,STAINED_GLASS:15)
B(-5,-4,2,STAINED_HARDENED_CLAY:9)
B(-4,-4,2,WATER:0)
B(-3,-4,2,WATER:0)
B(-2,-4,2,WOODEN_SLAB:5)
B(-1,-4,2,WATER:0)
B(0,-4,2,WATER:0)
B(1,-4,2,WATER:0)
B(2,-4,2,WATER:0)
B(3,-4,2,SAND:0)
B(4,-4,2,SAND:0)
B(5,-4,2,STAINED_HARDENED_CLAY:9)
B(-5,-4,3,WATER:0)
B(-4,-4,3,WATER:0)
B(-3,-4,3,SAND:0)
B(-2,-4,3,DARK_OAK_STAIRS:2)
B(-1,-4,3,WATER:0)
B(0,-4,3,WATER:0)
B(1,-4,3,WATER:0)
B(2,-4,3,WATER:0)
B(3,-4,3,SAND:0)
B(4,-4,3,STAINED_GLASS:15)
B(-4,-4,4,WATER:0)
B(-3,-4,4,SAND:0)
B(-2,-4,4,SAND:0)
B(-1,-4,4,WATER:0)
B(0,-4,4,WATER:0)
B(1,-4,4,DARK_OAK_STAIRS:0)
B(2,-4,4,WATER:0)
B(3,-4,4,SAND:0)
B(4,-4,4,STAINED_GLASS:15)
B(-4,-4,5,STAINED_HARDENED_CLAY:9)
B(-3,-4,5,STAINED_GLASS:15)
B(-2,-4,5,SAND:0)
B(-1,-4,5,SAND:0)
RB(0,-4,5,SKULL:1,../NBT/Skulls/dungeon_skull_01.nbt,6,SKULL:1,../NBT/Skulls/dungeon_skull_02.nbt,12,SKULL:1,../NBT/Skulls/dungeon_skull_03.nbt,18,SKULL:1,../NBT/Skulls/dungeon_skull_04.nbt,24,SKULL:1,../NBT/Skulls/dungeon_skull_05.nbt,30,SKULL:1,../NBT/Skulls/dungeon_skull_06.nbt,36,SKULL:1,../NBT/Skulls/dungeon_skull_07.nbt,42,SKULL:1,../NBT/Skulls/dungeon_skull_08.nbt,48,SKULL:1,../NBT/Skulls/dungeon_skull_09.nbt,54,SKULL:1,../NBT/Skulls/dungeon_skull_10.nbt,60,SKULL:1,../NBT/Skulls/dungeon_skull_11.nbt,66,SKULL:1,../NBT/Skulls/dungeon_skull_12.nbt,72,SKULL:1,../NBT/Skulls/dungeon_skull_13.nbt,78,SKULL:1,../NBT/Skulls/dungeon_skull_14.nbt,84,SKULL:1,../NBT/Skulls/dungeon_skull_15.nbt,90,SKULL:1,../NBT/Skulls/dungeon_skull_16.nbt,100)
B(1,-4,5,WATER:0)
B(2,-4,5,SAND:0)
B(3,-4,5,STAINED_GLASS:15)
B(4,-4,5,STAINED_HARDENED_CLAY:9)
B(-2,-4,6,STAINED_GLASS:15)
B(-1,-4,6,STAINED_GLASS:15)
B(0,-4,6,STAINED_HARDENED_CLAY:9)
B(1,-4,6,STAINED_GLASS:15)
B(2,-4,6,STAINED_GLASS:15)
B(-5,-3,-7,STAINED_HARDENED_CLAY:9)
B(-4,-3,-7,STAINED_HARDENED_CLAY:9)
B(-3,-3,-7,STAINED_HARDENED_CLAY:9)
B(-2,-3,-7,STAINED_HARDENED_CLAY:9)
B(-1,-3,-7,STAINED_HARDENED_CLAY:9)
B(0,-3,-7,STAINED_HARDENED_CLAY:9)
B(1,-3,-7,STAINED_HARDENED_CLAY:9)
B(2,-3,-7,STAINED_HARDENED_CLAY:9)
B(3,-3,-7,STAINED_HARDENED_CLAY:9)
B(4,-3,-7,STAINED_HARDENED_CLAY:9)
B(5,-3,-7,STAINED_HARDENED_CLAY:9)
B(-6,-3,-6,DARK_OAK_STAIRS:0)
B(-5,-3,-6,STAINED_HARDENED_CLAY:9)
B(-4,-3,-6,STAINED_HARDENED_CLAY:9)
B(-3,-3,-6,STAINED_HARDENED_CLAY:9)
B(-2,-3,-6,STAINED_HARDENED_CLAY:9)
B(-1,-3,-6,STAINED_HARDENED_CLAY:9)
B(0,-3,-6,LOG:1)
B(1,-3,-6,STAINED_HARDENED_CLAY:9)
B(2,-3,-6,STAINED_HARDENED_CLAY:9)
B(3,-3,-6,STAINED_HARDENED_CLAY:9)
B(4,-3,-6,STAINED_HARDENED_CLAY:9)
B(5,-3,-6,STAINED_HARDENED_CLAY:9)
B(6,-3,-6,DARK_OAK_STAIRS:1)
B(-6,-3,-5,WOODEN_SLAB:5)
B(-5,-3,-5,STAINED_HARDENED_CLAY:9)
B(-4,-3,-5,STAINED_HARDENED_CLAY:9)
B(-3,-3,-5,STAINED_HARDENED_CLAY:9)
B(-2,-3,-5,STAINED_HARDENED_CLAY:9)
B(-1,-3,-5,STAINED_HARDENED_CLAY:9)
B(0,-3,-5,STAINED_HARDENED_CLAY:9)
B(1,-3,-5,STAINED_HARDENED_CLAY:9)
B(2,-3,-5,STAINED_HARDENED_CLAY:9)
B(3,-3,-5,STAINED_HARDENED_CLAY:9)
B(4,-3,-5,STAINED_HARDENED_CLAY:9)
B(5,-3,-5,STAINED_HARDENED_CLAY:9)
B(6,-3,-5,WOODEN_SLAB:5)
B(-6,-3,-4,DARK_OAK_STAIRS:0)
B(-5,-3,-4,STAINED_HARDENED_CLAY:9)
B(-4,-3,-4,WATER:0)
B(-3,-3,-4,WATER:0)
B(-2,-3,-4,DARK_OAK_STAIRS:3)
B(-1,-3,-4,WATER:0)
B(0,-3,-4,WATER:0)
B(1,-3,-4,WATER:0)
B(2,-3,-4,DARK_OAK_STAIRS:3)
B(3,-3,-4,WATER:0)
B(4,-3,-4,WATER:0)
B(5,-3,-4,STAINED_HARDENED_CLAY:9)
B(6,-3,-4,DARK_OAK_STAIRS:1)
B(-5,-3,-3,STAINED_HARDENED_CLAY:9)
B(-4,-3,-3,WATER:0)
B(-3,-3,-3,WATER:0)
B(-2,-3,-3,WOODEN_SLAB:5)
B(-1,-3,-3,WATER:0)
B(0,-3,-3,WATER:0)
B(1,-3,-3,WATER:0)
B(2,-3,-3,WOODEN_SLAB:5)
B(3,-3,-3,WATER:0)
B(4,-3,-3,WATER:0)
B(5,-3,-3,STAINED_HARDENED_CLAY:9)
B(-5,-3,-2,STAINED_HARDENED_CLAY:9)
B(-4,-3,-2,WATER:0)
B(-3,-3,-2,WATER:0)
B(-2,-3,-2,DARK_OAK_STAIRS:2)
B(-1,-3,-2,WATER:0)
B(0,-3,-2,WATER:0)
B(1,-3,-2,WATER:0)
B(2,-3,-2,DARK_OAK_STAIRS:2)
B(3,-3,-2,WATER:0)
B(4,-3,-2,WATER:0)
B(5,-3,-2,STAINED_HARDENED_CLAY:9)
B(-5,-3,-1,STAINED_HARDENED_CLAY:9)
B(-4,-3,-1,STAINED_HARDENED_CLAY:9)
B(-3,-3,-1,STAINED_HARDENED_CLAY:9)
B(-2,-3,-1,PLANKS:5)
B(-1,-3,-1,DARK_OAK_STAIRS:1)
B(0,-3,-1,WOODEN_SLAB:5)
B(1,-3,-1,DARK_OAK_STAIRS:0)
B(2,-3,-1,DOUBLE_WOODEN_SLAB:5)
B(3,-3,-1,STAINED_HARDENED_CLAY:9)
B(4,-3,-1,STAINED_HARDENED_CLAY:9)
B(5,-3,-1,STAINED_HARDENED_CLAY:9)
B(-5,-3,0,STAINED_GLASS:15)
B(-4,-3,0,WATER:0)
B(-3,-3,0,WATER:0)
B(-2,-3,0,WATER:0)
B(-1,-3,0,WATER:0)
B(0,-3,0,WATER:0)
B(1,-3,0,WATER:0)
B(2,-3,0,WATER:0)
B(3,-3,0,WATER:0)
B(4,-3,0,WATER:0)
B(5,-3,0,STAINED_GLASS:15)
B(-5,-3,1,STAINED_GLASS:15)
B(-4,-3,1,WATER:0)
B(-3,-3,1,WATER:0)
B(-2,-3,1,WATER:0)
B(-1,-3,1,WATER:0)
B(0,-3,1,WATER:0)
B(1,-3,1,WATER:0)
B(2,-3,1,WATER:0)
B(3,-3,1,WATER:0)
B(4,-3,1,WATER:0)
B(5,-3,1,STAINED_GLASS:15)
B(-5,-3,2,STAINED_HARDENED_CLAY:9)
B(-4,-3,2,WATER:0)
B(-3,-3,2,WATER:0)
B(-2,-3,2,WATER:0)
B(-1,-3,2,WATER:0)
B(0,-3,2,WATER:0)
B(1,-3,2,WATER:0)
B(2,-3,2,WATER:0)
B(3,-3,2,WATER:0)
B(4,-3,2,SAND:0)
B(5,-3,2,STAINED_HARDENED_CLAY:9)
B(-5,-3,3,WATER:0)
B(-4,-3,3,WATER:0)
B(-3,-3,3,WATER:0)
B(-2,-3,3,WATER:0)
B(-1,-3,3,WATER:0)
B(0,-3,3,WATER:0)
B(1,-3,3,WATER:0)
B(2,-3,3,WATER:0)
B(3,-3,3,SAND:0)
B(4,-3,3,STAINED_GLASS:15)
B(-5,-3,4,WATER:0)
B(-4,-3,4,WATER:0)
B(-3,-3,4,SAND:0)
B(-2,-3,4,WATER:0)
B(-1,-3,4,WATER:0)
B(0,-3,4,WATER:0)
B(1,-3,4,WATER:0)
B(2,-3,4,WATER:0)
B(3,-3,4,WATER:0)
B(4,-3,4,STAINED_GLASS:15)
B(-4,-3,5,STAINED_HARDENED_CLAY:9)
B(-3,-3,5,STAINED_GLASS:15)
B(-2,-3,5,SAND:0)
B(-1,-3,5,DARK_OAK_STAIRS:4)
B(0,-3,5,DOUBLE_WOODEN_SLAB:5)
B(1,-3,5,DARK_OAK_STAIRS:5)
B(2,-3,5,WATER:0)
B(3,-3,5,STAINED_GLASS:15)
B(4,-3,5,STAINED_HARDENED_CLAY:9)
B(-2,-3,6,STAINED_GLASS:15)
B(-1,-3,6,STAINED_GLASS:15)
B(0,-3,6,STAINED_HARDENED_CLAY:9)
B(1,-3,6,STAINED_GLASS:15)
B(2,-3,6,STAINED_GLASS:15)
B(-5,-2,-7,STAINED_HARDENED_CLAY:9)
B(-4,-2,-7,SAND:0)
B(-3,-2,-7,WATER:0)
B(-2,-2,-7,WATER:0)
B(-1,-2,-7,WATER:0)
B(0,-2,-7,WATER:0)
B(1,-2,-7,WATER:0)
B(2,-2,-7,WATER:0)
B(3,-2,-7,WATER:0)
B(4,-2,-7,WATER:0)
B(5,-2,-7,STAINED_HARDENED_CLAY:9)
B(-5,-2,-6,STAINED_HARDENED_CLAY:9)
B(-4,-2,-6,SAND:0)
B(-3,-2,-6,WATER:0)
B(-2,-2,-6,WATER:0)
B(-1,-2,-6,WATER:0)
B(0,-2,-6,LOG:1)
B(1,-2,-6,WATER:0)
B(2,-2,-6,WATER:0)
B(3,-2,-6,WATER:0)
B(4,-2,-6,WATER:0)
B(5,-2,-6,STAINED_HARDENED_CLAY:9)
B(-5,-2,-5,STAINED_HARDENED_CLAY:9)
B(-4,-2,-5,STAINED_HARDENED_CLAY:9)
B(-3,-2,-5,STAINED_HARDENED_CLAY:9)
B(-2,-2,-5,STAINED_HARDENED_CLAY:9)
B(-1,-2,-5,WATER:0)
B(0,-2,-5,STAINED_HARDENED_CLAY:9)
B(1,-2,-5,WATER:0)
B(2,-2,-5,STAINED_HARDENED_CLAY:9)
B(3,-2,-5,STAINED_HARDENED_CLAY:9)
B(4,-2,-5,STAINED_HARDENED_CLAY:9)
B(5,-2,-5,STAINED_HARDENED_CLAY:9)
B(-5,-2,-4,STAINED_HARDENED_CLAY:9)
B(-4,-2,-4,WATER:0)
B(-3,-2,-4,WATER:0)
B(-2,-2,-4,WATER:0)
B(-1,-2,-4,WATER:0)
B(0,-2,-4,WATER:0)
B(1,-2,-4,WATER:0)
B(2,-2,-4,WATER:0)
B(3,-2,-4,WATER:0)
B(4,-2,-4,WATER:0)
B(5,-2,-4,STAINED_HARDENED_CLAY:9)
B(-5,-2,-3,STAINED_HARDENED_CLAY:9)
B(-4,-2,-3,WATER:0)
B(-3,-2,-3,WATER:0)
B(-2,-2,-3,WATER:0)
B(-1,-2,-3,WATER:0)
B(0,-2,-3,WATER:0)
B(1,-2,-3,WATER:0)
B(2,-2,-3,WATER:0)
B(3,-2,-3,WATER:0)
B(4,-2,-3,WATER:0)
B(5,-2,-3,STAINED_HARDENED_CLAY:9)
B(-5,-2,-2,STAINED_HARDENED_CLAY:9)
B(-4,-2,-2,WATER:0)
B(-3,-2,-2,WATER:0)
B(-2,-2,-2,WATER:0)
B(-1,-2,-2,WATER:0)
B(0,-2,-2,WATER:0)
B(1,-2,-2,WATER:0)
B(2,-2,-2,WATER:0)
B(3,-2,-2,WATER:0)
B(4,-2,-2,WATER:0)
B(5,-2,-2,STAINED_HARDENED_CLAY:9)
B(-5,-2,-1,PLANKS:5)
B(-4,-2,-1,STAINED_HARDENED_CLAY:9)
B(-3,-2,-1,STAINED_HARDENED_CLAY:9)
B(-2,-2,-1,PLANKS:5)
B(-1,-2,-1,WATER:0)
B(0,-2,-1,WATER:0)
B(1,-2,-1,WATER:0)
B(2,-2,-1,DOUBLE_WOODEN_SLAB:5)
B(3,-2,-1,STAINED_HARDENED_CLAY:9)
B(4,-2,-1,STAINED_HARDENED_CLAY:9)
B(5,-2,-1,DOUBLE_WOODEN_SLAB:5)
B(-5,-2,0,PLANKS:5)
B(-4,-2,0,WATER:0)
B(-3,-2,0,WATER:0)
B(-2,-2,0,WATER:0)
B(-1,-2,0,WATER:0)
B(0,-2,0,WATER:0)
B(1,-2,0,WATER:0)
B(2,-2,0,WATER:0)
B(3,-2,0,WATER:0)
B(4,-2,0,WATER:0)
B(5,-2,0,DOUBLE_WOODEN_SLAB:5)
B(-5,-2,1,DARK_OAK_STAIRS:0)
B(-4,-2,1,WATER:0)
B(-3,-2,1,WATER:0)
B(-2,-2,1,WATER:0)
B(-1,-2,1,WATER:0)
B(0,-2,1,WATER:0)
B(1,-2,1,WATER:0)
B(2,-2,1,WATER:0)
B(3,-2,1,WATER:0)
B(4,-2,1,WATER:0)
B(5,-2,1,DARK_OAK_STAIRS:1)
B(-5,-2,2,WOODEN_SLAB:5)
B(-4,-2,2,DOUBLE_WOODEN_SLAB:5)
B(-3,-2,2,WATER:0)
B(-2,-2,2,WATER:0)
B(-1,-2,2,WATER:0)
B(0,-2,2,WATER:0)
B(1,-2,2,WATER:0)
B(2,-2,2,WATER:0)
B(3,-2,2,WATER:0)
B(4,-2,2,DOUBLE_WOODEN_SLAB:5)
B(5,-2,2,WOODEN_SLAB:5)
B(-5,-2,3,WATER:0)
B(-4,-2,3,DARK_OAK_STAIRS:3)
B(-3,-2,3,WATER:0)
B(-2,-2,3,WATER:0)
B(-1,-2,3,WATER:0)
B(0,-2,3,WATER:0)
B(1,-2,3,WATER:0)
B(2,-2,3,WATER:0)
B(3,-2,3,WATER:0)
B(4,-2,3,DARK_OAK_STAIRS:3)
B(-5,-2,4,WATER:0)
B(-4,-2,4,DARK_OAK_STAIRS:0)
B(-3,-2,4,WATER:0)
B(-2,-2,4,WATER:0)
B(-1,-2,4,WATER:0)
B(0,-2,4,WATER:0)
B(1,-2,4,WATER:0)
B(2,-2,4,WATER:0)
B(3,-2,4,WATER:0)
B(4,-2,4,DARK_OAK_STAIRS:1)
B(-4,-2,5,DARK_OAK_STAIRS:0)
B(-3,-2,5,DARK_OAK_STAIRS:3)
B(-2,-2,5,DARK_OAK_STAIRS:0)
B(-1,-2,5,DOUBLE_WOODEN_SLAB:5)
B(0,-2,5,DOUBLE_WOODEN_SLAB:5)
B(1,-2,5,DOUBLE_WOODEN_SLAB:5)
B(2,-2,5,DARK_OAK_STAIRS:1)
B(3,-2,5,DARK_OAK_STAIRS:3)
B(4,-2,5,DARK_OAK_STAIRS:1)
B(-2,-2,6,WOODEN_SLAB:5)
B(-1,-2,6,DARK_OAK_STAIRS:3)
B(0,-2,6,WOODEN_SLAB:5)
B(1,-2,6,DARK_OAK_STAIRS:3)
B(2,-2,6,WOODEN_SLAB:5)
B(-5,-1,-7,STAINED_HARDENED_CLAY:9)
B(-4,-1,-7,WATER:0)
B(-3,-1,-7,WATER:0)
B(-2,-1,-7,WATER:0)
B(-1,-1,-7,WATER:0)
B(0,-1,-7,WATER:0)
B(1,-1,-7,WATER:0)
B(2,-1,-7,WATER:0)
B(3,-1,-7,WATER:0)
B(4,-1,-7,WATER:0)
B(5,-1,-7,STAINED_HARDENED_CLAY:9)
B(-5,-1,-6,WATER:0)
B(-4,-1,-6,WATER:0)
B(-3,-1,-6,WATER:0)
B(-2,-1,-6,WATER:0)
B(-1,-1,-6,WATER:0)
B(0,-1,-6,LOG:1)
B(1,-1,-6,WATER:0)
B(2,-1,-6,WATER:0)
B(3,-1,-6,WATER:0)
B(4,-1,-6,WATER:0)
B(5,-1,-6,WATER:0)
B(-5,-1,-5,STAINED_HARDENED_CLAY:9)
B(-4,-1,-5,STAINED_HARDENED_CLAY:9)
B(-3,-1,-5,STAINED_HARDENED_CLAY:9)
B(-2,-1,-5,STAINED_HARDENED_CLAY:9)
B(-1,-1,-5,WATER:0)
B(0,-1,-5,STAINED_HARDENED_CLAY:9)
B(1,-1,-5,WATER:0)
B(2,-1,-5,STAINED_HARDENED_CLAY:9)
B(3,-1,-5,STAINED_HARDENED_CLAY:9)
B(4,-1,-5,STAINED_HARDENED_CLAY:9)
B(5,-1,-5,STAINED_HARDENED_CLAY:9)
B(-5,-1,-4,PLANKS:5)
B(-4,-1,-4,WATER:0)
B(-3,-1,-4,WATER:0)
B(-2,-1,-4,WOODEN_SLAB:13)
B(-1,-1,-4,WATER:0)
B(0,-1,-4,WATER:0)
B(1,-1,-4,WATER:0)
B(2,-1,-4,SPRUCE_STAIRS:7)
B(4,-1,-4,SPRUCE_STAIRS:7)
B(5,-1,-4,PLANKS:5)
B(-5,-1,-3,PLANKS:5)
B(-4,-1,-3,WATER:0)
B(-3,-1,-3,WATER:0)
B(-2,-1,-3,WOODEN_SLAB:13)
B(-1,-1,-3,WATER:0)
B(0,-1,-3,WATER:0)
B(1,-1,-3,WATER:0)
B(2,-1,-3,DARK_OAK_STAIRS:1)
B(3,-1,-3,WOODEN_SLAB:5)
B(4,-1,-3,WOODEN_SLAB:5)
B(5,-1,-3,PLANKS:5)
B(-5,-1,-2,PLANKS:5)
B(-4,-1,-2,WATER:0)
B(-3,-1,-2,WATER:0)
B(-2,-1,-2,WOODEN_SLAB:13)
B(-1,-1,-2,WATER:0)
B(0,-1,-2,WATER:0)
B(1,-1,-2,WATER:0)
B(2,-1,-2,SPRUCE_STAIRS:6)
B(4,-1,-2,SPRUCE_STAIRS:6)
B(5,-1,-2,DOUBLE_WOODEN_SLAB:5)
B(-5,-1,-1,PLANKS:5)
B(-4,-1,-1,STAINED_HARDENED_CLAY:9)
B(-3,-1,-1,STAINED_HARDENED_CLAY:9)
B(-2,-1,-1,PLANKS:5)
B(-1,-1,-1,WATER:0)
B(0,-1,-1,WATER:0)
B(1,-1,-1,WATER:0)
B(2,-1,-1,DOUBLE_WOODEN_SLAB:5)
B(3,-1,-1,STAINED_HARDENED_CLAY:9)
B(4,-1,-1,STAINED_HARDENED_CLAY:9)
B(5,-1,-1,DOUBLE_WOODEN_SLAB:5)
B(-5,-1,0,PLANKS:5)
B(-4,-1,0,BOOKSHELF:0)
B(-3,-1,0,BOOKSHELF:0)
B(-2,-1,0,WATER:0)
B(-1,-1,0,WATER:0)
B(0,-1,0,WATER:0)
B(1,-1,0,WATER:0)
B(2,-1,0,SPRUCE_STAIRS:4)
B(3,-1,0,BOOKSHELF:0)
B(4,-1,0,BOOKSHELF:0)
B(5,-1,0,DOUBLE_WOODEN_SLAB:5)
B(-4,-1,1,PLANKS:5)
B(-3,-1,1,BOOKSHELF:0)
B(-2,-1,1,BOOKSHELF:0)
B(-1,-1,1,BOOKSHELF:0)
B(0,-1,1,WATER:0)
B(1,-1,1,WATER:0)
B(2,-1,1,BOOKSHELF:0)
B(3,-1,1,BOOKSHELF:0)
B(4,-1,1,PLANKS:5)
B(-5,-1,2,WATER:0)
B(-4,-1,2,PLANKS:5)
B(-3,-1,2,PLANKS:5)
B(-2,-1,2,DOUBLE_WOODEN_SLAB:5)
B(-1,-1,2,DOUBLE_WOODEN_SLAB:5)
B(0,-1,2,DOUBLE_WOODEN_SLAB:5)
B(1,-1,2,DOUBLE_WOODEN_SLAB:5)
B(2,-1,2,DOUBLE_WOODEN_SLAB:5)
B(3,-1,2,PLANKS:5)
B(4,-1,2,PLANKS:5)
B(-5,-1,3,WATER:0)
B(-4,-1,3,WATER:0)
B(-3,-1,3,WOODEN_SLAB:5)
B(-2,-1,3,STAINED_HARDENED_CLAY:9)
B(-1,-1,3,STAINED_HARDENED_CLAY:9)
B(0,-1,3,STAINED_HARDENED_CLAY:9)
B(1,-1,3,STAINED_HARDENED_CLAY:9)
B(2,-1,3,STAINED_HARDENED_CLAY:9)
B(3,-1,3,WOODEN_SLAB:5)
B(-5,-1,4,WATER:0)
B(-4,-1,4,WATER:0)
B(-3,-1,4,WOODEN_SLAB:5)
B(-2,-1,4,WOODEN_SLAB:5)
B(-1,-1,4,WOODEN_SLAB:5)
B(0,-1,4,WOODEN_SLAB:5)
B(1,-1,4,DARK_OAK_STAIRS:3)
B(2,-1,4,WOODEN_SLAB:5)
B(3,-1,4,WOODEN_SLAB:5)
B(-1,-1,5,WOODEN_SLAB:5)
B(0,-1,5,WOODEN_SLAB:5)
B(1,-1,5,WOODEN_SLAB:5)
B(-6,0,-7,DARK_OAK_STAIRS:7)
B(-5,0,-7,STAINED_HARDENED_CLAY:9)
B(-4,0,-7,WOODEN_SLAB:5)
B(-3,0,-7,WOODEN_SLAB:5)
B(-2,0,-7,WOODEN_SLAB:5)
B(-1,0,-7,DOUBLE_WOODEN_SLAB:5)
B(0,0,-7,DOUBLE_WOODEN_SLAB:5)
B(1,0,-7,DOUBLE_WOODEN_SLAB:5)
B(2,0,-7,DOUBLE_WOODEN_SLAB:5)
B(3,0,-7,WOODEN_SLAB:5)
B(4,0,-7,DOUBLE_WOODEN_SLAB:5)
B(5,0,-7,STAINED_HARDENED_CLAY:9)
B(6,0,-7,DARK_OAK_STAIRS:7)
B(-5,0,-6,STAINED_HARDENED_CLAY:9)
B(-4,0,-6,WOODEN_SLAB:5)
B(-3,0,-6,WOODEN_SLAB:5)
B(-2,0,-6,WOODEN_SLAB:5)
B(-1,0,-6,DOUBLE_WOODEN_SLAB:5)
B(0,0,-6,LOG:1)
B(1,0,-6,WOODEN_SLAB:5)
B(2,0,-6,DOUBLE_WOODEN_SLAB:5)
B(3,0,-6,WOODEN_SLAB:5)
B(4,0,-6,WOODEN_SLAB:5)
B(5,0,-6,STAINED_HARDENED_CLAY:9)
B(-5,0,-5,PLANKS:5)
B(-4,0,-5,WOODEN_SLAB:5)
B(-3,0,-5,DOUBLE_WOODEN_SLAB:5)
B(-2,0,-5,WOODEN_SLAB:5)
B(-1,0,-5,DOUBLE_WOODEN_SLAB:5)
B(0,0,-5,DOUBLE_WOODEN_SLAB:5)
B(1,0,-5,WOODEN_SLAB:5)
B(2,0,-5,WOODEN_SLAB:5)
B(3,0,-5,DOUBLE_WOODEN_SLAB:5)
B(4,0,-5,DOUBLE_WOODEN_SLAB:5)
B(5,0,-5,PLANKS:5)
B(-5,0,-4,PLANKS:5)
B(-4,0,-4,DOUBLE_WOODEN_SLAB:5)
B(-3,0,-4,DOUBLE_WOODEN_SLAB:5)
B(-2,0,-4,DOUBLE_WOODEN_SLAB:5)
B(-1,0,-4,DOUBLE_WOODEN_SLAB:5)
B(0,0,-4,DOUBLE_WOODEN_SLAB:5)
B(1,0,-4,DOUBLE_WOODEN_SLAB:5)
B(2,0,-4,DOUBLE_WOODEN_SLAB:5)
B(3,0,-4,DOUBLE_WOODEN_SLAB:5)
B(4,0,-4,DOUBLE_WOODEN_SLAB:5)
B(5,0,-4,PLANKS:5)
B(-5,0,-3,PLANKS:5)
B(-4,0,-3,WOODEN_SLAB:5)
B(-3,0,-3,WOODEN_SLAB:5)
B(-2,0,-3,DOUBLE_WOODEN_SLAB:5)
B(-1,0,-3,WOODEN_SLAB:5)
B(0,0,-3,WOODEN_SLAB:5)
B(1,0,-3,WOODEN_SLAB:5)
B(2,0,-3,DOUBLE_WOODEN_SLAB:5)
B(3,0,-3,WOODEN_SLAB:5)
B(4,0,-3,WOODEN_SLAB:5)
B(5,0,-3,DOUBLE_WOODEN_SLAB:5)
B(-5,0,-2,PLANKS:5)
B(-4,0,-2,WOODEN_SLAB:5)
B(-3,0,-2,WOODEN_SLAB:5)
B(-2,0,-2,WOODEN_SLAB:5)
B(-1,0,-2,WOODEN_SLAB:5)
B(0,0,-2,WOODEN_SLAB:5)
B(1,0,-2,WOODEN_SLAB:5)
B(2,0,-2,DOUBLE_WOODEN_SLAB:5)
B(3,0,-2,WOODEN_SLAB:5)
B(4,0,-2,WOODEN_SLAB:5)
B(5,0,-2,DOUBLE_WOODEN_SLAB:5)
B(-5,0,-1,PLANKS:5)
B(-4,0,-1,DOUBLE_WOODEN_SLAB:5)
B(-3,0,-1,WOODEN_SLAB:5)
B(-2,0,-1,WATER:0)
B(-1,0,-1,DOUBLE_WOODEN_SLAB:5)
B(0,0,-1,WOODEN_SLAB:5)
B(1,0,-1,DOUBLE_WOODEN_SLAB:5)
B(2,0,-1,WOODEN_SLAB:5)
B(3,0,-1,WOODEN_SLAB:5)
B(4,0,-1,DOUBLE_WOODEN_SLAB:5)
B(5,0,-1,DOUBLE_WOODEN_SLAB:5)
B(-4,0,0,PLANKS:5)
B(-3,0,0,DOUBLE_WOODEN_SLAB:5)
B(-2,0,0,WATER:0)
B(-1,0,0,DOUBLE_WOODEN_SLAB:5)
B(0,0,0,DOUBLE_WOODEN_SLAB:5)
B(1,0,0,DOUBLE_WOODEN_SLAB:5)
B(2,0,0,DOUBLE_WOODEN_SLAB:5)
B(3,0,0,DOUBLE_WOODEN_SLAB:5)
B(4,0,0,PLANKS:5)
B(-4,0,1,PLANKS:5)
B(-3,0,1,DOUBLE_WOODEN_SLAB:5)
B(-2,0,1,DOUBLE_WOODEN_SLAB:5)
B(-1,0,1,DOUBLE_WOODEN_SLAB:5)
B(0,0,1,DOUBLE_WOODEN_SLAB:5)
B(1,0,1,DOUBLE_WOODEN_SLAB:5)
B(2,0,1,DOUBLE_WOODEN_SLAB:5)
B(3,0,1,DOUBLE_WOODEN_SLAB:5)
B(4,0,1,PLANKS:5)
B(-5,0,2,WATER:0)
B(-4,0,2,WATER:0)
B(-3,0,2,STAINED_HARDENED_CLAY:9)
B(-2,0,2,STAINED_HARDENED_CLAY:9)
B(-1,0,2,STAINED_HARDENED_CLAY:9)
B(0,0,2,STAINED_HARDENED_CLAY:9)
B(1,0,2,STAINED_HARDENED_CLAY:9)
B(2,0,2,STAINED_HARDENED_CLAY:9)
B(3,0,2,STAINED_HARDENED_CLAY:9)
B(-5,0,3,WATER:0)
B(-4,0,3,WATER:0)
B(-3,0,3,WATER:0)
B(-2,0,3,WATER:0)
B(-5,0,4,WATER:0)
B(-4,0,4,WATER:0)
B(-3,0,4,WATER:0)
B(-6,1,-7,PLANKS:5)
B(-5,1,-7,WOODEN_SLAB:13)
B(-4,1,-7,WATER:0)
B(-3,1,-7,WATER:0)
B(-1,1,-7,SAND:0)
B(0,1,-7,SAND:0)
B(1,1,-7,WATER:0)
B(2,1,-7,WATER:0)
B(3,1,-7,WATER:0)
B(4,1,-7,WATER:0)
B(5,1,-7,WOODEN_SLAB:13)
B(6,1,-7,DOUBLE_WOODEN_SLAB:5)
B(-5,1,-6,PLANKS:5)
B(-4,1,-6,WOODEN_SLAB:13)
B(-3,1,-6,WATER:0)
B(0,1,-6,LOG:1)
B(1,1,-6,WATER:0)
B(2,1,-6,WATER:0)
B(3,1,-6,WATER:0)
B(4,1,-6,WOODEN_SLAB:13)
B(5,1,-6,PLANKS:5)
B(-5,1,-5,PLANKS:5)
B(-4,1,-5,WATER:0)
B(-3,1,-5,WATER:0)
B(0,1,-5,SAND:0)
B(1,1,-5,WATER:0)
B(2,1,-5,WATER:0)
B(3,1,-5,WATER:0)
B(4,1,-5,WATER:0)
B(5,1,-5,PLANKS:5)
B(-5,1,-4,PLANKS:5)
B(-4,1,-4,STAINED_HARDENED_CLAY:9)
B(-3,1,-4,STAINED_HARDENED_CLAY:9)
B(-2,1,-4,STAINED_HARDENED_CLAY:9)
B(-1,1,-4,WATER:0)
B(0,1,-4,STAINED_HARDENED_CLAY:9)
B(1,1,-4,WATER:0)
B(2,1,-4,STAINED_HARDENED_CLAY:9)
B(3,1,-4,STAINED_HARDENED_CLAY:9)
B(4,1,-4,STAINED_HARDENED_CLAY:9)
B(5,1,-4,PLANKS:5)
B(-5,1,-3,PLANKS:5)
B(-4,1,-3,WATER:0)
B(-3,1,-3,WATER:0)
B(-2,1,-3,LOG:1)
B(-1,1,-3,WATER:0)
B(0,1,-3,WATER:0)
B(1,1,-3,WATER:0)
B(2,1,-3,LOG:1)
B(3,1,-3,WATER:0)
B(4,1,-3,WATER:0)
B(5,1,-3,PLANKS:5)
B(-5,1,-2,PLANKS:5)
B(-4,1,-2,WATER:0)
B(-3,1,-2,WATER:0)
B(-2,1,-2,WATER:0)
B(-1,1,-2,WATER:0)
B(0,1,-2,WATER:0)
B(1,1,-2,WATER:0)
B(2,1,-2,WATER:0)
B(3,1,-2,WATER:0)
B(4,1,-2,WATER:0)
B(5,1,-2,PLANKS:5)
B(-5,1,-1,PLANKS:5)
B(-4,1,-1,DOUBLE_WOODEN_SLAB:5)
B(-3,1,-1,WATER:0)
B(-2,1,-1,WATER:0)
B(-1,1,-1,LOG:1)
B(0,1,-1,WATER:0)
B(1,1,-1,LOG:1)
B(2,1,-1,WATER:0)
B(3,1,-1,WATER:0)
B(4,1,-1,DOUBLE_WOODEN_SLAB:5)
B(5,1,-1,PLANKS:5)
B(-4,1,0,PLANKS:5)
B(-3,1,0,PLANKS:5)
B(-2,1,0,WATER:0)
B(-1,1,0,PLANKS:5)
B(0,1,0,REDSTONE_LAMP:0)
B(1,1,0,PLANKS:5)
B(2,1,0,PLANKS:5)
B(3,1,0,PLANKS:5)
B(4,1,0,PLANKS:5)
B(-5,1,1,WATER:0)
B(-4,1,1,WATER:0)
B(-3,1,1,PLANKS:5)
B(-2,1,1,PLANKS:5)
B(-1,1,1,PLANKS:5)
B(0,1,1,PLANKS:5)
B(1,1,1,PLANKS:5)
B(2,1,1,PLANKS:5)
B(3,1,1,PLANKS:5)
B(-5,1,2,WATER:0)
B(-4,1,2,WATER:0)
B(-3,1,2,WATER:0)
B(-2,1,2,WATER:0)
B(-6,1,3,WATER:0)
B(-5,1,3,WATER:0)
B(-4,1,3,WATER:0)
B(-3,1,3,WATER:0)
B(-2,1,3,WATER:0)
B(0,1,3,PLANKS:5)
B(-6,1,4,WATER:0)
B(-5,1,4,WATER:0)
B(-4,1,4,WATER:0)
B(-3,1,4,WATER:0)
B(-2,1,4,WATER:0)
B(0,1,4,PLANKS:5)
B(-5,1,5,WATER:0)
B(-4,1,5,WATER:0)
B(-6,2,-7,PLANKS:5)
B(-5,2,-7,SAND:0)
B(-4,2,-7,WATER:0)
B(-3,2,-7,WATER:0)
B(0,2,-7,SAND:0)
B(1,2,-7,WATER:0)
B(2,2,-7,WATER:0)
B(3,2,-7,WATER:0)
B(4,2,-7,WATER:0)
B(5,2,-7,WATER:0)
B(6,2,-7,PLANKS:5)
B(-5,2,-6,PLANKS:5)
B(-4,2,-6,SAND:0)
B(-3,2,-6,WATER:0)
B(0,2,-6,LOG:1)
B(1,2,-6,WATER:0)
B(2,2,-6,WATER:0)
B(3,2,-6,WATER:0)
B(4,2,-6,WATER:0)
B(5,2,-6,PLANKS:5)
B(-5,2,-5,SAND:0)
B(-4,2,-5,WATER:0)
B(-3,2,-5,WATER:0)
B(0,2,-5,SAND:0)
B(1,2,-5,WATER:0)
B(2,2,-5,WATER:0)
B(3,2,-5,WATER:0)
B(4,2,-5,WATER:0)
B(-5,2,-4,PLANKS:5)
B(-4,2,-4,STAINED_HARDENED_CLAY:9)
B(-3,2,-4,STAINED_HARDENED_CLAY:9)
B(-2,2,-4,STAINED_HARDENED_CLAY:9)
B(-1,2,-4,WATER:0)
B(0,2,-4,STAINED_HARDENED_CLAY:9)
B(1,2,-4,WATER:0)
B(2,2,-4,STAINED_HARDENED_CLAY:9)
B(3,2,-4,STAINED_HARDENED_CLAY:9)
B(4,2,-4,STAINED_HARDENED_CLAY:9)
B(5,2,-4,PLANKS:5)
B(-5,2,-3,PLANKS:5)
B(-4,2,-3,WATER:0)
B(-3,2,-3,WATER:0)
B(-2,2,-3,LOG:1)
B(-1,2,-3,WATER:0)
B(0,2,-3,WATER:0)
B(1,2,-3,WATER:0)
B(2,2,-3,LOG:1)
B(3,2,-3,WATER:0)
B(4,2,-3,WATER:0)
B(5,2,-3,PLANKS:5)
B(-5,2,-2,PLANKS:5)
B(-4,2,-2,WATER:0)
B(-3,2,-2,WATER:0)
B(-2,2,-2,WATER:0)
B(-1,2,-2,WATER:0)
B(0,2,-2,WATER:0)
B(1,2,-2,WATER:0)
B(2,2,-2,WATER:0)
B(3,2,-2,WATER:0)
B(4,2,-2,WATER:0)
B(5,2,-2,PLANKS:5)
B(-4,2,-1,PLANKS:5)
B(-3,2,-1,WATER:0)
B(-2,2,-1,WATER:0)
B(-1,2,-1,LOG:1)
B(0,2,-1,WATER:0)
B(1,2,-1,LOG:1)
B(2,2,-1,WATER:0)
B(3,2,-1,WATER:0)
B(4,2,-1,PLANKS:5)
B(-3,2,0,PLANKS:5)
B(-2,2,0,PLANKS:5)
B(-1,2,0,PLANKS:5)
B(0,2,0,PLANKS:5)
B(1,2,0,PLANKS:5)
B(2,2,0,PLANKS:5)
B(3,2,0,PLANKS:5)
B(-5,2,1,WATER:0)
B(-4,2,1,WATER:0)
B(-3,2,1,WATER:0)
B(-2,2,1,WATER:0)
B(-6,2,2,WATER:0)
B(-5,2,2,WATER:0)
B(-4,2,2,WATER:0)
B(-3,2,2,WATER:0)
B(-2,2,2,WATER:0)
B(0,2,2,PLANKS:5)
B(-6,2,3,WATER:0)
B(-5,2,3,WATER:0)
B(-4,2,3,WATER:0)
B(-3,2,3,WATER:0)
B(-2,2,3,WATER:0)
B(0,2,3,LOG_2:1)
B(-6,2,4,WATER:0)
B(-5,2,4,WATER:0)
B(-4,2,4,WATER:0)
B(-3,2,4,WATER:0)
B(-2,2,4,WATER:0)
B(0,2,4,PLANKS:5)
B(-6,2,5,WATER:0)
B(-5,2,5,WATER:0)
B(-4,2,5,WATER:0)
B(-3,2,5,WATER:0)
B(-5,3,-7,PLANKS:5)
B(-4,3,-7,PLANKS:5)
B(-3,3,-7,PLANKS:5)
B(-2,3,-7,PLANKS:5)
B(-1,3,-7,PLANKS:5)
B(0,3,-7,PLANKS:5)
B(1,3,-7,PLANKS:5)
B(2,3,-7,PLANKS:5)
B(3,3,-7,PLANKS:5)
B(4,3,-7,PLANKS:5)
B(5,3,-7,PLANKS:5)
B(-5,3,-6,PLANKS:5)
B(-4,3,-6,PLANKS:5)
B(-3,3,-6,PLANKS:5)
B(-2,3,-6,PLANKS:5)
B(-1,3,-6,PLANKS:5)
B(0,3,-6,LOG:1)
B(1,3,-6,PLANKS:5)
B(2,3,-6,PLANKS:5)
B(3,3,-6,PLANKS:5)
B(4,3,-6,PLANKS:5)
B(5,3,-6,PLANKS:5)
B(-5,3,-5,PLANKS:5)
B(-4,3,-5,PLANKS:5)
B(-3,3,-5,PLANKS:5)
B(-2,3,-5,PLANKS:5)
B(-1,3,-5,PLANKS:5)
B(0,3,-5,SAND:0)
B(1,3,-5,PLANKS:5)
B(2,3,-5,PLANKS:5)
B(3,3,-5,PLANKS:5)
B(4,3,-5,PLANKS:5)
B(5,3,-5,PLANKS:5)
B(-5,3,-4,PLANKS:5)
B(-4,3,-4,PLANKS:5)
B(-3,3,-4,PLANKS:5)
B(-2,3,-4,PLANKS:5)
B(-1,3,-4,PLANKS:5)
B(0,3,-4,PLANKS:5)
B(1,3,-4,PLANKS:5)
B(2,3,-4,PLANKS:5)
B(3,3,-4,PLANKS:5)
B(4,3,-4,PLANKS:5)
B(5,3,-4,PLANKS:5)
B(-5,3,-3,PLANKS:5)
B(-4,3,-3,PLANKS:5)
B(-3,3,-3,PLANKS:5)
B(-2,3,-3,PLANKS:5)
B(-1,3,-3,PLANKS:5)
B(0,3,-3,PLANKS:5)
B(1,3,-3,PLANKS:5)
B(2,3,-3,PLANKS:5)
B(3,3,-3,PLANKS:5)
B(4,3,-3,PLANKS:5)
B(5,3,-3,PLANKS:5)
B(-4,3,-2,PLANKS:5)
B(-3,3,-2,PLANKS:5)
B(-2,3,-2,PLANKS:5)
B(-1,3,-2,PLANKS:5)
B(0,3,-2,PLANKS:5)
B(1,3,-2,PLANKS:5)
B(2,3,-2,PLANKS:5)
B(3,3,-2,PLANKS:5)
B(4,3,-2,PLANKS:5)
B(-4,3,-1,PLANKS:5)
B(-3,3,-1,PLANKS:5)
B(-2,3,-1,PLANKS:5)
B(-1,3,-1,PLANKS:5)
B(0,3,-1,PLANKS:5)
B(1,3,-1,PLANKS:5)
B(2,3,-1,PLANKS:5)
B(3,3,-1,PLANKS:5)
B(4,3,-1,PLANKS:5)
B(-5,3,0,WATER:0)
B(-4,3,0,WATER:0)
B(-3,3,0,WATER:0)
B(-2,3,0,WATER:0)
B(-1,3,0,WATER:0)
B(-6,3,1,WATER:0)
B(-5,3,1,WATER:0)
B(-4,3,1,WATER:0)
B(-3,3,1,WATER:0)
B(-2,3,1,WATER:0)
B(-1,3,1,WATER:0)
B(0,3,1,PLANKS:5)
B(-6,3,2,WATER:0)
B(-5,3,2,WATER:0)
B(-4,3,2,WATER:0)
B(-3,3,2,WATER:0)
B(-2,3,2,WATER:0)
B(-1,3,2,WATER:0)
B(0,3,2,LOG_2:1)
B(-7,3,3,WATER:0)
B(-6,3,3,WATER:0)
B(-5,3,3,WATER:0)
B(-4,3,3,WATER:0)
B(-3,3,3,WATER:0)
B(-2,3,3,WATER:0)
B(-1,3,3,WATER:0)
B(0,3,3,LOG_2:1)
B(-6,3,4,WATER:0)
B(-5,3,4,WATER:0)
B(-4,3,4,WATER:0)
B(-3,3,4,WATER:0)
B(-2,3,4,WATER:0)
B(0,3,4,PLANKS:5)
B(-6,3,5,WATER:0)
B(-5,3,5,WATER:0)
B(-4,3,5,WATER:0)
B(-3,3,5,WATER:0)
B(-5,3,6,WATER:0)
B(-5,4,-7,LOG_2:1)
B(-4,4,-7,DOUBLE_WOODEN_SLAB:1)
B(-3,4,-7,DOUBLE_WOODEN_SLAB:1)
B(-2,4,-7,DOUBLE_WOODEN_SLAB:1)
B(-1,4,-7,SAND:0)
B(0,4,-7,PLANKS:5)
B(1,4,-7,DOUBLE_WOODEN_SLAB:1)
B(2,4,-7,DARK_OAK_DOOR:3)
B(3,4,-7,DOUBLE_WOODEN_SLAB:1)
B(4,4,-7,DOUBLE_WOODEN_SLAB:1)
B(5,4,-7,LOG_2:1)
B(-5,4,-6,LOG_2:1)
B(-3,4,-6,LOG_2:1)
B(-2,4,-6,SAND:0)
B(-1,4,-6,SAND:0)
B(0,4,-6,LOG:1)
B(1,4,-6,AIR:0)
B(2,4,-6,AIR:0)
B(3,4,-6,LOG_2:1)
B(5,4,-6,LOG_2:1)
B(-5,4,-5,LOG_2:1)
B(-4,4,-5,DOUBLE_WOODEN_SLAB:1)
B(-3,4,-5,SAND:0)
B(-2,4,-5,SAND:0)
B(-1,4,-5,SAND:0)
B(0,4,-5,SAND:0)
B(1,4,-5,AIR:0)
B(2,4,-5,AIR:0)
RB(3,4,-5,SKULL:1,../NBT/Skulls/dungeon_skull_01.nbt,6,SKULL:1,../NBT/Skulls/dungeon_skull_02.nbt,12,SKULL:1,../NBT/Skulls/dungeon_skull_03.nbt,18,SKULL:1,../NBT/Skulls/dungeon_skull_04.nbt,24,SKULL:1,../NBT/Skulls/dungeon_skull_05.nbt,30,SKULL:1,../NBT/Skulls/dungeon_skull_06.nbt,36,SKULL:1,../NBT/Skulls/dungeon_skull_07.nbt,42,SKULL:1,../NBT/Skulls/dungeon_skull_08.nbt,48,SKULL:1,../NBT/Skulls/dungeon_skull_09.nbt,54,SKULL:1,../NBT/Skulls/dungeon_skull_10.nbt,60,SKULL:1,../NBT/Skulls/dungeon_skull_11.nbt,66,SKULL:1,../NBT/Skulls/dungeon_skull_12.nbt,72,SKULL:1,../NBT/Skulls/dungeon_skull_13.nbt,78,SKULL:1,../NBT/Skulls/dungeon_skull_14.nbt,84,SKULL:1,../NBT/Skulls/dungeon_skull_15.nbt,90,SKULL:1,../NBT/Skulls/dungeon_skull_16.nbt,100)
B(4,4,-5,DOUBLE_WOODEN_SLAB:1)
B(5,4,-5,LOG_2:1)
B(-5,4,-4,LOG_2:1)
B(-4,4,-4,DOUBLE_WOODEN_SLAB:1)
B(-3,4,-4,SAND:0)
B(-2,4,-4,SAND:0)
B(-1,4,-4,SAND:0)
B(0,4,-4,AIR:0)
B(1,4,-4,AIR:0)
B(2,4,-4,AIR:0)
B(3,4,-4,CRAFTING_TABLE:0)
B(4,4,-4,DOUBLE_WOODEN_SLAB:1)
B(5,4,-4,LOG_2:1)
B(-4,4,-3,LOG_2:1)
B(-3,4,-3,DOUBLE_WOODEN_SLAB:1)
B(-2,4,-3,SAND:0)
B(-1,4,-3,BED:0)
B(0,4,-3,AIR:0)
B(1,4,-3,AIR:0)
B(2,4,-3,AIR:0)
B(3,4,-3,PLANKS:5)
B(4,4,-3,LOG_2:1)
B(-4,4,-2,LOG_2:1)
B(-3,4,-2,DOUBLE_WOODEN_SLAB:1)
B(-2,4,-2,SAND:0)
B(-1,4,-2,BED:8)
RB(0,4,-2,CHEST:2,../NBT/LoreStoryline/LoreGeneric_5.nbt,2,CHEST:2,../NBT/LoreStoryline/LoreGeneric_4.nbt,2,CHEST:2,../NBT/LoreStoryline/LoreGeneric_3.nbt,2,CHEST:2,../NBT/LoreStoryline/LoreGeneric_2.nbt,2,CHEST:2,../NBT/LoreStoryline/LoreGeneric_1.nbt,2,CHEST:2,../NBT/LoreStoryline/LoreShipSunk_5.nbt,3,CHEST:2,../NBT/LoreStoryline/LoreShipSunk_4.nbt,3,CHEST:2,../NBT/LoreStoryline/LoreShipSunk_3.nbt,3,CHEST:2,../NBT/LoreStoryline/LoreShipSunk_2.nbt,3,CHEST:2,../NBT/LoreStoryline/LoreShipSunk_1.nbt,3,CHEST:2,../NBT/StructureLoot/Common1.nbt,3,CHEST:2,../NBT/StructureLoot/Common2.nbt,3,CHEST:2,../NBT/StructureLoot/Common3.nbt,3,CHEST:2,../NBT/StructureLoot/Common4.nbt,3,CHEST:2,../NBT/StructureLoot/Common5.nbt,3,CHEST:2,../NBT/StructureLoot/Common5.nbt,3,CHEST:2,../NBT/StructureLoot/Common6.nbt,3,CHEST:2,../NBT/StructureLoot/Common7.nbt,3,CHEST:2,../NBT/StructureLoot/Common8.nbt,3,CHEST:2,../NBT/StructureLoot/Common9.nbt,3,CHEST:2,../NBT/StructureLoot/Common10.nbt,3,CHEST:2,../NBT/StructureLoot/Common11.nbt,3,CHEST:2,../NBT/StructureLoot/Common12.nbt,3,CHEST:2,../NBT/StructureLoot/Common13.nbt,3,CHEST:2,../NBT/StructureLoot/Common14.nbt,3,CHEST:2,../NBT/StructureLoot/Common15.nbt,3,CHEST:2,../NBT/StructureLoot/Rare1.nbt,3,CHEST:2,../NBT/StructureLoot/Rare2.nbt,3,CHEST:2,../NBT/StructureLoot/Rare3.nbt,3,CHEST:2,../NBT/StructureLoot/Rare4.nbt,3,CHEST:2,../NBT/StructureLoot/Rare5.nbt,3,CHEST:2,../NBT/StructureLoot/Rare6.nbt,3,CHEST:2,../NBT/StructureLoot/Rare7.nbt,3,CHEST:2,../NBT/StructureLoot/Rare8.nbt,3,CHEST:2,../NBT/StructureLoot/Rare9.nbt,3,CHEST:2,../NBT/StructureLoot/Rare10.nbt,3,CHEST:2,../NBT/StructureLoot/Rare11.nbt,3,CHEST:2,../NBT/StructureLoot/Rare12.nbt,3,CHEST:2,../NBT/StructureLoot/Rare13.nbt,3,CHEST:2,../NBT/StructureLoot/Rare14.nbt,3,CHEST:2,../NBT/StructureLoot/Rare15.nbt,3,CHEST:2,../NBT/StructureLoot/Epic1.nbt,3,CHEST:2,../NBT/StructureLoot/Epic2.nbt,3,CHEST:2,../NBT/StructureLoot/Epic3.nbt,3,CHEST:2,../NBT/StructureLoot/Epic4.nbt,3,CHEST:2,../NBT/StructureLoot/Epic5.nbt,3,CHEST:2,../NBT/StructureLoot/Epic6.nbt,3,CHEST:2,../NBT/StructureLoot/Epic7.nbt,3,CHEST:2,../NBT/StructureLoot/Epic8.nbt,3,CHEST:2,../NBT/StructureLoot/Epic9.nbt,3,CHEST:2,../NBT/StructureLoot/Epic10.nbt,3,CHEST:2,../NBT/StructureLoot/Epic11.nbt,3,CHEST:2,../NBT/StructureLoot/Epic12.nbt,3,CHEST:2,../NBT/StructureLoot/Epic13.nbt,3,CHEST:2,../NBT/StructureLoot/Epic14.nbt,3,CHEST:2,../NBT/StructureLoot/Epic15.nbt,1,CHEST:2,../NBT/StructureLoot/Common15.nbt,100)
RB(1,4,-2,SKULL:1,../NBT/Skulls/dungeon_skull_01.nbt,6,SKULL:1,../NBT/Skulls/dungeon_skull_02.nbt,12,SKULL:1,../NBT/Skulls/dungeon_skull_03.nbt,18,SKULL:1,../NBT/Skulls/dungeon_skull_04.nbt,24,SKULL:1,../NBT/Skulls/dungeon_skull_05.nbt,30,SKULL:1,../NBT/Skulls/dungeon_skull_06.nbt,36,SKULL:1,../NBT/Skulls/dungeon_skull_07.nbt,42,SKULL:1,../NBT/Skulls/dungeon_skull_08.nbt,48,SKULL:1,../NBT/Skulls/dungeon_skull_09.nbt,54,SKULL:1,../NBT/Skulls/dungeon_skull_10.nbt,60,SKULL:1,../NBT/Skulls/dungeon_skull_11.nbt,66,SKULL:1,../NBT/Skulls/dungeon_skull_12.nbt,72,SKULL:1,../NBT/Skulls/dungeon_skull_13.nbt,78,SKULL:1,../NBT/Skulls/dungeon_skull_14.nbt,84,SKULL:1,../NBT/Skulls/dungeon_skull_15.nbt,90,SKULL:1,../NBT/Skulls/dungeon_skull_16.nbt,100)
RB(2,4,-2,SKULL:1,../NBT/Skulls/dungeon_skull_01.nbt,6,SKULL:1,../NBT/Skulls/dungeon_skull_02.nbt,12,SKULL:1,../NBT/Skulls/dungeon_skull_03.nbt,18,SKULL:1,../NBT/Skulls/dungeon_skull_04.nbt,24,SKULL:1,../NBT/Skulls/dungeon_skull_05.nbt,30,SKULL:1,../NBT/Skulls/dungeon_skull_06.nbt,36,SKULL:1,../NBT/Skulls/dungeon_skull_07.nbt,42,SKULL:1,../NBT/Skulls/dungeon_skull_08.nbt,48,SKULL:1,../NBT/Skulls/dungeon_skull_09.nbt,54,SKULL:1,../NBT/Skulls/dungeon_skull_10.nbt,60,SKULL:1,../NBT/Skulls/dungeon_skull_11.nbt,66,SKULL:1,../NBT/Skulls/dungeon_skull_12.nbt,72,SKULL:1,../NBT/Skulls/dungeon_skull_13.nbt,78,SKULL:1,../NBT/Skulls/dungeon_skull_14.nbt,84,SKULL:1,../NBT/Skulls/dungeon_skull_15.nbt,90,SKULL:1,../NBT/Skulls/dungeon_skull_16.nbt,100)
B(3,4,-2,DOUBLE_WOODEN_SLAB:1)
B(4,4,-2,LOG_2:1)
B(-4,4,-1,LOG_2:1)
B(-3,4,-1,LOG_2:1)
B(-2,4,-1,LOG_2:1)
B(-1,4,-1,LOG_2:1)
B(0,4,-1,LOG_2:1)
B(1,4,-1,LOG_2:1)
B(2,4,-1,LOG_2:1)
B(3,4,-1,LOG_2:1)
B(4,4,-1,LOG_2:1)
B(-5,4,0,WATER:0)
B(-4,4,0,WATER:0)
B(-3,4,0,WATER:0)
B(-2,4,0,WATER:0)
B(-1,4,0,WATER:0)
B(-6,4,1,WATER:0)
B(-5,4,1,WATER:0)
B(-4,4,1,WATER:0)
B(-3,4,1,WATER:0)
B(-2,4,1,WATER:0)
B(-1,4,1,WATER:0)
B(0,4,1,LOG_2:1)
B(-6,4,2,WATER:0)
B(-5,4,2,WATER:0)
B(-4,4,2,WATER:0)
B(-3,4,2,WATER:0)
B(-2,4,2,WATER:0)
B(-1,4,2,WATER:0)
B(0,4,2,LOG_2:1)
B(-7,4,3,WATER:0)
B(-6,4,3,WATER:0)
B(-5,4,3,WATER:0)
B(-4,4,3,WATER:0)
B(-3,4,3,WATER:0)
B(-2,4,3,WATER:0)
B(-1,4,3,WATER:0)
B(0,4,3,LOG_2:1)
B(-7,4,4,WATER:0)
B(-6,4,4,WATER:0)
B(-5,4,4,WATER:0)
B(-4,4,4,WATER:0)
B(-3,4,4,WATER:0)
B(-2,4,4,WATER:0)
B(-1,4,4,WATER:0)
B(0,4,4,PLANKS:5)
B(-6,4,5,WATER:0)
B(-5,4,5,WATER:0)
B(-4,4,5,WATER:0)
B(-3,4,5,WATER:0)
B(0,4,5,PLANKS:5)
B(-6,4,6,WATER:0)
B(-5,4,6,WATER:0)
B(-4,4,6,WATER:0)
B(-4,5,-7,LOG_2:1)
B(-3,5,-7,DOUBLE_WOODEN_SLAB:1)
B(-2,5,-7,DOUBLE_WOODEN_SLAB:1)
B(-1,5,-7,SAND:0)
B(0,5,-7,LOG:9)
B(1,5,-7,DOUBLE_WOODEN_SLAB:1)
B(2,5,-7,DARK_OAK_DOOR:9)
B(3,5,-7,DOUBLE_WOODEN_SLAB:1)
B(4,5,-7,LOG_2:1)
B(-4,5,-6,LOG_2:1)
B(-3,5,-6,LOG_2:1)
B(-2,5,-6,SAND:0)
B(-1,5,-6,SAND:0)
B(0,5,-6,LOG:1)
B(1,5,-6,AIR:0)
B(2,5,-6,AIR:0)
B(3,5,-6,LOG_2:1)
B(4,5,-6,LOG_2:1)
B(-4,5,-5,LOG_2:1)
B(-3,5,-5,LOG_2:1)
B(-2,5,-5,SAND:0)
B(-1,5,-5,SAND:0)
RB(0,5,-5,SKULL:1,../NBT/Skulls/dungeon_skull_01.nbt,6,SKULL:1,../NBT/Skulls/dungeon_skull_02.nbt,12,SKULL:1,../NBT/Skulls/dungeon_skull_03.nbt,18,SKULL:1,../NBT/Skulls/dungeon_skull_04.nbt,24,SKULL:1,../NBT/Skulls/dungeon_skull_05.nbt,30,SKULL:1,../NBT/Skulls/dungeon_skull_06.nbt,36,SKULL:1,../NBT/Skulls/dungeon_skull_07.nbt,42,SKULL:1,../NBT/Skulls/dungeon_skull_08.nbt,48,SKULL:1,../NBT/Skulls/dungeon_skull_09.nbt,54,SKULL:1,../NBT/Skulls/dungeon_skull_10.nbt,60,SKULL:1,../NBT/Skulls/dungeon_skull_11.nbt,66,SKULL:1,../NBT/Skulls/dungeon_skull_12.nbt,72,SKULL:1,../NBT/Skulls/dungeon_skull_13.nbt,78,SKULL:1,../NBT/Skulls/dungeon_skull_14.nbt,84,SKULL:1,../NBT/Skulls/dungeon_skull_15.nbt,90,SKULL:1,../NBT/Skulls/dungeon_skull_16.nbt,100)
B(1,5,-5,AIR:0)
B(2,5,-5,AIR:0)
B(3,5,-5,LOG_2:1)
B(4,5,-5,LOG_2:1)
B(-4,5,-4,LOG_2:1)
B(-3,5,-4,LOG_2:1)
B(-2,5,-4,AIR:0)
RB(-1,5,-4,SKULL:1,../NBT/Skulls/dungeon_skull_01.nbt,6,SKULL:1,../NBT/Skulls/dungeon_skull_02.nbt,12,SKULL:1,../NBT/Skulls/dungeon_skull_03.nbt,18,SKULL:1,../NBT/Skulls/dungeon_skull_04.nbt,24,SKULL:1,../NBT/Skulls/dungeon_skull_05.nbt,30,SKULL:1,../NBT/Skulls/dungeon_skull_06.nbt,36,SKULL:1,../NBT/Skulls/dungeon_skull_07.nbt,42,SKULL:1,../NBT/Skulls/dungeon_skull_08.nbt,48,SKULL:1,../NBT/Skulls/dungeon_skull_09.nbt,54,SKULL:1,../NBT/Skulls/dungeon_skull_10.nbt,60,SKULL:1,../NBT/Skulls/dungeon_skull_11.nbt,66,SKULL:1,../NBT/Skulls/dungeon_skull_12.nbt,72,SKULL:1,../NBT/Skulls/dungeon_skull_13.nbt,78,SKULL:1,../NBT/Skulls/dungeon_skull_14.nbt,84,SKULL:1,../NBT/Skulls/dungeon_skull_15.nbt,90,SKULL:1,../NBT/Skulls/dungeon_skull_16.nbt,100)
B(0,5,-4,AIR)
B(1,5,-4,AIR:0)
B(2,5,-4,AIR:0)
B(3,5,-4,LOG_2:1)
B(4,5,-4,LOG_2:1)
B(-3,5,-3,LOG_2:1)
B(-2,5,-3,LOG_2:1)
B(-1,5,-3,AIR:0)
B(0,5,-3,AIR:0)
B(1,5,-3,AIR:0)
B(2,5,-3,LOG_2:1)
B(3,5,-3,LOG_2:1)
B(-4,5,-2,WATER:0)
B(-3,5,-2,LOG_2:1)
B(-2,5,-2,LOG_2:1)
B(-1,5,-2,AIR:0)
B(0,5,-2,AIR:0)
B(1,5,-2,AIR:0)
B(2,5,-2,LOG_2:1)
B(3,5,-2,LOG_2:1)
B(-4,5,-1,WATER:0)
B(-3,5,-1,LOG_2:1)
B(-2,5,-1,LOG_2:1)
B(-1,5,-1,LOG_2:1)
B(0,5,-1,LOG_2:1)
B(1,5,-1,LOG_2:1)
B(2,5,-1,LOG_2:1)
B(3,5,-1,LOG_2:1)
B(-6,5,0,WATER:0)
B(-5,5,0,WATER:0)
B(-4,5,0,WATER:0)
B(-3,5,0,WATER:0)
B(-2,5,0,WATER:0)
B(-1,5,0,WATER:0)
B(-6,5,1,WATER:0)
B(-5,5,1,WATER:0)
B(-4,5,1,WATER:0)
B(-3,5,1,WATER:0)
B(-2,5,1,WATER:0)
B(-1,5,1,WATER:0)
B(0,5,1,LOG_2:1)
B(-7,5,2,WATER:0)
B(-6,5,2,WATER:0)
B(-5,5,2,WATER:0)
B(-4,5,2,WATER:0)
B(-3,5,2,WATER:0)
B(-2,5,2,WATER:0)
B(-1,5,2,WATER:0)
B(0,5,2,LOG_2:1)
B(-7,5,3,WATER:0)
B(-6,5,3,WATER:0)
B(-5,5,3,WATER:0)
B(-4,5,3,WATER:0)
B(-3,5,3,WATER:0)
B(-2,5,3,WATER:0)
B(-1,5,3,WATER:0)
B(0,5,3,LOG_2:1)
B(-7,5,4,WATER:0)
B(-6,5,4,WATER:0)
B(-5,5,4,WATER:0)
B(-4,5,4,WATER:0)
B(-3,5,4,WATER:0)
B(-2,5,4,WATER:0)
B(-1,5,4,WATER:0)
B(0,5,4,LOG_2:1)
B(-6,5,5,WATER:0)
B(-5,5,5,WATER:0)
B(-4,5,5,WATER:0)
B(-3,5,5,WATER:0)
B(-2,5,5,WATER:0)
B(0,5,5,PLANKS:5)
B(-6,5,6,WATER:0)
B(-5,5,6,WATER:0)
B(-4,5,6,WATER:0)
B(-3,5,6,WATER:0)
B(-3,6,-7,LOG_2:1)
B(-2,6,-7,LOG_2:1)
B(-1,6,-7,LOG_2:1)
B(0,6,-7,REDSTONE_BLOCK:0)
B(1,6,-7,LOG_2:1)
B(2,6,-7,LOG_2:1)
B(3,6,-7,LOG_2:1)
B(-2,6,-6,LOG_2:1)
B(-1,6,-6,LOG_2:1)
B(0,6,-6,PLANKS:5)
B(1,6,-6,LOG_2:1)
B(2,6,-6,LOG_2:1)
B(-2,6,-5,LOG_2:1)
B(-1,6,-5,LOG_2:1)
B(0,6,-5,PLANKS:5)
B(1,6,-5,LOG_2:1)
B(2,6,-5,LOG_2:1)
B(-2,6,-4,LOG_2:1)
B(-1,6,-4,LOG_2:1)
B(0,6,-4,WOODEN_SLAB:1)
B(1,6,-4,LOG_2:1)
B(2,6,-4,LOG_2:1)
B(-3,6,-3,WATER:0)
B(-2,6,-3,WATER:0)
B(-1,6,-3,LOG_2:1)
B(0,6,-3,WOODEN_SLAB:1)
B(1,6,-3,LOG_2:1)
B(-4,6,-2,WATER:0)
B(-3,6,-2,WATER:0)
B(-2,6,-2,WATER:0)
B(-1,6,-2,LOG_2:1)
B(0,6,-2,WOODEN_SLAB:1)
B(1,6,-2,LOG_2:1)
B(-5,6,-1,WATER:0)
B(-4,6,-1,WATER:0)
B(-3,6,-1,WATER:0)
B(-2,6,-1,WATER:0)
B(-1,6,-1,LOG_2:1)
B(0,6,-1,LOG_2:1)
B(1,6,-1,LOG_2:1)
B(-6,6,0,WATER:0)
B(-5,6,0,WATER:0)
B(-4,6,0,WATER:0)
B(-3,6,0,WATER:0)
B(-2,6,0,WATER:0)
B(-1,6,0,WATER:0)
B(-7,6,1,WATER:0)
B(-6,6,1,WATER:0)
B(-5,6,1,WATER:0)
B(-4,6,1,WATER:0)
B(-3,6,1,WATER:0)
B(-2,6,1,WATER:0)
B(-1,6,1,WATER:0)
B(0,6,1,LOG_2:1)
B(-7,6,2,WATER:0)
B(-6,6,2,WATER:0)
B(-5,6,2,WATER:0)
B(-4,6,2,WATER:0)
B(-3,6,2,WATER:0)
B(-2,6,2,WATER:0)
B(-1,6,2,WATER:0)
B(0,6,2,LOG_2:1)
B(-7,6,3,WATER:0)
B(-6,6,3,WATER:0)
B(-5,6,3,WATER:0)
B(-4,6,3,WATER:0)
B(-3,6,3,WATER:0)
B(-2,6,3,WATER:0)
B(-1,6,3,WATER:0)
B(0,6,3,LOG_2:1)
B(-7,6,4,WATER:0)
B(-6,6,4,WATER:0)
B(-5,6,4,WATER:0)
B(-4,6,4,WATER:0)
B(-3,6,4,WATER:0)
B(-2,6,4,WATER:0)
B(-1,6,4,WATER:0)
B(0,6,4,LOG_2:1)
B(-7,6,5,WATER:0)
B(-6,6,5,WATER:0)
B(-5,6,5,WATER:0)
B(-4,6,5,WATER:0)
B(-3,6,5,WATER:0)
B(-2,6,5,WATER:0)
B(-1,6,5,WATER:0)
B(0,6,5,PLANKS:5)
B(-6,6,6,WATER:0)
B(-5,6,6,WATER:0)
B(-4,6,6,WATER:0)
B(-3,6,6,WATER:0)
B(-2,6,6,WATER:0)
B(-6,6,7,WATER:0)
B(-5,6,7,WATER:0)
B(-4,6,7,WATER:0)
B(-3,6,7,WATER:0)
B(0,7,-7,LOG_2:1)
B(0,7,-6,LOG_2:1)
B(0,7,-5,LOG_2:1)
B(0,7,-4,LOG_2:1)
B(-4,7,-3,WATER:0)
B(-3,7,-3,WATER:0)
B(-2,7,-3,WATER:0)
B(0,7,-3,LOG_2:1)
B(-5,7,-2,WATER:0)
B(-4,7,-2,WATER:0)
B(-3,7,-2,WATER:0)
B(-2,7,-2,WATER:0)
B(-1,7,-2,WATER:0)
B(0,7,-2,LOG_2:1)
B(-6,7,-1,WATER:0)
B(-5,7,-1,WATER:0)
B(-4,7,-1,WATER:0)
B(-3,7,-1,WATER:0)
B(-2,7,-1,WATER:0)
B(-1,7,-1,WATER:0)
B(0,7,-1,PLANKS:5)
B(-7,7,0,WATER:0)
B(-6,7,0,WATER:0)
B(-5,7,0,WATER:0)
B(-4,7,0,WATER:0)
B(-3,7,0,WATER:0)
B(-2,7,0,WATER:0)
B(-1,7,0,WATER:0)
B(0,7,0,WATER:0)
B(-7,7,1,WATER:0)
B(-6,7,1,WATER:0)
B(-5,7,1,WATER:0)
B(-4,7,1,WATER:0)
B(-3,7,1,WATER:0)
B(-2,7,1,WATER:0)
B(-1,7,1,WATER:0)
B(0,7,1,LOG_2:1)
B(-7,7,2,WATER:0)
B(-6,7,2,WATER:0)
B(-5,7,2,WATER:0)
B(-4,7,2,WATER:0)
B(-3,7,2,WATER:0)
B(-2,7,2,WATER:0)
B(-1,7,2,WATER:0)
B(0,7,2,LOG_2:1)
B(-7,7,3,WATER:0)
B(-6,7,3,WATER:0)
B(-5,7,3,WATER:0)
B(-4,7,3,WATER:0)
B(-3,7,3,WATER:0)
B(-2,7,3,WATER:0)
B(-1,7,3,WATER:0)
B(0,7,3,LOG_2:1)
B(-7,7,4,WATER:0)
B(-6,7,4,WATER:0)
B(-5,7,4,WATER:0)
B(-4,7,4,WATER:0)
B(-3,7,4,WATER:0)
B(-2,7,4,WATER:0)
B(-1,7,4,WATER:0)
B(0,7,4,LOG_2:1)
B(-7,7,5,WATER:0)
B(-6,7,5,WATER:0)
B(-5,7,5,WATER:0)
B(-4,7,5,WATER:0)
B(-3,7,5,WATER:0)
B(-2,7,5,WATER:0)
B(-1,7,5,WATER:0)
B(0,7,5,PLANKS:5)
B(-7,7,6,WATER:0)
B(-6,7,6,WATER:0)
B(-5,7,6,WATER:0)
B(-4,7,6,WATER:0)
B(-3,7,6,WATER:0)
B(-2,7,6,WATER:0)
B(-1,7,6,WATER:0)
B(-6,7,7,WATER:0)
B(-5,7,7,WATER:0)
B(-4,7,7,WATER:0)
B(-3,7,7,WATER:0)
B(-5,7,8,WATER:0)
B(-4,7,8,WATER:0)
B(-3,7,8,WATER:0)
B(0,8,-7,LOG_2:1)
B(0,8,-6,LOG_2:1)
B(0,8,-5,LOG_2:1)
B(0,8,-4,LOG_2:1)
B(0,8,-3,PLANKS:5)
B(0,8,-2,PLANKS:5)
B(0,8,1,LOG_2:1)
B(0,8,2,LOG_2:1)
B(0,8,3,LOG_2:1)
B(0,8,4,PLANKS:5)
B(0,8,5,PLANKS:5)
B(0,9,-7,LOG_2:1)
B(0,9,-6,LOG_2:1)
B(0,9,-5,PLANKS:5)
B(0,9,-4,PLANKS:5)
B(0,9,1,LOG_2:1)
B(0,9,2,LOG_2:1)
B(0,9,3,LOG_2:1)
B(0,9,4,PLANKS:5)
B(0,10,-7,PLANKS:5)
B(0,10,-6,PLANKS:5)
B(0,10,1,PLANKS:5)
B(0,10,2,PLANKS:5)
B(0,10,3,PLANKS:5)
B(0,10,4,PLANKS:5)

E(0,-3,2,GUARDIAN,1)
E(2,-2,-6,SQUID,1)
E(0,-2,-4,SQUID,1)
E(-4,1,-3,SQUID,1)
E(1,2,-3,SQUID,1)
E(0,5,-4,VINDICATOR,1,../NBT/MOBS/RandomPillager.txt)

